2020-04-19 14:18:05,336:ERROR:Internal Server Error: /postbox/
Traceback (most recent call last):
  File "C:\Program Files (x86)\Microsoft Visual Studio\Shared\Python37_64\lib\site-packages\django\db\backends\utils.py", line 86, in _execute
    return self.cursor.execute(sql, params)
  File "C:\Program Files (x86)\Microsoft Visual Studio\Shared\Python37_64\lib\site-packages\django\db\backends\sqlite3\base.py", line 396, in execute
    return Database.Cursor.execute(self, query, params)
sqlite3.OperationalError: no such table: book_book

The above exception was the direct cause of the following exception:

Traceback (most recent call last):
  File "C:\Program Files (x86)\Microsoft Visual Studio\Shared\Python37_64\lib\site-packages\django\core\handlers\exception.py", line 34, in inner
    response = get_response(request)
  File "C:\Program Files (x86)\Microsoft Visual Studio\Shared\Python37_64\lib\site-packages\django\core\handlers\base.py", line 115, in _get_response
    response = self.process_exception_by_middleware(e, request)
  File "C:\Program Files (x86)\Microsoft Visual Studio\Shared\Python37_64\lib\site-packages\django\core\handlers\base.py", line 113, in _get_response
    response = wrapped_callback(request, *callback_args, **callback_kwargs)
  File "C:\Program Files (x86)\Microsoft Visual Studio\Shared\Python37_64\lib\site-packages\django\views\decorators\csrf.py", line 54, in wrapped_view
    return view_func(*args, **kwargs)
  File "C:\Users\guo19\source\repos\resourcesNet\book\views.py", line 165, in postbox
    print(Book.objects.filter(file_name=file_name))
  File "C:\Program Files (x86)\Microsoft Visual Studio\Shared\Python37_64\lib\site-packages\django\db\models\query.py", line 252, in __repr__
    data = list(self[:REPR_OUTPUT_SIZE + 1])
  File "C:\Program Files (x86)\Microsoft Visual Studio\Shared\Python37_64\lib\site-packages\django\db\models\query.py", line 276, in __iter__
    self._fetch_all()
  File "C:\Program Files (x86)\Microsoft Visual Studio\Shared\Python37_64\lib\site-packages\django\db\models\query.py", line 1261, in _fetch_all
    self._result_cache = list(self._iterable_class(self))
  File "C:\Program Files (x86)\Microsoft Visual Studio\Shared\Python37_64\lib\site-packages\django\db\models\query.py", line 57, in __iter__
    results = compiler.execute_sql(chunked_fetch=self.chunked_fetch, chunk_size=self.chunk_size)
  File "C:\Program Files (x86)\Microsoft Visual Studio\Shared\Python37_64\lib\site-packages\django\db\models\sql\compiler.py", line 1151, in execute_sql
    cursor.execute(sql, params)
  File "C:\Program Files (x86)\Microsoft Visual Studio\Shared\Python37_64\lib\site-packages\django\db\backends\utils.py", line 100, in execute
    return super().execute(sql, params)
  File "C:\Program Files (x86)\Microsoft Visual Studio\Shared\Python37_64\lib\site-packages\django\db\backends\utils.py", line 68, in execute
    return self._execute_with_wrappers(sql, params, many=False, executor=self._execute)
  File "C:\Program Files (x86)\Microsoft Visual Studio\Shared\Python37_64\lib\site-packages\django\db\backends\utils.py", line 77, in _execute_with_wrappers
    return executor(sql, params, many, context)
  File "C:\Program Files (x86)\Microsoft Visual Studio\Shared\Python37_64\lib\site-packages\django\db\backends\utils.py", line 86, in _execute
    return self.cursor.execute(sql, params)
  File "C:\Program Files (x86)\Microsoft Visual Studio\Shared\Python37_64\lib\site-packages\django\db\utils.py", line 90, in __exit__
    raise dj_exc_value.with_traceback(traceback) from exc_value
  File "C:\Program Files (x86)\Microsoft Visual Studio\Shared\Python37_64\lib\site-packages\django\db\backends\utils.py", line 86, in _execute
    return self.cursor.execute(sql, params)
  File "C:\Program Files (x86)\Microsoft Visual Studio\Shared\Python37_64\lib\site-packages\django\db\backends\sqlite3\base.py", line 396, in execute
    return Database.Cursor.execute(self, query, params)
django.db.utils.OperationalError: no such table: book_book
2020-04-19 15:19:56,578:INFO:{"USER_AGENT": "Mozilla/5.0 (Windows NT 10.0; Win64; x64) AppleWebKit/537.36 (KHTML, like Gecko) Chrome/81.0.4044.113 Safari/537.36 Edg/81.0.416.58", "PATH_INFO": "/", "REMOTE_HOST": null, "USER_IP": "127.0.0.1"}

2020-04-19 15:20:24,343:WARNING:Forbidden (CSRF token missing or incorrect.): /admin/login/
2020-04-19 15:23:49,545:INFO:{"USER_AGENT": "Mozilla/5.0 (Windows NT 10.0; Win64; x64) AppleWebKit/537.36 (KHTML, like Gecko) Chrome/81.0.4044.113 Safari/537.36 Edg/81.0.416.58", "PATH_INFO": "/", "REMOTE_HOST": null, "USER_IP": "127.0.0.1"}

2020-04-19 15:24:26,362:INFO:{"USER_AGENT": "Mozilla/5.0 (Windows NT 10.0; Win64; x64) AppleWebKit/537.36 (KHTML, like Gecko) Chrome/81.0.4044.113 Safari/537.36 Edg/81.0.416.58", "PATH_INFO": "/detail/10471333/", "REMOTE_HOST": null, "USER_IP": "127.0.0.1"}

2020-04-19 15:27:09,186:INFO:{"USER_AGENT": "Mozilla/5.0 (Windows NT 10.0; Win64; x64) AppleWebKit/537.36 (KHTML, like Gecko) Chrome/81.0.4044.113 Safari/537.36 Edg/81.0.416.58", "PATH_INFO": "/", "REMOTE_HOST": null, "USER_IP": "127.0.0.1"}

2020-04-19 15:30:07,711:INFO:{"USER_AGENT": "Mozilla/5.0 (Windows NT 10.0; Win64; x64) AppleWebKit/537.36 (KHTML, like Gecko) Chrome/81.0.4044.113 Safari/537.36 Edg/81.0.416.58", "PATH_INFO": "/", "REMOTE_HOST": null, "USER_IP": "127.0.0.1"}

2020-04-19 15:32:22,329:INFO:{"USER_AGENT": "Mozilla/5.0 (Windows NT 10.0; Win64; x64) AppleWebKit/537.36 (KHTML, like Gecko) Chrome/81.0.4044.113 Safari/537.36 Edg/81.0.416.58", "PATH_INFO": "/", "REMOTE_HOST": null, "USER_IP": "127.0.0.1"}

2020-04-19 15:33:05,209:INFO:{"USER_AGENT": "Mozilla/5.0 (Windows NT 10.0; Win64; x64) AppleWebKit/537.36 (KHTML, like Gecko) Chrome/81.0.4044.113 Safari/537.36 Edg/81.0.416.58", "PATH_INFO": "/detail/26628819/", "REMOTE_HOST": null, "USER_IP": "127.0.0.1"}

2020-04-19 15:33:41,925:INFO:{"USER_AGENT": "Mozilla/5.0 (X11; U; Linux armv7l like Android; en-us) AppleWebKit/531.2+ (KHTML, like Gecko) Version/5.0 Safari/533.2+ Kindle/3.0+", "PATH_INFO": "/", "REMOTE_HOST": null, "USER_IP": "127.0.0.1"}

2020-04-19 15:33:51,382:INFO:{"USER_AGENT": "Mozilla/5.0 (X11; U; Linux armv7l like Android; en-us) AppleWebKit/531.2+ (KHTML, like Gecko) Version/5.0 Safari/533.2+ Kindle/3.0+", "PATH_INFO": "/detail/26628819/", "REMOTE_HOST": null, "USER_IP": "127.0.0.1"}

2020-04-19 15:35:07,847:INFO:{"USER_AGENT": "Mozilla/5.0 (X11; U; Linux armv7l like Android; en-us) AppleWebKit/531.2+ (KHTML, like Gecko) Version/5.0 Safari/533.2+ Kindle/3.0+", "PATH_INFO": "/detail/26628819/", "REMOTE_HOST": null, "USER_IP": "127.0.0.1"}

2020-04-19 15:36:22,231:INFO:{"USER_AGENT": "Mozilla/5.0 (X11; U; Linux armv7l like Android; en-us) AppleWebKit/531.2+ (KHTML, like Gecko) Version/5.0 Safari/533.2+ Kindle/3.0+", "PATH_INFO": "/detail/26628819/", "REMOTE_HOST": null, "USER_IP": "127.0.0.1"}

2020-04-19 15:38:05,369:INFO:{"USER_AGENT": "Mozilla/5.0 (X11; U; Linux armv7l like Android; en-us) AppleWebKit/531.2+ (KHTML, like Gecko) Version/5.0 Safari/533.2+ Kindle/3.0+", "PATH_INFO": "/detail/26628819/", "REMOTE_HOST": null, "USER_IP": "127.0.0.1"}

2020-04-19 15:39:06,973:INFO:{"USER_AGENT": "Mozilla/5.0 (X11; U; Linux armv7l like Android; en-us) AppleWebKit/531.2+ (KHTML, like Gecko) Version/5.0 Safari/533.2+ Kindle/3.0+", "PATH_INFO": "/detail/26628819/", "REMOTE_HOST": null, "USER_IP": "127.0.0.1"}

2020-04-19 15:39:28,486:INFO:{"USER_AGENT": "Mozilla/5.0 (Windows NT 10.0; Win64; x64) AppleWebKit/537.36 (KHTML, like Gecko) Chrome/81.0.4044.113 Safari/537.36 Edg/81.0.416.58", "PATH_INFO": "/detail/26628819/", "REMOTE_HOST": null, "USER_IP": "127.0.0.1"}

2020-04-19 15:40:46,082:INFO:{"USER_AGENT": "Mozilla/5.0 (X11; U; Linux armv7l like Android; en-us) AppleWebKit/531.2+ (KHTML, like Gecko) Version/5.0 Safari/533.2+ Kindle/3.0+", "PATH_INFO": "/detail/26628819/", "REMOTE_HOST": null, "USER_IP": "127.0.0.1"}

2020-04-19 15:40:53,312:INFO:{"USER_AGENT": "Mozilla/5.0 (X11; U; Linux armv7l like Android; en-us) AppleWebKit/531.2+ (KHTML, like Gecko) Version/5.0 Safari/533.2+ Kindle/3.0+", "PATH_INFO": "/detail/26628819/", "REMOTE_HOST": null, "USER_IP": "127.0.0.1"}

2020-04-19 16:03:26,625:INFO:{"USER_AGENT": "Mozilla/5.0 (Linux; Android 10; MI 8 SE Build/QKQ1.190828.002; wv) AppleWebKit/537.36 (KHTML, like Gecko) Version/4.0 Chrome/79.0.3945.116 Mobile Safari/537.36 (#Build; Xiaomi; MI 8 SE; QKQ1.190828.002 test-keys; 10) +CoolMarket/10.0.4", "PATH_INFO": "/", "REMOTE_HOST": null, "USER_IP": "127.0.0.1"}

2020-04-19 16:03:31,189:INFO:{"USER_AGENT": "Mozilla/5.0 (Linux; U; Android 10; zh-CN; MI 8 SE Build/QKQ1.190828.002) AppleWebKit/537.36 (KHTML, like Gecko) Version/4.0 Chrome/57.0.2987.108 Quark/4.0.0.130 Mobile Safari/537.36", "PATH_INFO": "/", "REMOTE_HOST": null, "USER_IP": "14.18.19.237"}

2020-04-19 16:05:29,645:INFO:{"USER_AGENT": "Mozilla/5.0 (Windows NT 10.0; Win64; x64) AppleWebKit/537.36 (KHTML, like Gecko) Chrome/81.0.4044.113 Safari/537.36 Edg/81.0.416.58", "PATH_INFO": "/detail/26628819/", "REMOTE_HOST": null, "USER_IP": "127.0.0.1"}

2020-04-19 16:05:29,679:ERROR:Internal Server Error: /detail/26628819/
Traceback (most recent call last):
  File "/usr/local/lib/python3.6/dist-packages/django/core/handlers/exception.py", line 34, in inner
    response = get_response(request)
  File "/usr/local/lib/python3.6/dist-packages/django/core/handlers/base.py", line 115, in _get_response
    response = self.process_exception_by_middleware(e, request)
  File "/usr/local/lib/python3.6/dist-packages/django/core/handlers/base.py", line 113, in _get_response
    response = wrapped_callback(request, *callback_args, **callback_kwargs)
  File "/home/ubuntu/resourcesNet/book/views.py", line 64, in _log_record
    return func(*args,**kwargs)
  File "/home/ubuntu/resourcesNet/book/views.py", line 48, in _block_spider
    return func(*args, **kwargs)
  File "/home/ubuntu/resourcesNet/book/views.py", line 102, in detail
    b = Book.objects.get(douban_id=id)
  File "/usr/local/lib/python3.6/dist-packages/django/db/models/manager.py", line 82, in manager_method
    return getattr(self.get_queryset(), name)(*args, **kwargs)
  File "/usr/local/lib/python3.6/dist-packages/django/db/models/query.py", line 417, in get
    self.model._meta.object_name
book.models.Book.DoesNotExist: Book matching query does not exist.
2020-04-19 16:05:44,924:INFO:{"USER_AGENT": "Mozilla/5.0 (Windows NT 10.0; Win64; x64) AppleWebKit/537.36 (KHTML, like Gecko) Chrome/81.0.4044.113 Safari/537.36 Edg/81.0.416.58", "PATH_INFO": "/", "REMOTE_HOST": null, "USER_IP": "127.0.0.1"}

2020-04-19 16:07:09,733:INFO:{"USER_AGENT": "Mozilla/5.0 (Linux; U; Android 10; zh-CN; MI 8 SE Build/QKQ1.190828.002) AppleWebKit/537.36 (KHTML, like Gecko) Version/4.0 Chrome/57.0.2987.108 Quark/4.0.0.130 Mobile Safari/537.36", "PATH_INFO": "/", "REMOTE_HOST": null, "USER_IP": "127.0.0.1"}

2020-04-19 16:08:03,267:INFO:{"USER_AGENT": "Mozilla/5.0 (Windows NT 10.0; Win64; x64) AppleWebKit/537.36 (KHTML, like Gecko) Chrome/81.0.4044.113 Safari/537.36 Edg/81.0.416.58", "PATH_INFO": "/", "REMOTE_HOST": null, "USER_IP": "127.0.0.1"}

2020-04-19 16:08:12,173:INFO:{"USER_AGENT": "Mozilla/5.0 (Windows NT 10.0; Win64; x64) AppleWebKit/537.36 (KHTML, like Gecko) Chrome/81.0.4044.113 Safari/537.36 Edg/81.0.416.58", "PATH_INFO": "/detail/26628819/", "REMOTE_HOST": null, "USER_IP": "127.0.0.1"}

2020-04-19 16:08:59,290:INFO:{"USER_AGENT": "Mozilla/5.0 (X11; U; Linux armv7l like Android; en-us) AppleWebKit/531.2+ (KHTML, like Gecko) Version/5.0 Safari/533.2+ Kindle/3.0+", "PATH_INFO": "/", "REMOTE_HOST": null, "USER_IP": "127.0.0.1"}

2020-04-19 16:09:10,197:INFO:{"USER_AGENT": "Mozilla/5.0 (X11; U; Linux armv7l like Android; en-us) AppleWebKit/531.2+ (KHTML, like Gecko) Version/5.0 Safari/533.2+ Kindle/3.0+", "PATH_INFO": "/detail/26628819/", "REMOTE_HOST": null, "USER_IP": "127.0.0.1"}

2020-04-19 16:13:59,233:INFO:{"USER_AGENT": "Mozilla/5.0 (X11; U; Linux armv7l like Android; en-us) AppleWebKit/531.2+ (KHTML, like Gecko) Version/5.0 Safari/533.2+ Kindle/3.0+", "PATH_INFO": "/", "REMOTE_HOST": null, "USER_IP": "127.0.0.1"}

2020-04-19 16:14:24,896:INFO:{"USER_AGENT": "Mozilla/5.0 (X11; U; Linux armv7l like Android; en-us) AppleWebKit/531.2+ (KHTML, like Gecko) Version/5.0 Safari/533.2+ Kindle/3.0+", "PATH_INFO": "/detail/26628819/", "REMOTE_HOST": null, "USER_IP": "127.0.0.1"}

2020-04-19 16:19:43,126:INFO:{"USER_AGENT": "Mozilla/5.0 (Linux; Android 9; ONEPLUS A5000) AppleWebKit/537.36 (KHTML, like Gecko) Chrome/80.0.3987.162 Mobile Safari/537.36", "PATH_INFO": "/", "REMOTE_HOST": null, "USER_IP": "127.0.0.1"}

2020-04-19 16:20:39,027:INFO:{"USER_AGENT": "Mozilla/5.0 (Linux; Android 9; ONEPLUS A5000) AppleWebKit/537.36 (KHTML, like Gecko) Chrome/80.0.3987.162 Mobile Safari/537.36", "PATH_INFO": "/", "REMOTE_HOST": null, "USER_IP": "127.0.0.1"}

2020-04-19 16:20:51,176:INFO:{"USER_AGENT": "Mozilla/5.0 (Linux; Android 9; ONEPLUS A5000) AppleWebKit/537.36 (KHTML, like Gecko) Chrome/80.0.3987.162 Mobile Safari/537.36", "PATH_INFO": "/", "REMOTE_HOST": null, "USER_IP": "127.0.0.1"}

2020-04-19 16:20:51,219:ERROR:Internal Server Error: /
Traceback (most recent call last):
  File "/usr/local/lib/python3.6/dist-packages/django/core/handlers/exception.py", line 34, in inner
    response = get_response(request)
  File "/usr/local/lib/python3.6/dist-packages/django/core/handlers/base.py", line 115, in _get_response
    response = self.process_exception_by_middleware(e, request)
  File "/usr/local/lib/python3.6/dist-packages/django/core/handlers/base.py", line 113, in _get_response
    response = wrapped_callback(request, *callback_args, **callback_kwargs)
  File "/home/ubuntu/resourcesNet/book/views.py", line 64, in _log_record
    return func(*args,**kwargs)
  File "/home/ubuntu/resourcesNet/book/views.py", line 48, in _block_spider
    return func(*args, **kwargs)
  File "/home/ubuntu/resourcesNet/book/views.py", line 95, in index
    a = Book.objects.filter(book_name__icontains = search)
  File "/usr/local/lib/python3.6/dist-packages/django/db/models/manager.py", line 82, in manager_method
    return getattr(self.get_queryset(), name)(*args, **kwargs)
  File "/usr/local/lib/python3.6/dist-packages/django/db/models/query.py", line 904, in filter
    return self._filter_or_exclude(False, *args, **kwargs)
  File "/usr/local/lib/python3.6/dist-packages/django/db/models/query.py", line 923, in _filter_or_exclude
    clone.query.add_q(Q(*args, **kwargs))
  File "/usr/local/lib/python3.6/dist-packages/django/db/models/sql/query.py", line 1350, in add_q
    clause, _ = self._add_q(q_object, self.used_aliases)
  File "/usr/local/lib/python3.6/dist-packages/django/db/models/sql/query.py", line 1381, in _add_q
    check_filterable=check_filterable,
  File "/usr/local/lib/python3.6/dist-packages/django/db/models/sql/query.py", line 1250, in build_filter
    lookups, parts, reffed_expression = self.solve_lookup_type(arg)
  File "/usr/local/lib/python3.6/dist-packages/django/db/models/sql/query.py", line 1087, in solve_lookup_type
    _, field, _, lookup_parts = self.names_to_path(lookup_splitted, self.get_meta())
  File "/usr/local/lib/python3.6/dist-packages/django/db/models/sql/query.py", line 1483, in names_to_path
    "Choices are: %s" % (name, ", ".join(available)))
django.core.exceptions.FieldError: Cannot resolve keyword 'book_name' into field. Choices are: author, author_book, azw3_download, azw3_flag, catalog, cover, date, douban_id, english_title, epub_download, epub_flag, file_name, id, isbn10, isbn13, kfx_download, kfx_flag, large_cover, mobi_download, mobi_flag, pages, pdf_download, pdf_flag, price, publisher, publisher_book, series, series_book, subtitle, summary, tag_book, tags, title, translator, translator_book, true_douban_id
2020-04-19 16:21:10,044:INFO:{"USER_AGENT": "Mozilla/5.0 (Linux; Android 9; ONEPLUS A5000) AppleWebKit/537.36 (KHTML, like Gecko) Chrome/80.0.3987.162 Mobile Safari/537.36", "PATH_INFO": "/", "REMOTE_HOST": null, "USER_IP": "127.0.0.1"}

2020-04-19 16:21:10,087:ERROR:Internal Server Error: /
Traceback (most recent call last):
  File "/usr/local/lib/python3.6/dist-packages/django/core/handlers/exception.py", line 34, in inner
    response = get_response(request)
  File "/usr/local/lib/python3.6/dist-packages/django/core/handlers/base.py", line 115, in _get_response
    response = self.process_exception_by_middleware(e, request)
  File "/usr/local/lib/python3.6/dist-packages/django/core/handlers/base.py", line 113, in _get_response
    response = wrapped_callback(request, *callback_args, **callback_kwargs)
  File "/home/ubuntu/resourcesNet/book/views.py", line 64, in _log_record
    return func(*args,**kwargs)
  File "/home/ubuntu/resourcesNet/book/views.py", line 48, in _block_spider
    return func(*args, **kwargs)
  File "/home/ubuntu/resourcesNet/book/views.py", line 95, in index
    a = Book.objects.filter(book_name__icontains = search)
  File "/usr/local/lib/python3.6/dist-packages/django/db/models/manager.py", line 82, in manager_method
    return getattr(self.get_queryset(), name)(*args, **kwargs)
  File "/usr/local/lib/python3.6/dist-packages/django/db/models/query.py", line 904, in filter
    return self._filter_or_exclude(False, *args, **kwargs)
  File "/usr/local/lib/python3.6/dist-packages/django/db/models/query.py", line 923, in _filter_or_exclude
    clone.query.add_q(Q(*args, **kwargs))
  File "/usr/local/lib/python3.6/dist-packages/django/db/models/sql/query.py", line 1350, in add_q
    clause, _ = self._add_q(q_object, self.used_aliases)
  File "/usr/local/lib/python3.6/dist-packages/django/db/models/sql/query.py", line 1381, in _add_q
    check_filterable=check_filterable,
  File "/usr/local/lib/python3.6/dist-packages/django/db/models/sql/query.py", line 1250, in build_filter
    lookups, parts, reffed_expression = self.solve_lookup_type(arg)
  File "/usr/local/lib/python3.6/dist-packages/django/db/models/sql/query.py", line 1087, in solve_lookup_type
    _, field, _, lookup_parts = self.names_to_path(lookup_splitted, self.get_meta())
  File "/usr/local/lib/python3.6/dist-packages/django/db/models/sql/query.py", line 1483, in names_to_path
    "Choices are: %s" % (name, ", ".join(available)))
django.core.exceptions.FieldError: Cannot resolve keyword 'book_name' into field. Choices are: author, author_book, azw3_download, azw3_flag, catalog, cover, date, douban_id, english_title, epub_download, epub_flag, file_name, id, isbn10, isbn13, kfx_download, kfx_flag, large_cover, mobi_download, mobi_flag, pages, pdf_download, pdf_flag, price, publisher, publisher_book, series, series_book, subtitle, summary, tag_book, tags, title, translator, translator_book, true_douban_id
2020-04-19 16:23:07,864:INFO:{"USER_AGENT": "Mozilla/5.0 (Windows NT 10.0; WOW64) AppleWebKit/537.36 (KHTML, like Gecko) Chrome/51.0.2704.103 Safari/537.36", "PATH_INFO": "/", "REMOTE_HOST": null, "USER_IP": "127.0.0.1"}

2020-04-19 16:23:54,178:INFO:{"USER_AGENT": "Mozilla/5.0 (Windows NT 10.0; Win64; x64) AppleWebKit/537.36 (KHTML, like Gecko) Chrome/81.0.4044.92 Safari/537.36 Edg/81.0.416.53", "PATH_INFO": "/", "REMOTE_HOST": null, "USER_IP": "127.0.0.1"}

2020-04-19 16:23:58,856:INFO:{"USER_AGENT": "Mozilla/5.0 (Windows NT 10.0; Win64; x64) AppleWebKit/537.36 (KHTML, like Gecko) Chrome/81.0.4044.92 Safari/537.36 Edg/81.0.416.53", "PATH_INFO": "/detail/26628819/", "REMOTE_HOST": null, "USER_IP": "127.0.0.1"}

2020-04-19 16:27:58,393:INFO:{"USER_AGENT": "Mozilla/5.0 (Windows NT 10.0; Win64; x64) AppleWebKit/537.36 (KHTML, like Gecko) Chrome/81.0.4044.92 Safari/537.36 Edg/81.0.416.53", "PATH_INFO": "/", "REMOTE_HOST": null, "USER_IP": "127.0.0.1"}

2020-04-19 16:28:37,637:INFO:{"USER_AGENT": "Mozilla/5.0 (Linux; Android 10; Redmi K20 Pro Build/QKQ1.190825.002; wv) AppleWebKit/537.36 (KHTML, like Gecko) Version/4.0 Chrome/80.0.3987.162 Mobile Safari/537.36 (#Build; Xiaomi; Redmi K20 Pro; QKQ1.190825.002 test-keys; 10) +CoolMarket/10.0.4", "PATH_INFO": "/", "REMOTE_HOST": null, "USER_IP": "127.0.0.1"}

2020-04-19 16:28:46,625:INFO:{"USER_AGENT": "Mozilla/5.0 (Linux; Android 10; Redmi K20 Pro Build/QKQ1.190825.002; wv) AppleWebKit/537.36 (KHTML, like Gecko) Version/4.0 Chrome/80.0.3987.162 Mobile Safari/537.36 (#Build; Xiaomi; Redmi K20 Pro; QKQ1.190825.002 test-keys; 10) +CoolMarket/10.0.4", "PATH_INFO": "/about/", "REMOTE_HOST": null, "USER_IP": "127.0.0.1"}

2020-04-19 16:29:06,201:INFO:{"USER_AGENT": "Mozilla/5.0 (Linux; Android 10; Redmi K20 Pro Build/QKQ1.190825.002; wv) AppleWebKit/537.36 (KHTML, like Gecko) Version/4.0 Chrome/80.0.3987.162 Mobile Safari/537.36 (#Build; Xiaomi; Redmi K20 Pro; QKQ1.190825.002 test-keys; 10) +CoolMarket/10.0.4", "PATH_INFO": "/", "REMOTE_HOST": null, "USER_IP": "127.0.0.1"}

2020-04-19 16:29:13,796:INFO:{"USER_AGENT": "Mozilla/5.0 (Linux; Android 10; Redmi K20 Pro Build/QKQ1.190825.002; wv) AppleWebKit/537.36 (KHTML, like Gecko) Version/4.0 Chrome/80.0.3987.162 Mobile Safari/537.36 (#Build; Xiaomi; Redmi K20 Pro; QKQ1.190825.002 test-keys; 10) +CoolMarket/10.0.4", "PATH_INFO": "/", "REMOTE_HOST": null, "USER_IP": "127.0.0.1"}

2020-04-19 16:29:13,838:ERROR:Internal Server Error: /
Traceback (most recent call last):
  File "/usr/local/lib/python3.6/dist-packages/django/core/handlers/exception.py", line 34, in inner
    response = get_response(request)
  File "/usr/local/lib/python3.6/dist-packages/django/core/handlers/base.py", line 115, in _get_response
    response = self.process_exception_by_middleware(e, request)
  File "/usr/local/lib/python3.6/dist-packages/django/core/handlers/base.py", line 113, in _get_response
    response = wrapped_callback(request, *callback_args, **callback_kwargs)
  File "/home/ubuntu/resourcesNet/book/views.py", line 64, in _log_record
    return func(*args,**kwargs)
  File "/home/ubuntu/resourcesNet/book/views.py", line 48, in _block_spider
    return func(*args, **kwargs)
  File "/home/ubuntu/resourcesNet/book/views.py", line 95, in index
    a = Book.objects.filter(book_name__icontains = search)
  File "/usr/local/lib/python3.6/dist-packages/django/db/models/manager.py", line 82, in manager_method
    return getattr(self.get_queryset(), name)(*args, **kwargs)
  File "/usr/local/lib/python3.6/dist-packages/django/db/models/query.py", line 904, in filter
    return self._filter_or_exclude(False, *args, **kwargs)
  File "/usr/local/lib/python3.6/dist-packages/django/db/models/query.py", line 923, in _filter_or_exclude
    clone.query.add_q(Q(*args, **kwargs))
  File "/usr/local/lib/python3.6/dist-packages/django/db/models/sql/query.py", line 1350, in add_q
    clause, _ = self._add_q(q_object, self.used_aliases)
  File "/usr/local/lib/python3.6/dist-packages/django/db/models/sql/query.py", line 1381, in _add_q
    check_filterable=check_filterable,
  File "/usr/local/lib/python3.6/dist-packages/django/db/models/sql/query.py", line 1250, in build_filter
    lookups, parts, reffed_expression = self.solve_lookup_type(arg)
  File "/usr/local/lib/python3.6/dist-packages/django/db/models/sql/query.py", line 1087, in solve_lookup_type
    _, field, _, lookup_parts = self.names_to_path(lookup_splitted, self.get_meta())
  File "/usr/local/lib/python3.6/dist-packages/django/db/models/sql/query.py", line 1483, in names_to_path
    "Choices are: %s" % (name, ", ".join(available)))
django.core.exceptions.FieldError: Cannot resolve keyword 'book_name' into field. Choices are: author, author_book, azw3_download, azw3_flag, catalog, cover, date, douban_id, english_title, epub_download, epub_flag, file_name, id, isbn10, isbn13, kfx_download, kfx_flag, large_cover, mobi_download, mobi_flag, pages, pdf_download, pdf_flag, price, publisher, publisher_book, series, series_book, subtitle, summary, tag_book, tags, title, translator, translator_book, true_douban_id
2020-04-19 16:29:15,260:WARNING:Not Found: /favicon.ico
2020-04-19 16:29:17,720:INFO:{"USER_AGENT": "Mozilla/5.0 (Linux; Android 10; Redmi K20 Pro Build/QKQ1.190825.002; wv) AppleWebKit/537.36 (KHTML, like Gecko) Version/4.0 Chrome/80.0.3987.162 Mobile Safari/537.36 (#Build; Xiaomi; Redmi K20 Pro; QKQ1.190825.002 test-keys; 10) +CoolMarket/10.0.4", "PATH_INFO": "/detail/26628819/", "REMOTE_HOST": null, "USER_IP": "127.0.0.1"}

2020-04-19 16:29:29,007:INFO:{"USER_AGENT": "Mozilla/5.0 (Windows NT 10.0; Win64; x64) AppleWebKit/537.36 (KHTML, like Gecko) Chrome/81.0.4044.92 Safari/537.36 Edg/81.0.416.53", "PATH_INFO": "/detail/26628819/", "REMOTE_HOST": null, "USER_IP": "127.0.0.1"}

2020-04-19 16:33:23,166:INFO:{"USER_AGENT": "Mozilla/5.0 (Linux; Android 10; MI 8 Lite) AppleWebKit/537.36 (KHTML, like Gecko) Chrome/77.0.3865.116 Mobile Safari/537.36 EdgA/45.02.4.4931", "PATH_INFO": "/", "REMOTE_HOST": null, "USER_IP": "127.0.0.1"}

2020-04-19 16:33:31,298:INFO:{"USER_AGENT": "Mozilla/5.0 (Linux; Android 10; MI 8 Lite) AppleWebKit/537.36 (KHTML, like Gecko) Chrome/77.0.3865.116 Mobile Safari/537.36 EdgA/45.02.4.4931", "PATH_INFO": "/detail/26628819/", "REMOTE_HOST": null, "USER_IP": "127.0.0.1"}

2020-04-19 16:41:36,679:INFO:{"USER_AGENT": "Mozilla/5.0 (X11; U; Linux armv7l like Android; en-us) AppleWebKit/531.2+ (KHTML, like Gecko) Version/5.0 Safari/533.2+ Kindle/3.0+", "PATH_INFO": "/", "REMOTE_HOST": null, "USER_IP": "127.0.0.1"}

2020-04-19 16:41:43,123:INFO:{"USER_AGENT": "Mozilla/5.0 (X11; U; Linux armv7l like Android; en-us) AppleWebKit/531.2+ (KHTML, like Gecko) Version/5.0 Safari/533.2+ Kindle/3.0+", "PATH_INFO": "/detail/26628819/", "REMOTE_HOST": null, "USER_IP": "127.0.0.1"}

2020-04-19 16:42:06,829:INFO:{"USER_AGENT": "Mozilla/5.0 (Windows NT 10.0; WOW64) AppleWebKit/537.36 (KHTML, like Gecko) Chrome/52.0.2743.116 Safari/537.36", "PATH_INFO": "/", "REMOTE_HOST": null, "USER_IP": "127.0.0.1"}

2020-04-19 16:42:21,609:INFO:{"USER_AGENT": "Mozilla/5.0 (X11; U; Linux armv7l like Android; en-us) AppleWebKit/531.2+ (KHTML, like Gecko) Version/5.0 Safari/533.2+ Kindle/3.0+", "PATH_INFO": "/detail/26628819/", "REMOTE_HOST": null, "USER_IP": "127.0.0.1"}

2020-04-19 16:42:41,487:INFO:{"USER_AGENT": "Mozilla/5.0 (Linux; Android 10; HLK-AL00 Build/HONORHLK-AL00; wv) AppleWebKit/537.36 (KHTML, like Gecko) Version/4.0 Chrome/70.0.3538.64 Mobile Safari/537.36 (#Build; HONOR; HLK-AL00; HLK-AL00 10.0.1.120(C00E120R5P2); 10) +CoolMarket/10.0.4", "PATH_INFO": "/", "REMOTE_HOST": null, "USER_IP": "127.0.0.1"}

2020-04-19 16:42:53,656:INFO:{"USER_AGENT": "Mozilla/5.0 (Linux; Android 10; HLK-AL00 Build/HONORHLK-AL00; wv) AppleWebKit/537.36 (KHTML, like Gecko) Version/4.0 Chrome/70.0.3538.64 Mobile Safari/537.36 (#Build; HONOR; HLK-AL00; HLK-AL00 10.0.1.120(C00E120R5P2); 10) +CoolMarket/10.0.4", "PATH_INFO": "/", "REMOTE_HOST": null, "USER_IP": "127.0.0.1"}

2020-04-19 16:51:34,797:INFO:{"USER_AGENT": "Mozilla/5.0 (X11; U; Linux armv7l like Android; en-us) AppleWebKit/531.2+ (KHTML, like Gecko) Version/5.0 Safari/533.2+ Kindle/3.0+", "PATH_INFO": "/", "REMOTE_HOST": null, "USER_IP": "127.0.0.1"}

2020-04-19 16:52:01,507:INFO:{"USER_AGENT": "Mozilla/5.0 (X11; U; Linux armv7l like Android; en-us) AppleWebKit/531.2+ (KHTML, like Gecko) Version/5.0 Safari/533.2+ Kindle/3.0+", "PATH_INFO": "/detail/26628819/", "REMOTE_HOST": null, "USER_IP": "127.0.0.1"}

2020-04-19 16:57:44,689:INFO:{"USER_AGENT": "Mozilla/5.0 (Linux; Android 10; MI 8 Build/QKQ1.190828.002; wv) AppleWebKit/537.36 (KHTML, like Gecko) Version/4.0 Chrome/80.0.3987.99 Mobile Safari/537.36 (#Build; Xiaomi; MI 8; QKQ1.190828.002 test-keys; 10) +CoolMarket/10.0.4", "PATH_INFO": "/", "REMOTE_HOST": null, "USER_IP": "127.0.0.1"}

2020-04-19 16:57:52,223:INFO:{"USER_AGENT": "Mozilla/5.0 (Linux; U; Android 10; zh-cn; MI 8 Build/QKQ1.190828.002) AppleWebKit/537.36 (KHTML, like Gecko) Version/4.0 Chrome/71.0.3578.141 Mobile Safari/537.36 XiaoMi/MiuiBrowser/11.10.24", "PATH_INFO": "/", "REMOTE_HOST": null, "USER_IP": "127.0.0.1"}

2020-04-19 16:57:53,927:INFO:{"USER_AGENT": "Mozilla/5.0 (Windows NT 10.0; Win64; x64) AppleWebKit/537.36 (KHTML, like Gecko) Chrome/46.0.2486.0 Safari/537.36 Edge/13.10586", "PATH_INFO": "/", "REMOTE_HOST": null, "USER_IP": "127.0.0.1"}

2020-04-19 16:57:55,461:INFO:{"USER_AGENT": "Mozilla/5.0 (Windows NT 10.0; Win64; x64) AppleWebKit/537.36 (KHTML, like Gecko) Chrome/46.0.2486.0 Safari/537.36 Edge/13.10586", "PATH_INFO": "/detail/26628819/", "REMOTE_HOST": null, "USER_IP": "127.0.0.1"}

2020-04-19 16:57:56,502:INFO:{"USER_AGENT": "Mozilla/5.0 (Windows NT 10.0; Win64; x64) AppleWebKit/537.36 (KHTML, like Gecko) Chrome/46.0.2486.0 Safari/537.36 Edge/13.10586", "PATH_INFO": "/about/", "REMOTE_HOST": null, "USER_IP": "127.0.0.1"}

2020-04-19 16:58:32,062:INFO:{"USER_AGENT": "Mozilla/5.0 (Linux; Android 10; MI 9 Build/QKQ1.190825.002; wv) AppleWebKit/537.36 (KHTML, like Gecko) Version/4.0 Chrome/80.0.3987.149 Mobile Safari/537.36 (#Build; Xiaomi; MI 9; QKQ1.190825.002 test-keys; 10) +CoolMarket/10.0.4", "PATH_INFO": "/", "REMOTE_HOST": null, "USER_IP": "127.0.0.1"}

2020-04-19 16:58:37,454:INFO:{"USER_AGENT": "Mozilla/5.0 (Linux; Android 10; MI 9 Build/QKQ1.190825.002; wv) AppleWebKit/537.36 (KHTML, like Gecko) Version/4.0 Chrome/80.0.3987.149 Mobile Safari/537.36 (#Build; Xiaomi; MI 9; QKQ1.190825.002 test-keys; 10) +CoolMarket/10.0.4", "PATH_INFO": "/detail/26628819/", "REMOTE_HOST": null, "USER_IP": "127.0.0.1"}

2020-04-19 16:58:49,917:INFO:{"USER_AGENT": "Mozilla/5.0 (Linux; U; Android 10; zh-CN; MI 9 Build/QKQ1.190825.002) AppleWebKit/537.36 (KHTML, like Gecko) Version/4.0 Chrome/57.0.2987.108 Quark/4.0.0.130 Mobile Safari/537.36", "PATH_INFO": "/detail/26628819/", "REMOTE_HOST": null, "USER_IP": "27.204.110.160"}

2020-04-19 16:59:19,611:INFO:{"USER_AGENT": "Mozilla/5.0 (Linux; Android 10; MI 9 Build/QKQ1.190825.002; wv) AppleWebKit/537.36 (KHTML, like Gecko) Version/4.0 Chrome/80.0.3987.149 Mobile Safari/537.36 (#Build; Xiaomi; MI 9; QKQ1.190825.002 test-keys; 10) +CoolMarket/10.0.4", "PATH_INFO": "/", "REMOTE_HOST": null, "USER_IP": "127.0.0.1"}

2020-04-19 17:04:27,505:INFO:{"USER_AGENT": "Mozilla/5.0 (X11; U; Linux armv7l like Android; en-us) AppleWebKit/531.2+ (KHTML, like Gecko) Version/5.0 Safari/533.2+ Kindle/3.0+", "PATH_INFO": "/", "REMOTE_HOST": null, "USER_IP": "127.0.0.1"}

2020-04-19 17:04:42,614:INFO:{"USER_AGENT": "Mozilla/5.0 (X11; U; Linux armv7l like Android; en-us) AppleWebKit/531.2+ (KHTML, like Gecko) Version/5.0 Safari/533.2+ Kindle/3.0+", "PATH_INFO": "/detail/26628819/", "REMOTE_HOST": null, "USER_IP": "127.0.0.1"}

2020-04-19 17:14:31,808:INFO:{"USER_AGENT": "Mozilla/5.0 (X11; U; Linux armv7l like Android; en-us) AppleWebKit/531.2+ (KHTML, like Gecko) Version/5.0 Safari/533.2+ Kindle/3.0+", "PATH_INFO": "/", "REMOTE_HOST": null, "USER_IP": "127.0.0.1"}

2020-04-19 17:14:41,529:INFO:{"USER_AGENT": "Mozilla/5.0 (X11; U; Linux armv7l like Android; en-us) AppleWebKit/531.2+ (KHTML, like Gecko) Version/5.0 Safari/533.2+ Kindle/3.0+", "PATH_INFO": "/detail/26628819/", "REMOTE_HOST": null, "USER_IP": "127.0.0.1"}

2020-04-19 17:14:48,886:INFO:{"USER_AGENT": "Mozilla/5.0 (Linux; Android 10; V1824A) AppleWebKit/537.36 (KHTML, like Gecko) Chrome/81.0.4044.111 Mobile Safari/537.36", "PATH_INFO": "/", "REMOTE_HOST": null, "USER_IP": "127.0.0.1"}

2020-04-19 17:14:57,523:INFO:{"USER_AGENT": "Mozilla/5.0 (Linux; Android 10; V1824A) AppleWebKit/537.36 (KHTML, like Gecko) Chrome/81.0.4044.111 Mobile Safari/537.36", "PATH_INFO": "/", "REMOTE_HOST": null, "USER_IP": "127.0.0.1"}

2020-04-19 17:31:53,688:INFO:{"USER_AGENT": "Mozilla/5.0 (Windows NT 10.0; WOW64) AppleWebKit/537.36 (KHTML, like Gecko) Chrome/52.0.2743.116 Safari/537.36", "PATH_INFO": "/", "REMOTE_HOST": null, "USER_IP": "127.0.0.1"}

2020-04-19 17:37:07,472:INFO:{"USER_AGENT": "Mozilla/5.0 (Linux; Android 10; TNY-AL00 Build/HUAWEITNY-AL00; wv) AppleWebKit/537.36 (KHTML, like Gecko) Version/4.0 Chrome/74.0.3729.186 Mobile Safari/537.36 (#Build; HONOR; TNY-AL00; TNY-AL00 10.0.0.189(C00E63R2P11); 10) +CoolMarket/10.0.4", "PATH_INFO": "/", "REMOTE_HOST": null, "USER_IP": "127.0.0.1"}

2020-04-19 17:53:45,253:INFO:{"USER_AGENT": "Mozilla/5.0 (Linux; Android 10; CLT-TL00 Build/HUAWEICLT-TL00; wv) AppleWebKit/537.36 (KHTML, like Gecko) Version/4.0 Chrome/79.0.3945.116 Mobile Safari/537.36 (#Build; HUAWEI; CLT-TL00; CLT-TL00 10.0.0.162(C01E156R1P4); 10) +CoolMarket/10.0.4", "PATH_INFO": "/", "REMOTE_HOST": null, "USER_IP": "127.0.0.1"}

2020-04-19 18:07:50,086:INFO:{"USER_AGENT": "Mozilla/5.0 (Windows NT 10.0; Win64; x64) AppleWebKit/537.36 (KHTML, like Gecko) Chrome/81.0.4044.113 Safari/537.36 Edg/81.0.416.58", "PATH_INFO": "/detail/26628819/", "REMOTE_HOST": null, "USER_IP": "127.0.0.1"}

2020-04-19 18:08:14,591:INFO:{"USER_AGENT": "Mozilla/5.0 (X11; U; Linux armv7l like Android; en-us) AppleWebKit/531.2+ (KHTML, like Gecko) Version/5.0 Safari/533.2+ Kindle/3.0+", "PATH_INFO": "/", "REMOTE_HOST": null, "USER_IP": "127.0.0.1"}

2020-04-19 18:08:58,629:INFO:{"USER_AGENT": "Mozilla/5.0 (X11; U; Linux armv7l like Android; en-us) AppleWebKit/531.2+ (KHTML, like Gecko) Version/5.0 Safari/533.2+ Kindle/3.0+", "PATH_INFO": "/detail/26628819/", "REMOTE_HOST": null, "USER_IP": "127.0.0.1"}

2020-04-19 18:21:51,173:INFO:{"USER_AGENT": "Mozilla/5.0 (Windows NT 10.0; Win64; x64) AppleWebKit/537.36 (KHTML, like Gecko) Chrome/81.0.4044.113 Safari/537.36 Edg/81.0.416.58", "PATH_INFO": "/detail/26628819/", "REMOTE_HOST": null, "USER_IP": "127.0.0.1"}

2020-04-19 18:22:00,334:INFO:{"USER_AGENT": "Mozilla/5.0 (Windows NT 10.0; Win64; x64) AppleWebKit/537.36 (KHTML, like Gecko) Chrome/81.0.4044.113 Safari/537.36 Edg/81.0.416.58", "PATH_INFO": "/", "REMOTE_HOST": null, "USER_IP": "127.0.0.1"}

2020-04-19 18:23:49,329:INFO:{"USER_AGENT": "Mozilla/5.0 (Windows NT 10.0; Win64; x64) AppleWebKit/537.36 (KHTML, like Gecko) Chrome/81.0.4044.113 Safari/537.36 Edg/81.0.416.58", "PATH_INFO": "/", "REMOTE_HOST": null, "USER_IP": "127.0.0.1"}

2020-04-19 18:23:52,027:INFO:{"USER_AGENT": "Mozilla/5.0 (Windows NT 10.0; Win64; x64) AppleWebKit/537.36 (KHTML, like Gecko) Chrome/81.0.4044.113 Safari/537.36 Edg/81.0.416.58", "PATH_INFO": "/detail/10471333/", "REMOTE_HOST": null, "USER_IP": "127.0.0.1"}

2020-04-19 18:27:20,157:INFO:{"USER_AGENT": "Mozilla/5.0 (Windows NT 10.0; Win64; x64) AppleWebKit/537.36 (KHTML, like Gecko) Chrome/81.0.4044.113 Safari/537.36 Edg/81.0.416.58", "PATH_INFO": "/", "REMOTE_HOST": null, "USER_IP": "127.0.0.1"}

2020-04-19 18:28:06,022:INFO:{"USER_AGENT": "Mozilla/5.0 (Linux; Android 10; MI 8 Lite Build/QKQ1.190910.002; wv) AppleWebKit/537.36 (KHTML, like Gecko) Version/4.0 Chrome/78.0.3904.96 Mobile Safari/537.36 (#Build; Xiaomi; MI 8 Lite; QKQ1.190910.002 test-keys; 10) +CoolMarket/10.0.4", "PATH_INFO": "/", "REMOTE_HOST": null, "USER_IP": "127.0.0.1"}

2020-04-19 19:05:27,918:INFO:{"USER_AGENT": "Mozilla/5.0 (Linux; Android 10; MIX 2S Build/QKQ1.190828.002; wv) AppleWebKit/537.36 (KHTML, like Gecko) Version/4.0 Chrome/80.0.3987.162 Mobile Safari/537.36 (#Build; Xiaomi; MIX 2S; QKQ1.190828.002 test-keys; 10) +CoolMarket/10.0.4", "PATH_INFO": "/", "REMOTE_HOST": null, "USER_IP": "127.0.0.1"}

2020-04-19 19:31:21,276:INFO:{"USER_AGENT": "Mozilla/5.0 (Windows NT 10.0; Win64; x64) AppleWebKit/537.36 (KHTML, like Gecko) Chrome/81.0.4044.113 Safari/537.36 Edg/81.0.416.58", "PATH_INFO": "/", "REMOTE_HOST": null, "USER_IP": "127.0.0.1"}

2020-04-19 19:35:52,230:INFO:{"USER_AGENT": "Mozilla/5.0 (Windows NT 10.0; Win64; x64) AppleWebKit/537.36 (KHTML, like Gecko) Chrome/81.0.4044.113 Safari/537.36 Edg/81.0.416.58", "PATH_INFO": "/", "REMOTE_HOST": null, "USER_IP": "127.0.0.1"}

2020-04-19 19:42:22,903:INFO:{"USER_AGENT": "Mozilla/5.0 (Windows NT 10.0; Win64; x64) AppleWebKit/537.36 (KHTML, like Gecko) Chrome/81.0.4044.113 Safari/537.36 Edg/81.0.416.58", "PATH_INFO": "/", "REMOTE_HOST": null, "USER_IP": "127.0.0.1"}

2020-04-19 19:44:44,865:INFO:{"USER_AGENT": "Mozilla/5.0 (Linux; Android 10; ONEPLUS A6000) AppleWebKit/537.36 (KHTML, like Gecko) Chrome/80.0.3987.162 Mobile Safari/537.36", "PATH_INFO": "/", "REMOTE_HOST": null, "USER_IP": "127.0.0.1"}

2020-04-19 19:44:53,883:INFO:{"USER_AGENT": "Mozilla/5.0 (Linux; Android 10; ONEPLUS A6000) AppleWebKit/537.36 (KHTML, like Gecko) Chrome/80.0.3987.162 Mobile Safari/537.36", "PATH_INFO": "/", "REMOTE_HOST": null, "USER_IP": "127.0.0.1"}

2020-04-19 19:45:04,922:INFO:{"USER_AGENT": "Mozilla/5.0 (Linux; Android 10; ONEPLUS A6000) AppleWebKit/537.36 (KHTML, like Gecko) Chrome/80.0.3987.162 Mobile Safari/537.36", "PATH_INFO": "/", "REMOTE_HOST": null, "USER_IP": "127.0.0.1"}

2020-04-19 19:45:04,967:ERROR:Internal Server Error: /
Traceback (most recent call last):
  File "/usr/local/lib/python3.6/dist-packages/django/core/handlers/exception.py", line 34, in inner
    response = get_response(request)
  File "/usr/local/lib/python3.6/dist-packages/django/core/handlers/base.py", line 115, in _get_response
    response = self.process_exception_by_middleware(e, request)
  File "/usr/local/lib/python3.6/dist-packages/django/core/handlers/base.py", line 113, in _get_response
    response = wrapped_callback(request, *callback_args, **callback_kwargs)
  File "/home/ubuntu/resourcesNet/book/views.py", line 64, in _log_record
    return func(*args,**kwargs)
  File "/home/ubuntu/resourcesNet/book/views.py", line 48, in _block_spider
    return func(*args, **kwargs)
  File "/home/ubuntu/resourcesNet/book/views.py", line 95, in index
    a = Book.objects.filter(book_name__icontains = search)
  File "/usr/local/lib/python3.6/dist-packages/django/db/models/manager.py", line 82, in manager_method
    return getattr(self.get_queryset(), name)(*args, **kwargs)
  File "/usr/local/lib/python3.6/dist-packages/django/db/models/query.py", line 904, in filter
    return self._filter_or_exclude(False, *args, **kwargs)
  File "/usr/local/lib/python3.6/dist-packages/django/db/models/query.py", line 923, in _filter_or_exclude
    clone.query.add_q(Q(*args, **kwargs))
  File "/usr/local/lib/python3.6/dist-packages/django/db/models/sql/query.py", line 1350, in add_q
    clause, _ = self._add_q(q_object, self.used_aliases)
  File "/usr/local/lib/python3.6/dist-packages/django/db/models/sql/query.py", line 1381, in _add_q
    check_filterable=check_filterable,
  File "/usr/local/lib/python3.6/dist-packages/django/db/models/sql/query.py", line 1250, in build_filter
    lookups, parts, reffed_expression = self.solve_lookup_type(arg)
  File "/usr/local/lib/python3.6/dist-packages/django/db/models/sql/query.py", line 1087, in solve_lookup_type
    _, field, _, lookup_parts = self.names_to_path(lookup_splitted, self.get_meta())
  File "/usr/local/lib/python3.6/dist-packages/django/db/models/sql/query.py", line 1483, in names_to_path
    "Choices are: %s" % (name, ", ".join(available)))
django.core.exceptions.FieldError: Cannot resolve keyword 'book_name' into field. Choices are: author, author_book, azw3_download, azw3_flag, catalog, cover, date, douban_id, english_title, epub_download, epub_flag, file_name, id, isbn10, isbn13, kfx_download, kfx_flag, large_cover, mobi_download, mobi_flag, pages, pdf_download, pdf_flag, price, publisher, publisher_book, series, series_book, subtitle, summary, tag_book, tags, title, translator, translator_book, true_douban_id
2020-04-19 19:45:05,282:INFO:{"USER_AGENT": "Mozilla/5.0 (Linux; Android 10; ONEPLUS A6000) AppleWebKit/537.36 (KHTML, like Gecko) Chrome/80.0.3987.162 Mobile Safari/537.36", "PATH_INFO": "/", "REMOTE_HOST": null, "USER_IP": "127.0.0.1"}

2020-04-19 19:45:05,325:ERROR:Internal Server Error: /
Traceback (most recent call last):
  File "/usr/local/lib/python3.6/dist-packages/django/core/handlers/exception.py", line 34, in inner
    response = get_response(request)
  File "/usr/local/lib/python3.6/dist-packages/django/core/handlers/base.py", line 115, in _get_response
    response = self.process_exception_by_middleware(e, request)
  File "/usr/local/lib/python3.6/dist-packages/django/core/handlers/base.py", line 113, in _get_response
    response = wrapped_callback(request, *callback_args, **callback_kwargs)
  File "/home/ubuntu/resourcesNet/book/views.py", line 64, in _log_record
    return func(*args,**kwargs)
  File "/home/ubuntu/resourcesNet/book/views.py", line 48, in _block_spider
    return func(*args, **kwargs)
  File "/home/ubuntu/resourcesNet/book/views.py", line 95, in index
    a = Book.objects.filter(book_name__icontains = search)
  File "/usr/local/lib/python3.6/dist-packages/django/db/models/manager.py", line 82, in manager_method
    return getattr(self.get_queryset(), name)(*args, **kwargs)
  File "/usr/local/lib/python3.6/dist-packages/django/db/models/query.py", line 904, in filter
    return self._filter_or_exclude(False, *args, **kwargs)
  File "/usr/local/lib/python3.6/dist-packages/django/db/models/query.py", line 923, in _filter_or_exclude
    clone.query.add_q(Q(*args, **kwargs))
  File "/usr/local/lib/python3.6/dist-packages/django/db/models/sql/query.py", line 1350, in add_q
    clause, _ = self._add_q(q_object, self.used_aliases)
  File "/usr/local/lib/python3.6/dist-packages/django/db/models/sql/query.py", line 1381, in _add_q
    check_filterable=check_filterable,
  File "/usr/local/lib/python3.6/dist-packages/django/db/models/sql/query.py", line 1250, in build_filter
    lookups, parts, reffed_expression = self.solve_lookup_type(arg)
  File "/usr/local/lib/python3.6/dist-packages/django/db/models/sql/query.py", line 1087, in solve_lookup_type
    _, field, _, lookup_parts = self.names_to_path(lookup_splitted, self.get_meta())
  File "/usr/local/lib/python3.6/dist-packages/django/db/models/sql/query.py", line 1483, in names_to_path
    "Choices are: %s" % (name, ", ".join(available)))
django.core.exceptions.FieldError: Cannot resolve keyword 'book_name' into field. Choices are: author, author_book, azw3_download, azw3_flag, catalog, cover, date, douban_id, english_title, epub_download, epub_flag, file_name, id, isbn10, isbn13, kfx_download, kfx_flag, large_cover, mobi_download, mobi_flag, pages, pdf_download, pdf_flag, price, publisher, publisher_book, series, series_book, subtitle, summary, tag_book, tags, title, translator, translator_book, true_douban_id
2020-04-19 19:45:16,793:INFO:{"USER_AGENT": "Mozilla/5.0 (Linux; Android 10; ONEPLUS A6000) AppleWebKit/537.36 (KHTML, like Gecko) Chrome/80.0.3987.162 Mobile Safari/537.36", "PATH_INFO": "/", "REMOTE_HOST": null, "USER_IP": "127.0.0.1"}

2020-04-19 19:45:16,837:ERROR:Internal Server Error: /
Traceback (most recent call last):
  File "/usr/local/lib/python3.6/dist-packages/django/core/handlers/exception.py", line 34, in inner
    response = get_response(request)
  File "/usr/local/lib/python3.6/dist-packages/django/core/handlers/base.py", line 115, in _get_response
    response = self.process_exception_by_middleware(e, request)
  File "/usr/local/lib/python3.6/dist-packages/django/core/handlers/base.py", line 113, in _get_response
    response = wrapped_callback(request, *callback_args, **callback_kwargs)
  File "/home/ubuntu/resourcesNet/book/views.py", line 64, in _log_record
    return func(*args,**kwargs)
  File "/home/ubuntu/resourcesNet/book/views.py", line 48, in _block_spider
    return func(*args, **kwargs)
  File "/home/ubuntu/resourcesNet/book/views.py", line 95, in index
    a = Book.objects.filter(book_name__icontains = search)
  File "/usr/local/lib/python3.6/dist-packages/django/db/models/manager.py", line 82, in manager_method
    return getattr(self.get_queryset(), name)(*args, **kwargs)
  File "/usr/local/lib/python3.6/dist-packages/django/db/models/query.py", line 904, in filter
    return self._filter_or_exclude(False, *args, **kwargs)
  File "/usr/local/lib/python3.6/dist-packages/django/db/models/query.py", line 923, in _filter_or_exclude
    clone.query.add_q(Q(*args, **kwargs))
  File "/usr/local/lib/python3.6/dist-packages/django/db/models/sql/query.py", line 1350, in add_q
    clause, _ = self._add_q(q_object, self.used_aliases)
  File "/usr/local/lib/python3.6/dist-packages/django/db/models/sql/query.py", line 1381, in _add_q
    check_filterable=check_filterable,
  File "/usr/local/lib/python3.6/dist-packages/django/db/models/sql/query.py", line 1250, in build_filter
    lookups, parts, reffed_expression = self.solve_lookup_type(arg)
  File "/usr/local/lib/python3.6/dist-packages/django/db/models/sql/query.py", line 1087, in solve_lookup_type
    _, field, _, lookup_parts = self.names_to_path(lookup_splitted, self.get_meta())
  File "/usr/local/lib/python3.6/dist-packages/django/db/models/sql/query.py", line 1483, in names_to_path
    "Choices are: %s" % (name, ", ".join(available)))
django.core.exceptions.FieldError: Cannot resolve keyword 'book_name' into field. Choices are: author, author_book, azw3_download, azw3_flag, catalog, cover, date, douban_id, english_title, epub_download, epub_flag, file_name, id, isbn10, isbn13, kfx_download, kfx_flag, large_cover, mobi_download, mobi_flag, pages, pdf_download, pdf_flag, price, publisher, publisher_book, series, series_book, subtitle, summary, tag_book, tags, title, translator, translator_book, true_douban_id
2020-04-19 19:45:28,595:INFO:{"USER_AGENT": "Mozilla/5.0 (X11; U; Linux armv7l like Android; en-us) AppleWebKit/531.2+ (KHTML, like Gecko) Version/5.0 Safari/533.2+ Kindle/3.0+", "PATH_INFO": "/", "REMOTE_HOST": null, "USER_IP": "127.0.0.1"}

2020-04-19 19:45:28,746:INFO:{"USER_AGENT": "Mozilla/5.0 (Linux; Android 10; ONEPLUS A6000) AppleWebKit/537.36 (KHTML, like Gecko) Chrome/80.0.3987.162 Mobile Safari/537.36", "PATH_INFO": "/", "REMOTE_HOST": null, "USER_IP": "127.0.0.1"}

2020-04-19 19:45:28,789:ERROR:Internal Server Error: /
Traceback (most recent call last):
  File "/usr/local/lib/python3.6/dist-packages/django/core/handlers/exception.py", line 34, in inner
    response = get_response(request)
  File "/usr/local/lib/python3.6/dist-packages/django/core/handlers/base.py", line 115, in _get_response
    response = self.process_exception_by_middleware(e, request)
  File "/usr/local/lib/python3.6/dist-packages/django/core/handlers/base.py", line 113, in _get_response
    response = wrapped_callback(request, *callback_args, **callback_kwargs)
  File "/home/ubuntu/resourcesNet/book/views.py", line 64, in _log_record
    return func(*args,**kwargs)
  File "/home/ubuntu/resourcesNet/book/views.py", line 48, in _block_spider
    return func(*args, **kwargs)
  File "/home/ubuntu/resourcesNet/book/views.py", line 93, in index
    a = a.filter(book_name__icontains = s)
  File "/usr/local/lib/python3.6/dist-packages/django/db/models/query.py", line 904, in filter
    return self._filter_or_exclude(False, *args, **kwargs)
  File "/usr/local/lib/python3.6/dist-packages/django/db/models/query.py", line 923, in _filter_or_exclude
    clone.query.add_q(Q(*args, **kwargs))
  File "/usr/local/lib/python3.6/dist-packages/django/db/models/sql/query.py", line 1350, in add_q
    clause, _ = self._add_q(q_object, self.used_aliases)
  File "/usr/local/lib/python3.6/dist-packages/django/db/models/sql/query.py", line 1381, in _add_q
    check_filterable=check_filterable,
  File "/usr/local/lib/python3.6/dist-packages/django/db/models/sql/query.py", line 1250, in build_filter
    lookups, parts, reffed_expression = self.solve_lookup_type(arg)
  File "/usr/local/lib/python3.6/dist-packages/django/db/models/sql/query.py", line 1087, in solve_lookup_type
    _, field, _, lookup_parts = self.names_to_path(lookup_splitted, self.get_meta())
  File "/usr/local/lib/python3.6/dist-packages/django/db/models/sql/query.py", line 1483, in names_to_path
    "Choices are: %s" % (name, ", ".join(available)))
django.core.exceptions.FieldError: Cannot resolve keyword 'book_name' into field. Choices are: author, author_book, azw3_download, azw3_flag, catalog, cover, date, douban_id, english_title, epub_download, epub_flag, file_name, id, isbn10, isbn13, kfx_download, kfx_flag, large_cover, mobi_download, mobi_flag, pages, pdf_download, pdf_flag, price, publisher, publisher_book, series, series_book, subtitle, summary, tag_book, tags, title, translator, translator_book, true_douban_id
2020-04-19 19:45:33,882:INFO:{"USER_AGENT": "Mozilla/5.0 (Linux; Android 10; ONEPLUS A6000) AppleWebKit/537.36 (KHTML, like Gecko) Chrome/80.0.3987.162 Mobile Safari/537.36", "PATH_INFO": "/detail/10471333/", "REMOTE_HOST": null, "USER_IP": "127.0.0.1"}

2020-04-19 19:45:38,708:INFO:{"USER_AGENT": "Mozilla/5.0 (X11; U; Linux armv7l like Android; en-us) AppleWebKit/531.2+ (KHTML, like Gecko) Version/5.0 Safari/533.2+ Kindle/3.0+", "PATH_INFO": "/detail/3035593/", "REMOTE_HOST": null, "USER_IP": "127.0.0.1"}

2020-04-19 19:45:40,009:INFO:{"USER_AGENT": "Mozilla/5.0 (Linux; Android 10; ONEPLUS A6000) AppleWebKit/537.36 (KHTML, like Gecko) Chrome/80.0.3987.162 Mobile Safari/537.36", "PATH_INFO": "/detail/10471334/", "REMOTE_HOST": null, "USER_IP": "127.0.0.1"}

2020-04-19 19:45:40,040:ERROR:Internal Server Error: /detail/10471334/
Traceback (most recent call last):
  File "/usr/local/lib/python3.6/dist-packages/django/core/handlers/exception.py", line 34, in inner
    response = get_response(request)
  File "/usr/local/lib/python3.6/dist-packages/django/core/handlers/base.py", line 115, in _get_response
    response = self.process_exception_by_middleware(e, request)
  File "/usr/local/lib/python3.6/dist-packages/django/core/handlers/base.py", line 113, in _get_response
    response = wrapped_callback(request, *callback_args, **callback_kwargs)
  File "/home/ubuntu/resourcesNet/book/views.py", line 64, in _log_record
    return func(*args,**kwargs)
  File "/home/ubuntu/resourcesNet/book/views.py", line 48, in _block_spider
    return func(*args, **kwargs)
  File "/home/ubuntu/resourcesNet/book/views.py", line 102, in detail
    b = Book.objects.get(douban_id=id)
  File "/usr/local/lib/python3.6/dist-packages/django/db/models/manager.py", line 82, in manager_method
    return getattr(self.get_queryset(), name)(*args, **kwargs)
  File "/usr/local/lib/python3.6/dist-packages/django/db/models/query.py", line 417, in get
    self.model._meta.object_name
book.models.Book.DoesNotExist: Book matching query does not exist.
2020-04-19 19:45:58,749:INFO:{"USER_AGENT": "Mozilla/5.0 (X11; U; Linux armv7l like Android; en-us) AppleWebKit/531.2+ (KHTML, like Gecko) Version/5.0 Safari/533.2+ Kindle/3.0+", "PATH_INFO": "/", "REMOTE_HOST": null, "USER_IP": "127.0.0.1"}

2020-04-19 19:46:10,964:INFO:{"USER_AGENT": "Mozilla/5.0 (X11; U; Linux armv7l like Android; en-us) AppleWebKit/531.2+ (KHTML, like Gecko) Version/5.0 Safari/533.2+ Kindle/3.0+", "PATH_INFO": "/detail/1076343/", "REMOTE_HOST": null, "USER_IP": "127.0.0.1"}

2020-04-19 19:47:31,113:INFO:{"USER_AGENT": "Mozilla/5.0 (Windows NT 10.0; Win64; x64) AppleWebKit/537.36 (KHTML, like Gecko) Chrome/81.0.4044.113 Safari/537.36 Edg/81.0.416.58", "PATH_INFO": "/", "REMOTE_HOST": null, "USER_IP": "127.0.0.1"}

2020-04-19 19:48:34,170:INFO:{"USER_AGENT": "Mozilla/5.0 (X11; U; Linux armv7l like Android; en-us) AppleWebKit/531.2+ (KHTML, like Gecko) Version/5.0 Safari/533.2+ Kindle/3.0+", "PATH_INFO": "/detail/1076343/", "REMOTE_HOST": null, "USER_IP": "127.0.0.1"}

2020-04-19 19:51:27,529:INFO:{"USER_AGENT": "Mozilla/5.0 (X11; U; Linux armv7l like Android; en-us) AppleWebKit/531.2+ (KHTML, like Gecko) Version/5.0 Safari/533.2+ Kindle/3.0+", "PATH_INFO": "/detail/1076343/", "REMOTE_HOST": null, "USER_IP": "127.0.0.1"}

2020-04-19 19:54:12,079:INFO:{"USER_AGENT": "Mozilla/5.0 (Windows NT 10.0; Win64; x64) AppleWebKit/537.36 (KHTML, like Gecko) Chrome/81.0.4044.113 Safari/537.36 Edg/81.0.416.58", "PATH_INFO": "/", "REMOTE_HOST": null, "USER_IP": "127.0.0.1"}

2020-04-19 19:54:48,657:INFO:{"USER_AGENT": "Mozilla/5.0 (X11; U; Linux armv7l like Android; en-us) AppleWebKit/531.2+ (KHTML, like Gecko) Version/5.0 Safari/533.2+ Kindle/3.0+", "PATH_INFO": "/detail/1076343/", "REMOTE_HOST": null, "USER_IP": "127.0.0.1"}

2020-04-19 19:55:06,119:INFO:{"USER_AGENT": "Mozilla/5.0 (X11; U; Linux armv7l like Android; en-us) AppleWebKit/531.2+ (KHTML, like Gecko) Version/5.0 Safari/533.2+ Kindle/3.0+", "PATH_INFO": "/detail/1076343/", "REMOTE_HOST": null, "USER_IP": "127.0.0.1"}

2020-04-19 19:55:27,036:INFO:{"USER_AGENT": "Mozilla/5.0 (X11; U; Linux armv7l like Android; en-us) AppleWebKit/531.2+ (KHTML, like Gecko) Version/5.0 Safari/533.2+ Kindle/3.0+", "PATH_INFO": "/", "REMOTE_HOST": null, "USER_IP": "127.0.0.1"}

2020-04-19 19:55:30,669:INFO:{"USER_AGENT": "Mozilla/5.0 (Windows NT 10.0; Win64; x64) AppleWebKit/537.36 (KHTML, like Gecko) Chrome/81.0.4044.113 Safari/537.36 Edg/81.0.416.58", "PATH_INFO": "/detail/1076343/", "REMOTE_HOST": null, "USER_IP": "127.0.0.1"}

2020-04-19 19:56:41,892:INFO:{"USER_AGENT": "Mozilla/5.0 (Linux; Android 9; MI 6 Build/PKQ1.190118.001; wv) AppleWebKit/537.36 (KHTML, like Gecko) Version/4.0 Chrome/80.0.3987.99 Mobile Safari/537.36 (#Build; Xiaomi; MI 6; PKQ1.190118.001; 9) +CoolMarket/10.0.3", "PATH_INFO": "/", "REMOTE_HOST": null, "USER_IP": "127.0.0.1"}

2020-04-19 19:56:49,646:INFO:{"USER_AGENT": "Mozilla/5.0 (Macintosh; Intel Mac OS X 10_15_2) AppleWebKit/537.36 (KHTML, like Gecko) Chrome/79.0.3945.130 Safari/537.36", "PATH_INFO": "/", "REMOTE_HOST": null, "USER_IP": "127.0.0.1"}

2020-04-19 19:57:06,938:INFO:{"USER_AGENT": "Mozilla/5.0 (Macintosh; Intel Mac OS X 10_15_2) AppleWebKit/537.36 (KHTML, like Gecko) Chrome/79.0.3945.130 Safari/537.36", "PATH_INFO": "/detail/10471333/", "REMOTE_HOST": null, "USER_IP": "127.0.0.1"}

2020-04-19 19:57:22,588:INFO:{"USER_AGENT": "Mozilla/5.0 (Macintosh; Intel Mac OS X 10_15_2) AppleWebKit/537.36 (KHTML, like Gecko) Chrome/79.0.3945.130 Safari/537.36", "PATH_INFO": "/detail/33426136/", "REMOTE_HOST": null, "USER_IP": "127.0.0.1"}

2020-04-19 19:57:54,725:INFO:{"USER_AGENT": "Mozilla/5.0 (Linux; Android 10; Redmi K20 Build/QKQ1.190825.002; wv) AppleWebKit/537.36 (KHTML, like Gecko) Version/4.0 Chrome/80.0.3987.162 Mobile Safari/537.36 (#Build; Xiaomi; Redmi K20; QKQ1.190825.002 test-keys; 10) +CoolMarket/10.0.4", "PATH_INFO": "/", "REMOTE_HOST": null, "USER_IP": "127.0.0.1"}

2020-04-19 20:02:54,564:INFO:{"USER_AGENT": "Mozilla/5.0 (Macintosh; Intel Mac OS X 10_15_2) AppleWebKit/537.36 (KHTML, like Gecko) Chrome/79.0.3945.130 Safari/537.36", "PATH_INFO": "/", "REMOTE_HOST": null, "USER_IP": "127.0.0.1"}

2020-04-19 20:02:54,608:ERROR:Internal Server Error: /
Traceback (most recent call last):
  File "/usr/local/lib/python3.6/dist-packages/django/core/handlers/exception.py", line 34, in inner
    response = get_response(request)
  File "/usr/local/lib/python3.6/dist-packages/django/core/handlers/base.py", line 115, in _get_response
    response = self.process_exception_by_middleware(e, request)
  File "/usr/local/lib/python3.6/dist-packages/django/core/handlers/base.py", line 113, in _get_response
    response = wrapped_callback(request, *callback_args, **callback_kwargs)
  File "/home/ubuntu/resourcesNet/book/views.py", line 64, in _log_record
    return func(*args,**kwargs)
  File "/home/ubuntu/resourcesNet/book/views.py", line 48, in _block_spider
    return func(*args, **kwargs)
  File "/home/ubuntu/resourcesNet/book/views.py", line 95, in index
    a = Book.objects.filter(book_name__icontains = search)
  File "/usr/local/lib/python3.6/dist-packages/django/db/models/manager.py", line 82, in manager_method
    return getattr(self.get_queryset(), name)(*args, **kwargs)
  File "/usr/local/lib/python3.6/dist-packages/django/db/models/query.py", line 904, in filter
    return self._filter_or_exclude(False, *args, **kwargs)
  File "/usr/local/lib/python3.6/dist-packages/django/db/models/query.py", line 923, in _filter_or_exclude
    clone.query.add_q(Q(*args, **kwargs))
  File "/usr/local/lib/python3.6/dist-packages/django/db/models/sql/query.py", line 1350, in add_q
    clause, _ = self._add_q(q_object, self.used_aliases)
  File "/usr/local/lib/python3.6/dist-packages/django/db/models/sql/query.py", line 1381, in _add_q
    check_filterable=check_filterable,
  File "/usr/local/lib/python3.6/dist-packages/django/db/models/sql/query.py", line 1250, in build_filter
    lookups, parts, reffed_expression = self.solve_lookup_type(arg)
  File "/usr/local/lib/python3.6/dist-packages/django/db/models/sql/query.py", line 1087, in solve_lookup_type
    _, field, _, lookup_parts = self.names_to_path(lookup_splitted, self.get_meta())
  File "/usr/local/lib/python3.6/dist-packages/django/db/models/sql/query.py", line 1483, in names_to_path
    "Choices are: %s" % (name, ", ".join(available)))
django.core.exceptions.FieldError: Cannot resolve keyword 'book_name' into field. Choices are: author, author_book, azw3_download, azw3_flag, catalog, cover, date, douban_id, english_title, epub_download, epub_flag, file_name, id, isbn10, isbn13, kfx_download, kfx_flag, large_cover, mobi_download, mobi_flag, pages, pdf_download, pdf_flag, price, publisher, publisher_book, series, series_book, subtitle, summary, tag_book, tags, title, translator, translator_book, true_douban_id
2020-04-19 20:02:58,623:WARNING:Not Found: /favicon.ico
2020-04-19 20:03:22,421:INFO:{"USER_AGENT": "Mozilla/5.0 (Macintosh; Intel Mac OS X 10_15_2) AppleWebKit/537.36 (KHTML, like Gecko) Chrome/79.0.3945.130 Safari/537.36", "PATH_INFO": "/detail/1035247/", "REMOTE_HOST": null, "USER_IP": "127.0.0.1"}

2020-04-19 20:03:49,766:INFO:{"USER_AGENT": "Mozilla/5.0 (Macintosh; Intel Mac OS X 10_15_2) AppleWebKit/537.36 (KHTML, like Gecko) Chrome/79.0.3945.130 Safari/537.36", "PATH_INFO": "/detail/33426136/", "REMOTE_HOST": null, "USER_IP": "127.0.0.1"}

2020-04-19 20:04:18,969:INFO:{"USER_AGENT": "Mozilla/5.0 (Macintosh; Intel Mac OS X 10_15_2) AppleWebKit/537.36 (KHTML, like Gecko) Chrome/79.0.3945.130 Safari/537.36", "PATH_INFO": "/", "REMOTE_HOST": null, "USER_IP": "127.0.0.1"}

2020-04-19 20:04:19,012:ERROR:Internal Server Error: /
Traceback (most recent call last):
  File "/usr/local/lib/python3.6/dist-packages/django/core/handlers/exception.py", line 34, in inner
    response = get_response(request)
  File "/usr/local/lib/python3.6/dist-packages/django/core/handlers/base.py", line 115, in _get_response
    response = self.process_exception_by_middleware(e, request)
  File "/usr/local/lib/python3.6/dist-packages/django/core/handlers/base.py", line 113, in _get_response
    response = wrapped_callback(request, *callback_args, **callback_kwargs)
  File "/home/ubuntu/resourcesNet/book/views.py", line 64, in _log_record
    return func(*args,**kwargs)
  File "/home/ubuntu/resourcesNet/book/views.py", line 48, in _block_spider
    return func(*args, **kwargs)
  File "/home/ubuntu/resourcesNet/book/views.py", line 95, in index
    a = Book.objects.filter(book_name__icontains = search)
  File "/usr/local/lib/python3.6/dist-packages/django/db/models/manager.py", line 82, in manager_method
    return getattr(self.get_queryset(), name)(*args, **kwargs)
  File "/usr/local/lib/python3.6/dist-packages/django/db/models/query.py", line 904, in filter
    return self._filter_or_exclude(False, *args, **kwargs)
  File "/usr/local/lib/python3.6/dist-packages/django/db/models/query.py", line 923, in _filter_or_exclude
    clone.query.add_q(Q(*args, **kwargs))
  File "/usr/local/lib/python3.6/dist-packages/django/db/models/sql/query.py", line 1350, in add_q
    clause, _ = self._add_q(q_object, self.used_aliases)
  File "/usr/local/lib/python3.6/dist-packages/django/db/models/sql/query.py", line 1381, in _add_q
    check_filterable=check_filterable,
  File "/usr/local/lib/python3.6/dist-packages/django/db/models/sql/query.py", line 1250, in build_filter
    lookups, parts, reffed_expression = self.solve_lookup_type(arg)
  File "/usr/local/lib/python3.6/dist-packages/django/db/models/sql/query.py", line 1087, in solve_lookup_type
    _, field, _, lookup_parts = self.names_to_path(lookup_splitted, self.get_meta())
  File "/usr/local/lib/python3.6/dist-packages/django/db/models/sql/query.py", line 1483, in names_to_path
    "Choices are: %s" % (name, ", ".join(available)))
django.core.exceptions.FieldError: Cannot resolve keyword 'book_name' into field. Choices are: author, author_book, azw3_download, azw3_flag, catalog, cover, date, douban_id, english_title, epub_download, epub_flag, file_name, id, isbn10, isbn13, kfx_download, kfx_flag, large_cover, mobi_download, mobi_flag, pages, pdf_download, pdf_flag, price, publisher, publisher_book, series, series_book, subtitle, summary, tag_book, tags, title, translator, translator_book, true_douban_id
2020-04-19 20:06:14,854:INFO:{"USER_AGENT": "Mozilla/5.0 (Linux; Android 9; ONEPLUS A5010) AppleWebKit/537.36 (KHTML, like Gecko) Chrome/80.0.3987.132 Mobile Safari/537.36", "PATH_INFO": "/", "REMOTE_HOST": null, "USER_IP": "127.0.0.1"}

2020-04-19 20:06:37,777:INFO:{"USER_AGENT": "Mozilla/5.0 (Linux; Android 9; ONEPLUS A5010) AppleWebKit/537.36 (KHTML, like Gecko) Chrome/80.0.3987.132 Mobile Safari/537.36", "PATH_INFO": "/", "REMOTE_HOST": null, "USER_IP": "127.0.0.1"}

2020-04-19 20:06:37,821:ERROR:Internal Server Error: /
Traceback (most recent call last):
  File "/usr/local/lib/python3.6/dist-packages/django/core/handlers/exception.py", line 34, in inner
    response = get_response(request)
  File "/usr/local/lib/python3.6/dist-packages/django/core/handlers/base.py", line 115, in _get_response
    response = self.process_exception_by_middleware(e, request)
  File "/usr/local/lib/python3.6/dist-packages/django/core/handlers/base.py", line 113, in _get_response
    response = wrapped_callback(request, *callback_args, **callback_kwargs)
  File "/home/ubuntu/resourcesNet/book/views.py", line 64, in _log_record
    return func(*args,**kwargs)
  File "/home/ubuntu/resourcesNet/book/views.py", line 48, in _block_spider
    return func(*args, **kwargs)
  File "/home/ubuntu/resourcesNet/book/views.py", line 95, in index
    a = Book.objects.filter(book_name__icontains = search)
  File "/usr/local/lib/python3.6/dist-packages/django/db/models/manager.py", line 82, in manager_method
    return getattr(self.get_queryset(), name)(*args, **kwargs)
  File "/usr/local/lib/python3.6/dist-packages/django/db/models/query.py", line 904, in filter
    return self._filter_or_exclude(False, *args, **kwargs)
  File "/usr/local/lib/python3.6/dist-packages/django/db/models/query.py", line 923, in _filter_or_exclude
    clone.query.add_q(Q(*args, **kwargs))
  File "/usr/local/lib/python3.6/dist-packages/django/db/models/sql/query.py", line 1350, in add_q
    clause, _ = self._add_q(q_object, self.used_aliases)
  File "/usr/local/lib/python3.6/dist-packages/django/db/models/sql/query.py", line 1381, in _add_q
    check_filterable=check_filterable,
  File "/usr/local/lib/python3.6/dist-packages/django/db/models/sql/query.py", line 1250, in build_filter
    lookups, parts, reffed_expression = self.solve_lookup_type(arg)
  File "/usr/local/lib/python3.6/dist-packages/django/db/models/sql/query.py", line 1087, in solve_lookup_type
    _, field, _, lookup_parts = self.names_to_path(lookup_splitted, self.get_meta())
  File "/usr/local/lib/python3.6/dist-packages/django/db/models/sql/query.py", line 1483, in names_to_path
    "Choices are: %s" % (name, ", ".join(available)))
django.core.exceptions.FieldError: Cannot resolve keyword 'book_name' into field. Choices are: author, author_book, azw3_download, azw3_flag, catalog, cover, date, douban_id, english_title, epub_download, epub_flag, file_name, id, isbn10, isbn13, kfx_download, kfx_flag, large_cover, mobi_download, mobi_flag, pages, pdf_download, pdf_flag, price, publisher, publisher_book, series, series_book, subtitle, summary, tag_book, tags, title, translator, translator_book, true_douban_id
2020-04-19 20:06:39,939:INFO:{"USER_AGENT": "Mozilla/5.0 (Linux; Android 9; ONEPLUS A5010) AppleWebKit/537.36 (KHTML, like Gecko) Chrome/80.0.3987.132 Mobile Safari/537.36", "PATH_INFO": "/", "REMOTE_HOST": null, "USER_IP": "127.0.0.1"}

2020-04-19 20:06:44,242:INFO:{"USER_AGENT": "Mozilla/5.0 (Linux; Android 9; ONEPLUS A5010) AppleWebKit/537.36 (KHTML, like Gecko) Chrome/80.0.3987.132 Mobile Safari/537.36", "PATH_INFO": "/", "REMOTE_HOST": null, "USER_IP": "127.0.0.1"}

2020-04-19 20:06:44,286:ERROR:Internal Server Error: /
Traceback (most recent call last):
  File "/usr/local/lib/python3.6/dist-packages/django/core/handlers/exception.py", line 34, in inner
    response = get_response(request)
  File "/usr/local/lib/python3.6/dist-packages/django/core/handlers/base.py", line 115, in _get_response
    response = self.process_exception_by_middleware(e, request)
  File "/usr/local/lib/python3.6/dist-packages/django/core/handlers/base.py", line 113, in _get_response
    response = wrapped_callback(request, *callback_args, **callback_kwargs)
  File "/home/ubuntu/resourcesNet/book/views.py", line 64, in _log_record
    return func(*args,**kwargs)
  File "/home/ubuntu/resourcesNet/book/views.py", line 48, in _block_spider
    return func(*args, **kwargs)
  File "/home/ubuntu/resourcesNet/book/views.py", line 95, in index
    a = Book.objects.filter(book_name__icontains = search)
  File "/usr/local/lib/python3.6/dist-packages/django/db/models/manager.py", line 82, in manager_method
    return getattr(self.get_queryset(), name)(*args, **kwargs)
  File "/usr/local/lib/python3.6/dist-packages/django/db/models/query.py", line 904, in filter
    return self._filter_or_exclude(False, *args, **kwargs)
  File "/usr/local/lib/python3.6/dist-packages/django/db/models/query.py", line 923, in _filter_or_exclude
    clone.query.add_q(Q(*args, **kwargs))
  File "/usr/local/lib/python3.6/dist-packages/django/db/models/sql/query.py", line 1350, in add_q
    clause, _ = self._add_q(q_object, self.used_aliases)
  File "/usr/local/lib/python3.6/dist-packages/django/db/models/sql/query.py", line 1381, in _add_q
    check_filterable=check_filterable,
  File "/usr/local/lib/python3.6/dist-packages/django/db/models/sql/query.py", line 1250, in build_filter
    lookups, parts, reffed_expression = self.solve_lookup_type(arg)
  File "/usr/local/lib/python3.6/dist-packages/django/db/models/sql/query.py", line 1087, in solve_lookup_type
    _, field, _, lookup_parts = self.names_to_path(lookup_splitted, self.get_meta())
  File "/usr/local/lib/python3.6/dist-packages/django/db/models/sql/query.py", line 1483, in names_to_path
    "Choices are: %s" % (name, ", ".join(available)))
django.core.exceptions.FieldError: Cannot resolve keyword 'book_name' into field. Choices are: author, author_book, azw3_download, azw3_flag, catalog, cover, date, douban_id, english_title, epub_download, epub_flag, file_name, id, isbn10, isbn13, kfx_download, kfx_flag, large_cover, mobi_download, mobi_flag, pages, pdf_download, pdf_flag, price, publisher, publisher_book, series, series_book, subtitle, summary, tag_book, tags, title, translator, translator_book, true_douban_id
2020-04-19 20:06:56,109:INFO:{"USER_AGENT": "Mozilla/5.0 (Linux; Android 9; ONEPLUS A5010) AppleWebKit/537.36 (KHTML, like Gecko) Chrome/80.0.3987.132 Mobile Safari/537.36", "PATH_INFO": "/", "REMOTE_HOST": null, "USER_IP": "127.0.0.1"}

2020-04-19 20:07:02,763:INFO:{"USER_AGENT": "Mozilla/5.0 (Linux; Android 9; ONEPLUS A5010) AppleWebKit/537.36 (KHTML, like Gecko) Chrome/80.0.3987.132 Mobile Safari/537.36", "PATH_INFO": "/", "REMOTE_HOST": null, "USER_IP": "127.0.0.1"}

2020-04-19 20:07:21,187:INFO:{"USER_AGENT": "Mozilla/5.0 (Linux; Android 9; ONEPLUS A5010) AppleWebKit/537.36 (KHTML, like Gecko) Chrome/80.0.3987.132 Mobile Safari/537.36", "PATH_INFO": "/", "REMOTE_HOST": null, "USER_IP": "127.0.0.1"}

2020-04-19 20:07:21,231:ERROR:Internal Server Error: /
Traceback (most recent call last):
  File "/usr/local/lib/python3.6/dist-packages/django/core/handlers/exception.py", line 34, in inner
    response = get_response(request)
  File "/usr/local/lib/python3.6/dist-packages/django/core/handlers/base.py", line 115, in _get_response
    response = self.process_exception_by_middleware(e, request)
  File "/usr/local/lib/python3.6/dist-packages/django/core/handlers/base.py", line 113, in _get_response
    response = wrapped_callback(request, *callback_args, **callback_kwargs)
  File "/home/ubuntu/resourcesNet/book/views.py", line 64, in _log_record
    return func(*args,**kwargs)
  File "/home/ubuntu/resourcesNet/book/views.py", line 48, in _block_spider
    return func(*args, **kwargs)
  File "/home/ubuntu/resourcesNet/book/views.py", line 95, in index
    a = Book.objects.filter(book_name__icontains = search)
  File "/usr/local/lib/python3.6/dist-packages/django/db/models/manager.py", line 82, in manager_method
    return getattr(self.get_queryset(), name)(*args, **kwargs)
  File "/usr/local/lib/python3.6/dist-packages/django/db/models/query.py", line 904, in filter
    return self._filter_or_exclude(False, *args, **kwargs)
  File "/usr/local/lib/python3.6/dist-packages/django/db/models/query.py", line 923, in _filter_or_exclude
    clone.query.add_q(Q(*args, **kwargs))
  File "/usr/local/lib/python3.6/dist-packages/django/db/models/sql/query.py", line 1350, in add_q
    clause, _ = self._add_q(q_object, self.used_aliases)
  File "/usr/local/lib/python3.6/dist-packages/django/db/models/sql/query.py", line 1381, in _add_q
    check_filterable=check_filterable,
  File "/usr/local/lib/python3.6/dist-packages/django/db/models/sql/query.py", line 1250, in build_filter
    lookups, parts, reffed_expression = self.solve_lookup_type(arg)
  File "/usr/local/lib/python3.6/dist-packages/django/db/models/sql/query.py", line 1087, in solve_lookup_type
    _, field, _, lookup_parts = self.names_to_path(lookup_splitted, self.get_meta())
  File "/usr/local/lib/python3.6/dist-packages/django/db/models/sql/query.py", line 1483, in names_to_path
    "Choices are: %s" % (name, ", ".join(available)))
django.core.exceptions.FieldError: Cannot resolve keyword 'book_name' into field. Choices are: author, author_book, azw3_download, azw3_flag, catalog, cover, date, douban_id, english_title, epub_download, epub_flag, file_name, id, isbn10, isbn13, kfx_download, kfx_flag, large_cover, mobi_download, mobi_flag, pages, pdf_download, pdf_flag, price, publisher, publisher_book, series, series_book, subtitle, summary, tag_book, tags, title, translator, translator_book, true_douban_id
2020-04-19 20:23:57,366:INFO:{"USER_AGENT": "Mozilla/5.0 (Windows NT 10.0; Win64; x64) AppleWebKit/537.36 (KHTML, like Gecko) Chrome/81.0.4044.113 Safari/537.36 Edg/81.0.416.58", "PATH_INFO": "/", "REMOTE_HOST": null, "USER_IP": "127.0.0.1"}

2020-04-19 20:24:32,630:INFO:{"USER_AGENT": "Mozilla/5.0 (Windows NT 10.0; Win64; x64) AppleWebKit/537.36 (KHTML, like Gecko) Chrome/81.0.4044.113 Safari/537.36 Edg/81.0.416.58", "PATH_INFO": "/", "REMOTE_HOST": null, "USER_IP": "127.0.0.1"}

2020-04-19 20:25:26,752:INFO:{"USER_AGENT": "Mozilla/5.0 (Windows NT 10.0; Win64; x64) AppleWebKit/537.36 (KHTML, like Gecko) Chrome/81.0.4044.113 Safari/537.36 Edg/81.0.416.58", "PATH_INFO": "/", "REMOTE_HOST": null, "USER_IP": "127.0.0.1"}

2020-04-19 20:26:04,634:INFO:{"USER_AGENT": "Mozilla/5.0 (Windows NT 6.1; WOW64) AppleWebKit/537.36 (KHTML, like Gecko) Chrome/51.0.2704.103 Safari/537.36", "PATH_INFO": "/", "REMOTE_HOST": null, "USER_IP": "127.0.0.1"}

2020-04-19 20:26:21,086:INFO:{"USER_AGENT": "Mozilla/5.0 (Linux; Android 9; J9110 Build/55.0.A.10.26; wv) AppleWebKit/537.36 (KHTML, like Gecko) Version/4.0 Chrome/80.0.3987.149 Mobile Safari/537.36 (#Build; Sony; J9110; 55.0.A.10.26; 9) +CoolMarket/10.0.4", "PATH_INFO": "/", "REMOTE_HOST": null, "USER_IP": "127.0.0.1"}

2020-04-19 20:26:23,812:INFO:{"USER_AGENT": "Mozilla/5.0 (Linux; Android 9; J9110 Build/55.0.A.10.26; wv) AppleWebKit/537.36 (KHTML, like Gecko) Version/4.0 Chrome/80.0.3987.149 Mobile Safari/537.36", "PATH_INFO": "/", "REMOTE_HOST": null, "USER_IP": "127.0.0.1"}

2020-04-19 20:28:46,861:INFO:{"USER_AGENT": "Mozilla/5.0 (Windows NT 10.0; Win64; x64) AppleWebKit/537.36 (KHTML, like Gecko) Chrome/81.0.4044.113 Safari/537.36 Edg/81.0.416.58", "PATH_INFO": "/", "REMOTE_HOST": null, "USER_IP": "127.0.0.1"}

2020-04-19 20:29:18,193:INFO:{"USER_AGENT": "Mozilla/5.0 (Linux; Android 8.1.0; vivo X9s Build/OPM1.171019.019; wv) AppleWebKit/537.36 (KHTML, like Gecko) Version/4.0 Chrome/62.0.3202.84 Mobile Safari/537.36 (#Build; vivo; vivo X9s; OPM1.171019.019 release-keys; 8.1.0) +CoolMarket/9.6.2", "PATH_INFO": "/", "REMOTE_HOST": null, "USER_IP": "127.0.0.1"}

2020-04-19 20:29:41,361:INFO:{"USER_AGENT": "Mozilla/5.0 (Linux; Android 8.1.0; vivo X9s Build/OPM1.171019.019; wv) AppleWebKit/537.36 (KHTML, like Gecko) Version/4.0 Chrome/62.0.3202.84 Mobile Safari/537.36", "PATH_INFO": "/", "REMOTE_HOST": null, "USER_IP": "127.0.0.1"}

2020-04-19 20:30:08,064:INFO:{"USER_AGENT": "Mozilla/5.0 (Linux; Android 8.1.0; vivo X9s Build/OPM1.171019.019; wv) AppleWebKit/537.36 (KHTML, like Gecko) Version/4.0 Chrome/62.0.3202.84 Mobile Safari/537.36 (#Build; vivo; vivo X9s; OPM1.171019.019 release-keys; 8.1.0) +CoolMarket/9.6.2", "PATH_INFO": "/", "REMOTE_HOST": null, "USER_IP": "127.0.0.1"}

2020-04-19 20:33:30,336:INFO:{"USER_AGENT": "Mozilla/5.0 (Linux; Android 10; MI 8 Build/QKQ1.190828.002; wv) AppleWebKit/537.36 (KHTML, like Gecko) Version/4.0 Chrome/78.0.3904.96 Mobile Safari/537.36 (#Build; Xiaomi; MI 8; QKQ1.190828.002 test-keys; 10) +CoolMarket/10.0.4", "PATH_INFO": "/", "REMOTE_HOST": null, "USER_IP": "127.0.0.1"}

2020-04-19 20:36:59,236:INFO:{"USER_AGENT": "Mozilla/5.0 (Windows NT 10.0; Win64; x64) AppleWebKit/537.36 (KHTML, like Gecko) Chrome/81.0.4044.113 Safari/537.36 Edg/81.0.416.58", "PATH_INFO": "/", "REMOTE_HOST": null, "USER_IP": "127.0.0.1"}

2020-04-19 20:38:32,622:INFO:{"USER_AGENT": "Mozilla/5.0 (Windows NT 10.0; Win64; x64) AppleWebKit/537.36 (KHTML, like Gecko) Chrome/81.0.4044.113 Safari/537.36 Edg/81.0.416.58", "PATH_INFO": "/", "REMOTE_HOST": null, "USER_IP": "127.0.0.1"}

2020-04-19 20:39:21,956:INFO:{"USER_AGENT": "Mozilla/5.0 (Windows NT 10.0; Win64; x64) AppleWebKit/537.36 (KHTML, like Gecko) Chrome/81.0.4044.113 Safari/537.36 Edg/81.0.416.58", "PATH_INFO": "/detail/1004322/", "REMOTE_HOST": null, "USER_IP": "127.0.0.1"}

2020-04-19 20:40:56,920:INFO:{"USER_AGENT": "Mozilla/5.0 (Windows NT 10.0; Win64; x64) AppleWebKit/537.36 (KHTML, like Gecko) Chrome/81.0.4044.113 Safari/537.36 Edg/81.0.416.58", "PATH_INFO": "/", "REMOTE_HOST": null, "USER_IP": "127.0.0.1"}

2020-04-19 20:41:39,903:INFO:{"USER_AGENT": "Mozilla/5.0 (Windows NT 10.0; Win64; x64) AppleWebKit/537.36 (KHTML, like Gecko) Chrome/59.0.3071.104 Safari/537.36", "PATH_INFO": "/", "REMOTE_HOST": null, "USER_IP": "127.0.0.1"}

2020-04-19 20:43:06,638:INFO:{"USER_AGENT": "Mozilla/5.0 (Linux; Android 9; J9110 Build/55.0.A.10.26; wv) AppleWebKit/537.36 (KHTML, like Gecko) Version/4.0 Chrome/80.0.3987.149 Mobile Safari/537.36", "PATH_INFO": "/", "REMOTE_HOST": null, "USER_IP": "127.0.0.1"}

2020-04-19 20:45:59,991:INFO:{"USER_AGENT": "Mozilla/5.0 (Linux; Android 10; HMA-TL00 Build/HUAWEIHMA-TL00; wv) AppleWebKit/537.36 (KHTML, like Gecko) Version/4.0 Chrome/74.0.3729.186 Mobile Safari/537.36 (#Build; HUAWEI; HMA-TL00; HMA-TL00 10.0.0.188(C01E76R2P8); 10) +CoolMarket/10.0.4", "PATH_INFO": "/", "REMOTE_HOST": null, "USER_IP": "127.0.0.1"}

2020-04-19 20:46:16,905:INFO:{"USER_AGENT": "Mozilla/5.0 (Linux; Android 10; HMA-TL00 Build/HUAWEIHMA-TL00; wv) AppleWebKit/537.36 (KHTML, like Gecko) Version/4.0 Chrome/74.0.3729.186 Mobile Safari/537.36", "PATH_INFO": "/", "REMOTE_HOST": null, "USER_IP": "127.0.0.1"}

2020-04-19 20:46:27,065:INFO:{"USER_AGENT": "Mozilla/5.0 (Linux; Android 10; HMA-TL00 Build/HUAWEIHMA-TL00; wv) AppleWebKit/537.36 (KHTML, like Gecko) Version/4.0 Chrome/74.0.3729.186 Mobile Safari/537.36", "PATH_INFO": "/page=2/", "REMOTE_HOST": null, "USER_IP": "127.0.0.1"}

2020-04-19 20:46:32,363:INFO:{"USER_AGENT": "Mozilla/5.0 (Linux; Android 10; HMA-TL00 Build/HUAWEIHMA-TL00; wv) AppleWebKit/537.36 (KHTML, like Gecko) Version/4.0 Chrome/74.0.3729.186 Mobile Safari/537.36", "PATH_INFO": "/page=1/", "REMOTE_HOST": null, "USER_IP": "127.0.0.1"}

2020-04-19 20:46:34,665:INFO:{"USER_AGENT": "Mozilla/5.0 (Linux; Android 10; HMA-TL00 Build/HUAWEIHMA-TL00; wv) AppleWebKit/537.36 (KHTML, like Gecko) Version/4.0 Chrome/74.0.3729.186 Mobile Safari/537.36", "PATH_INFO": "/detail/1005706/", "REMOTE_HOST": null, "USER_IP": "127.0.0.1"}

2020-04-19 20:46:42,807:INFO:{"USER_AGENT": "Mozilla/5.0 (Linux; Android 10; HMA-TL00 Build/HUAWEIHMA-TL00; wv) AppleWebKit/537.36 (KHTML, like Gecko) Version/4.0 Chrome/74.0.3729.186 Mobile Safari/537.36", "PATH_INFO": "/detail/3035593/", "REMOTE_HOST": null, "USER_IP": "127.0.0.1"}

2020-04-19 20:47:14,750:INFO:{"USER_AGENT": "Mozilla/5.0 (Linux; Android 8.1.0; vivo X9s Build/OPM1.171019.019; wv) AppleWebKit/537.36 (KHTML, like Gecko) Version/4.0 Chrome/62.0.3202.84 Mobile Safari/537.36", "PATH_INFO": "/", "REMOTE_HOST": null, "USER_IP": "127.0.0.1"}

2020-04-19 20:47:14,795:ERROR:Internal Server Error: /
Traceback (most recent call last):
  File "/usr/local/lib/python3.6/dist-packages/django/core/handlers/exception.py", line 34, in inner
    response = get_response(request)
  File "/usr/local/lib/python3.6/dist-packages/django/core/handlers/base.py", line 115, in _get_response
    response = self.process_exception_by_middleware(e, request)
  File "/usr/local/lib/python3.6/dist-packages/django/core/handlers/base.py", line 113, in _get_response
    response = wrapped_callback(request, *callback_args, **callback_kwargs)
  File "/home/ubuntu/resourcesNet/book/views.py", line 64, in _log_record
    return func(*args,**kwargs)
  File "/home/ubuntu/resourcesNet/book/views.py", line 48, in _block_spider
    return func(*args, **kwargs)
  File "/home/ubuntu/resourcesNet/book/views.py", line 95, in index
    a = Book.objects.filter(book_name__icontains = search)
  File "/usr/local/lib/python3.6/dist-packages/django/db/models/manager.py", line 82, in manager_method
    return getattr(self.get_queryset(), name)(*args, **kwargs)
  File "/usr/local/lib/python3.6/dist-packages/django/db/models/query.py", line 904, in filter
    return self._filter_or_exclude(False, *args, **kwargs)
  File "/usr/local/lib/python3.6/dist-packages/django/db/models/query.py", line 923, in _filter_or_exclude
    clone.query.add_q(Q(*args, **kwargs))
  File "/usr/local/lib/python3.6/dist-packages/django/db/models/sql/query.py", line 1350, in add_q
    clause, _ = self._add_q(q_object, self.used_aliases)
  File "/usr/local/lib/python3.6/dist-packages/django/db/models/sql/query.py", line 1381, in _add_q
    check_filterable=check_filterable,
  File "/usr/local/lib/python3.6/dist-packages/django/db/models/sql/query.py", line 1250, in build_filter
    lookups, parts, reffed_expression = self.solve_lookup_type(arg)
  File "/usr/local/lib/python3.6/dist-packages/django/db/models/sql/query.py", line 1087, in solve_lookup_type
    _, field, _, lookup_parts = self.names_to_path(lookup_splitted, self.get_meta())
  File "/usr/local/lib/python3.6/dist-packages/django/db/models/sql/query.py", line 1483, in names_to_path
    "Choices are: %s" % (name, ", ".join(available)))
django.core.exceptions.FieldError: Cannot resolve keyword 'book_name' into field. Choices are: author, author_book, azw3_download, azw3_flag, catalog, cover, date, douban_id, english_title, epub_download, epub_flag, file_name, id, isbn10, isbn13, kfx_download, kfx_flag, large_cover, mobi_download, mobi_flag, pages, pdf_download, pdf_flag, price, publisher, publisher_book, series, series_book, subtitle, summary, tag_book, tags, title, translator, translator_book, true_douban_id
2020-04-19 20:47:36,236:INFO:{"USER_AGENT": "Mozilla/5.0 (Linux; Android 10; HMA-TL00 Build/HUAWEIHMA-TL00; wv) AppleWebKit/537.36 (KHTML, like Gecko) Version/4.0 Chrome/74.0.3729.186 Mobile Safari/537.36 (#Build; HUAWEI; HMA-TL00; HMA-TL00 10.0.0.188(C01E76R2P8); 10) +CoolMarket/10.0.4", "PATH_INFO": "/", "REMOTE_HOST": null, "USER_IP": "127.0.0.1"}

2020-04-19 20:47:48,715:INFO:{"USER_AGENT": "Mozilla/5.0 (Linux; Android 10; HMA-TL00 Build/HUAWEIHMA-TL00; wv) AppleWebKit/537.36 (KHTML, like Gecko) Version/4.0 Chrome/74.0.3729.186 Mobile Safari/537.36 (#Build; HUAWEI; HMA-TL00; HMA-TL00 10.0.0.188(C01E76R2P8); 10) +CoolMarket/10.0.4", "PATH_INFO": "/", "REMOTE_HOST": null, "USER_IP": "127.0.0.1"}

2020-04-19 20:47:48,761:ERROR:Internal Server Error: /
Traceback (most recent call last):
  File "/usr/local/lib/python3.6/dist-packages/django/core/handlers/exception.py", line 34, in inner
    response = get_response(request)
  File "/usr/local/lib/python3.6/dist-packages/django/core/handlers/base.py", line 115, in _get_response
    response = self.process_exception_by_middleware(e, request)
  File "/usr/local/lib/python3.6/dist-packages/django/core/handlers/base.py", line 113, in _get_response
    response = wrapped_callback(request, *callback_args, **callback_kwargs)
  File "/home/ubuntu/resourcesNet/book/views.py", line 64, in _log_record
    return func(*args,**kwargs)
  File "/home/ubuntu/resourcesNet/book/views.py", line 48, in _block_spider
    return func(*args, **kwargs)
  File "/home/ubuntu/resourcesNet/book/views.py", line 95, in index
    a = Book.objects.filter(book_name__icontains = search)
  File "/usr/local/lib/python3.6/dist-packages/django/db/models/manager.py", line 82, in manager_method
    return getattr(self.get_queryset(), name)(*args, **kwargs)
  File "/usr/local/lib/python3.6/dist-packages/django/db/models/query.py", line 904, in filter
    return self._filter_or_exclude(False, *args, **kwargs)
  File "/usr/local/lib/python3.6/dist-packages/django/db/models/query.py", line 923, in _filter_or_exclude
    clone.query.add_q(Q(*args, **kwargs))
  File "/usr/local/lib/python3.6/dist-packages/django/db/models/sql/query.py", line 1350, in add_q
    clause, _ = self._add_q(q_object, self.used_aliases)
  File "/usr/local/lib/python3.6/dist-packages/django/db/models/sql/query.py", line 1381, in _add_q
    check_filterable=check_filterable,
  File "/usr/local/lib/python3.6/dist-packages/django/db/models/sql/query.py", line 1250, in build_filter
    lookups, parts, reffed_expression = self.solve_lookup_type(arg)
  File "/usr/local/lib/python3.6/dist-packages/django/db/models/sql/query.py", line 1087, in solve_lookup_type
    _, field, _, lookup_parts = self.names_to_path(lookup_splitted, self.get_meta())
  File "/usr/local/lib/python3.6/dist-packages/django/db/models/sql/query.py", line 1483, in names_to_path
    "Choices are: %s" % (name, ", ".join(available)))
django.core.exceptions.FieldError: Cannot resolve keyword 'book_name' into field. Choices are: author, author_book, azw3_download, azw3_flag, catalog, cover, date, douban_id, english_title, epub_download, epub_flag, file_name, id, isbn10, isbn13, kfx_download, kfx_flag, large_cover, mobi_download, mobi_flag, pages, pdf_download, pdf_flag, price, publisher, publisher_book, series, series_book, subtitle, summary, tag_book, tags, title, translator, translator_book, true_douban_id
2020-04-19 20:47:49,629:WARNING:Not Found: /favicon.ico
2020-04-19 20:47:58,213:INFO:{"USER_AGENT": "Mozilla/5.0 (Linux; Android 10; HMA-TL00 Build/HUAWEIHMA-TL00; wv) AppleWebKit/537.36 (KHTML, like Gecko) Version/4.0 Chrome/74.0.3729.186 Mobile Safari/537.36", "PATH_INFO": "/", "REMOTE_HOST": null, "USER_IP": "127.0.0.1"}

2020-04-19 20:48:00,330:INFO:{"USER_AGENT": "Mozilla/5.0 (Linux; Android 10; HMA-TL00 Build/HUAWEIHMA-TL00; wv) AppleWebKit/537.36 (KHTML, like Gecko) Version/4.0 Chrome/74.0.3729.186 Mobile Safari/537.36", "PATH_INFO": "/detail/1005706/", "REMOTE_HOST": null, "USER_IP": "127.0.0.1"}

2020-04-19 20:48:01,962:INFO:{"USER_AGENT": "Mozilla/5.0 (Linux; Android 10; HMA-TL00 Build/HUAWEIHMA-TL00; wv) AppleWebKit/537.36 (KHTML, like Gecko) Version/4.0 Chrome/74.0.3729.186 Mobile Safari/537.36", "PATH_INFO": "/", "REMOTE_HOST": null, "USER_IP": "127.0.0.1"}

2020-04-19 20:48:05,830:INFO:{"USER_AGENT": "Mozilla/5.0 (Linux; Android 10; HMA-TL00 Build/HUAWEIHMA-TL00; wv) AppleWebKit/537.36 (KHTML, like Gecko) Version/4.0 Chrome/74.0.3729.186 Mobile Safari/537.36", "PATH_INFO": "/", "REMOTE_HOST": null, "USER_IP": "127.0.0.1"}

2020-04-19 20:48:05,874:ERROR:Internal Server Error: /
Traceback (most recent call last):
  File "/usr/local/lib/python3.6/dist-packages/django/core/handlers/exception.py", line 34, in inner
    response = get_response(request)
  File "/usr/local/lib/python3.6/dist-packages/django/core/handlers/base.py", line 115, in _get_response
    response = self.process_exception_by_middleware(e, request)
  File "/usr/local/lib/python3.6/dist-packages/django/core/handlers/base.py", line 113, in _get_response
    response = wrapped_callback(request, *callback_args, **callback_kwargs)
  File "/home/ubuntu/resourcesNet/book/views.py", line 64, in _log_record
    return func(*args,**kwargs)
  File "/home/ubuntu/resourcesNet/book/views.py", line 48, in _block_spider
    return func(*args, **kwargs)
  File "/home/ubuntu/resourcesNet/book/views.py", line 95, in index
    a = Book.objects.filter(book_name__icontains = search)
  File "/usr/local/lib/python3.6/dist-packages/django/db/models/manager.py", line 82, in manager_method
    return getattr(self.get_queryset(), name)(*args, **kwargs)
  File "/usr/local/lib/python3.6/dist-packages/django/db/models/query.py", line 904, in filter
    return self._filter_or_exclude(False, *args, **kwargs)
  File "/usr/local/lib/python3.6/dist-packages/django/db/models/query.py", line 923, in _filter_or_exclude
    clone.query.add_q(Q(*args, **kwargs))
  File "/usr/local/lib/python3.6/dist-packages/django/db/models/sql/query.py", line 1350, in add_q
    clause, _ = self._add_q(q_object, self.used_aliases)
  File "/usr/local/lib/python3.6/dist-packages/django/db/models/sql/query.py", line 1381, in _add_q
    check_filterable=check_filterable,
  File "/usr/local/lib/python3.6/dist-packages/django/db/models/sql/query.py", line 1250, in build_filter
    lookups, parts, reffed_expression = self.solve_lookup_type(arg)
  File "/usr/local/lib/python3.6/dist-packages/django/db/models/sql/query.py", line 1087, in solve_lookup_type
    _, field, _, lookup_parts = self.names_to_path(lookup_splitted, self.get_meta())
  File "/usr/local/lib/python3.6/dist-packages/django/db/models/sql/query.py", line 1483, in names_to_path
    "Choices are: %s" % (name, ", ".join(available)))
django.core.exceptions.FieldError: Cannot resolve keyword 'book_name' into field. Choices are: author, author_book, azw3_download, azw3_flag, catalog, cover, date, douban_id, english_title, epub_download, epub_flag, file_name, id, isbn10, isbn13, kfx_download, kfx_flag, large_cover, mobi_download, mobi_flag, pages, pdf_download, pdf_flag, price, publisher, publisher_book, series, series_book, subtitle, summary, tag_book, tags, title, translator, translator_book, true_douban_id
2020-04-19 20:48:06,849:WARNING:Not Found: /favicon.ico
2020-04-19 20:48:16,874:INFO:{"USER_AGENT": "Mozilla/5.0 (Linux; Android 8.1.0; vivo X9s Build/OPM1.171019.019; wv) AppleWebKit/537.36 (KHTML, like Gecko) Version/4.0 Chrome/62.0.3202.84 Mobile Safari/537.36", "PATH_INFO": "/", "REMOTE_HOST": null, "USER_IP": "127.0.0.1"}

2020-04-19 20:49:13,947:INFO:{"USER_AGENT": "Mozilla/5.0 (Linux; Android 10; MI 8 Build/QKQ1.190828.002; wv) AppleWebKit/537.36 (KHTML, like Gecko) Version/4.0 Chrome/78.0.3904.96 Mobile Safari/537.36 (#Build; Xiaomi; MI 8; QKQ1.190828.002 test-keys; 10) +CoolMarket/10.0.4", "PATH_INFO": "/", "REMOTE_HOST": null, "USER_IP": "127.0.0.1"}

2020-04-19 20:50:21,845:INFO:{"USER_AGENT": "Mozilla/5.0 (Linux; Android 9; HLK-AL00 Build/HONORHLK-AL00; wv) AppleWebKit/537.36 (KHTML, like Gecko) Version/4.0 Chrome/70.0.3538.64 Mobile Safari/537.36 (#Build; HONOR; HLK-AL00; HLK-AL00 9.1.1.156(C00E150R6P2); 9) +CoolMarket/10.0.3", "PATH_INFO": "/", "REMOTE_HOST": null, "USER_IP": "127.0.0.1"}

2020-04-19 20:50:39,280:INFO:{"USER_AGENT": "Mozilla/5.0 (Windows NT 10.0; Win64; x64) AppleWebKit/537.36 (KHTML, like Gecko) Chrome/81.0.4044.113 Safari/537.36 Edg/81.0.416.58", "PATH_INFO": "/page=2/", "REMOTE_HOST": null, "USER_IP": "127.0.0.1"}

2020-04-19 20:50:42,616:INFO:{"USER_AGENT": "Mozilla/5.0 (Windows NT 10.0; Win64; x64) AppleWebKit/537.36 (KHTML, like Gecko) Chrome/81.0.4044.113 Safari/537.36 Edg/81.0.416.58", "PATH_INFO": "/page=1/", "REMOTE_HOST": null, "USER_IP": "127.0.0.1"}

2020-04-19 20:54:59,891:INFO:{"USER_AGENT": "Mozilla/5.0 (Linux; Android 9; HLK-AL00 Build/HONORHLK-AL00; wv) AppleWebKit/537.36 (KHTML, like Gecko) Version/4.0 Chrome/70.0.3538.64 Mobile Safari/537.36 (#Build; HONOR; HLK-AL00; HLK-AL00 9.1.1.156(C00E150R6P2); 9) +CoolMarket/10.0.3", "PATH_INFO": "/", "REMOTE_HOST": null, "USER_IP": "127.0.0.1"}

2020-04-19 20:54:59,936:ERROR:Internal Server Error: /
Traceback (most recent call last):
  File "/usr/local/lib/python3.6/dist-packages/django/core/handlers/exception.py", line 34, in inner
    response = get_response(request)
  File "/usr/local/lib/python3.6/dist-packages/django/core/handlers/base.py", line 115, in _get_response
    response = self.process_exception_by_middleware(e, request)
  File "/usr/local/lib/python3.6/dist-packages/django/core/handlers/base.py", line 113, in _get_response
    response = wrapped_callback(request, *callback_args, **callback_kwargs)
  File "/home/ubuntu/resourcesNet/book/views.py", line 64, in _log_record
    return func(*args,**kwargs)
  File "/home/ubuntu/resourcesNet/book/views.py", line 48, in _block_spider
    return func(*args, **kwargs)
  File "/home/ubuntu/resourcesNet/book/views.py", line 95, in index
    a = Book.objects.filter(book_name__icontains = search)
  File "/usr/local/lib/python3.6/dist-packages/django/db/models/manager.py", line 82, in manager_method
    return getattr(self.get_queryset(), name)(*args, **kwargs)
  File "/usr/local/lib/python3.6/dist-packages/django/db/models/query.py", line 904, in filter
    return self._filter_or_exclude(False, *args, **kwargs)
  File "/usr/local/lib/python3.6/dist-packages/django/db/models/query.py", line 923, in _filter_or_exclude
    clone.query.add_q(Q(*args, **kwargs))
  File "/usr/local/lib/python3.6/dist-packages/django/db/models/sql/query.py", line 1350, in add_q
    clause, _ = self._add_q(q_object, self.used_aliases)
  File "/usr/local/lib/python3.6/dist-packages/django/db/models/sql/query.py", line 1381, in _add_q
    check_filterable=check_filterable,
  File "/usr/local/lib/python3.6/dist-packages/django/db/models/sql/query.py", line 1250, in build_filter
    lookups, parts, reffed_expression = self.solve_lookup_type(arg)
  File "/usr/local/lib/python3.6/dist-packages/django/db/models/sql/query.py", line 1087, in solve_lookup_type
    _, field, _, lookup_parts = self.names_to_path(lookup_splitted, self.get_meta())
  File "/usr/local/lib/python3.6/dist-packages/django/db/models/sql/query.py", line 1483, in names_to_path
    "Choices are: %s" % (name, ", ".join(available)))
django.core.exceptions.FieldError: Cannot resolve keyword 'book_name' into field. Choices are: author, author_book, azw3_download, azw3_flag, catalog, cover, date, douban_id, english_title, epub_download, epub_flag, file_name, id, isbn10, isbn13, kfx_download, kfx_flag, large_cover, mobi_download, mobi_flag, pages, pdf_download, pdf_flag, price, publisher, publisher_book, series, series_book, subtitle, summary, tag_book, tags, title, translator, translator_book, true_douban_id
2020-04-19 20:55:01,355:WARNING:Not Found: /favicon.ico
2020-04-19 20:55:03,219:INFO:{"USER_AGENT": "Mozilla/5.0 (Linux; Android 9; HLK-AL00 Build/HONORHLK-AL00; wv) AppleWebKit/537.36 (KHTML, like Gecko) Version/4.0 Chrome/70.0.3538.64 Mobile Safari/537.36 (#Build; HONOR; HLK-AL00; HLK-AL00 9.1.1.156(C00E150R6P2); 9) +CoolMarket/10.0.3", "PATH_INFO": "/", "REMOTE_HOST": null, "USER_IP": "127.0.0.1"}

2020-04-19 20:55:05,492:INFO:{"USER_AGENT": "Mozilla/5.0 (Linux; Android 9; HLK-AL00 Build/HONORHLK-AL00; wv) AppleWebKit/537.36 (KHTML, like Gecko) Version/4.0 Chrome/70.0.3538.64 Mobile Safari/537.36 (#Build; HONOR; HLK-AL00; HLK-AL00 9.1.1.156(C00E150R6P2); 9) +CoolMarket/10.0.3", "PATH_INFO": "/", "REMOTE_HOST": null, "USER_IP": "127.0.0.1"}

2020-04-19 20:55:05,535:ERROR:Internal Server Error: /
Traceback (most recent call last):
  File "/usr/local/lib/python3.6/dist-packages/django/core/handlers/exception.py", line 34, in inner
    response = get_response(request)
  File "/usr/local/lib/python3.6/dist-packages/django/core/handlers/base.py", line 115, in _get_response
    response = self.process_exception_by_middleware(e, request)
  File "/usr/local/lib/python3.6/dist-packages/django/core/handlers/base.py", line 113, in _get_response
    response = wrapped_callback(request, *callback_args, **callback_kwargs)
  File "/home/ubuntu/resourcesNet/book/views.py", line 64, in _log_record
    return func(*args,**kwargs)
  File "/home/ubuntu/resourcesNet/book/views.py", line 48, in _block_spider
    return func(*args, **kwargs)
  File "/home/ubuntu/resourcesNet/book/views.py", line 95, in index
    a = Book.objects.filter(book_name__icontains = search)
  File "/usr/local/lib/python3.6/dist-packages/django/db/models/manager.py", line 82, in manager_method
    return getattr(self.get_queryset(), name)(*args, **kwargs)
  File "/usr/local/lib/python3.6/dist-packages/django/db/models/query.py", line 904, in filter
    return self._filter_or_exclude(False, *args, **kwargs)
  File "/usr/local/lib/python3.6/dist-packages/django/db/models/query.py", line 923, in _filter_or_exclude
    clone.query.add_q(Q(*args, **kwargs))
  File "/usr/local/lib/python3.6/dist-packages/django/db/models/sql/query.py", line 1350, in add_q
    clause, _ = self._add_q(q_object, self.used_aliases)
  File "/usr/local/lib/python3.6/dist-packages/django/db/models/sql/query.py", line 1381, in _add_q
    check_filterable=check_filterable,
  File "/usr/local/lib/python3.6/dist-packages/django/db/models/sql/query.py", line 1250, in build_filter
    lookups, parts, reffed_expression = self.solve_lookup_type(arg)
  File "/usr/local/lib/python3.6/dist-packages/django/db/models/sql/query.py", line 1087, in solve_lookup_type
    _, field, _, lookup_parts = self.names_to_path(lookup_splitted, self.get_meta())
  File "/usr/local/lib/python3.6/dist-packages/django/db/models/sql/query.py", line 1483, in names_to_path
    "Choices are: %s" % (name, ", ".join(available)))
django.core.exceptions.FieldError: Cannot resolve keyword 'book_name' into field. Choices are: author, author_book, azw3_download, azw3_flag, catalog, cover, date, douban_id, english_title, epub_download, epub_flag, file_name, id, isbn10, isbn13, kfx_download, kfx_flag, large_cover, mobi_download, mobi_flag, pages, pdf_download, pdf_flag, price, publisher, publisher_book, series, series_book, subtitle, summary, tag_book, tags, title, translator, translator_book, true_douban_id
2020-04-19 20:55:17,824:INFO:{"USER_AGENT": "Mozilla/5.0 (Linux; Android 9; HLK-AL00 Build/HONORHLK-AL00; wv) AppleWebKit/537.36 (KHTML, like Gecko) Version/4.0 Chrome/70.0.3538.64 Mobile Safari/537.36 (#Build; HONOR; HLK-AL00; HLK-AL00 9.1.1.156(C00E150R6P2); 9) +CoolMarket/10.0.3", "PATH_INFO": "/page=2/", "REMOTE_HOST": null, "USER_IP": "127.0.0.1"}

2020-04-19 20:55:33,189:INFO:{"USER_AGENT": "Mozilla/5.0 (Linux; Android 9; HLK-AL00 Build/HONORHLK-AL00; wv) AppleWebKit/537.36 (KHTML, like Gecko) Version/4.0 Chrome/70.0.3538.64 Mobile Safari/537.36 (#Build; HONOR; HLK-AL00; HLK-AL00 9.1.1.156(C00E150R6P2); 9) +CoolMarket/10.0.3", "PATH_INFO": "/", "REMOTE_HOST": null, "USER_IP": "127.0.0.1"}

2020-04-19 20:55:33,234:ERROR:Internal Server Error: /
Traceback (most recent call last):
  File "/usr/local/lib/python3.6/dist-packages/django/core/handlers/exception.py", line 34, in inner
    response = get_response(request)
  File "/usr/local/lib/python3.6/dist-packages/django/core/handlers/base.py", line 115, in _get_response
    response = self.process_exception_by_middleware(e, request)
  File "/usr/local/lib/python3.6/dist-packages/django/core/handlers/base.py", line 113, in _get_response
    response = wrapped_callback(request, *callback_args, **callback_kwargs)
  File "/home/ubuntu/resourcesNet/book/views.py", line 64, in _log_record
    return func(*args,**kwargs)
  File "/home/ubuntu/resourcesNet/book/views.py", line 48, in _block_spider
    return func(*args, **kwargs)
  File "/home/ubuntu/resourcesNet/book/views.py", line 95, in index
    a = Book.objects.filter(book_name__icontains = search)
  File "/usr/local/lib/python3.6/dist-packages/django/db/models/manager.py", line 82, in manager_method
    return getattr(self.get_queryset(), name)(*args, **kwargs)
  File "/usr/local/lib/python3.6/dist-packages/django/db/models/query.py", line 904, in filter
    return self._filter_or_exclude(False, *args, **kwargs)
  File "/usr/local/lib/python3.6/dist-packages/django/db/models/query.py", line 923, in _filter_or_exclude
    clone.query.add_q(Q(*args, **kwargs))
  File "/usr/local/lib/python3.6/dist-packages/django/db/models/sql/query.py", line 1350, in add_q
    clause, _ = self._add_q(q_object, self.used_aliases)
  File "/usr/local/lib/python3.6/dist-packages/django/db/models/sql/query.py", line 1381, in _add_q
    check_filterable=check_filterable,
  File "/usr/local/lib/python3.6/dist-packages/django/db/models/sql/query.py", line 1250, in build_filter
    lookups, parts, reffed_expression = self.solve_lookup_type(arg)
  File "/usr/local/lib/python3.6/dist-packages/django/db/models/sql/query.py", line 1087, in solve_lookup_type
    _, field, _, lookup_parts = self.names_to_path(lookup_splitted, self.get_meta())
  File "/usr/local/lib/python3.6/dist-packages/django/db/models/sql/query.py", line 1483, in names_to_path
    "Choices are: %s" % (name, ", ".join(available)))
django.core.exceptions.FieldError: Cannot resolve keyword 'book_name' into field. Choices are: author, author_book, azw3_download, azw3_flag, catalog, cover, date, douban_id, english_title, epub_download, epub_flag, file_name, id, isbn10, isbn13, kfx_download, kfx_flag, large_cover, mobi_download, mobi_flag, pages, pdf_download, pdf_flag, price, publisher, publisher_book, series, series_book, subtitle, summary, tag_book, tags, title, translator, translator_book, true_douban_id
2020-04-19 20:55:38,728:INFO:{"USER_AGENT": "Mozilla/5.0 (Linux; Android 9; HLK-AL00 Build/HONORHLK-AL00; wv) AppleWebKit/537.36 (KHTML, like Gecko) Version/4.0 Chrome/70.0.3538.64 Mobile Safari/537.36 (#Build; HONOR; HLK-AL00; HLK-AL00 9.1.1.156(C00E150R6P2); 9) +CoolMarket/10.0.3", "PATH_INFO": "/", "REMOTE_HOST": null, "USER_IP": "127.0.0.1"}

2020-04-19 20:55:38,772:ERROR:Internal Server Error: /
Traceback (most recent call last):
  File "/usr/local/lib/python3.6/dist-packages/django/core/handlers/exception.py", line 34, in inner
    response = get_response(request)
  File "/usr/local/lib/python3.6/dist-packages/django/core/handlers/base.py", line 115, in _get_response
    response = self.process_exception_by_middleware(e, request)
  File "/usr/local/lib/python3.6/dist-packages/django/core/handlers/base.py", line 113, in _get_response
    response = wrapped_callback(request, *callback_args, **callback_kwargs)
  File "/home/ubuntu/resourcesNet/book/views.py", line 64, in _log_record
    return func(*args,**kwargs)
  File "/home/ubuntu/resourcesNet/book/views.py", line 48, in _block_spider
    return func(*args, **kwargs)
  File "/home/ubuntu/resourcesNet/book/views.py", line 95, in index
    a = Book.objects.filter(book_name__icontains = search)
  File "/usr/local/lib/python3.6/dist-packages/django/db/models/manager.py", line 82, in manager_method
    return getattr(self.get_queryset(), name)(*args, **kwargs)
  File "/usr/local/lib/python3.6/dist-packages/django/db/models/query.py", line 904, in filter
    return self._filter_or_exclude(False, *args, **kwargs)
  File "/usr/local/lib/python3.6/dist-packages/django/db/models/query.py", line 923, in _filter_or_exclude
    clone.query.add_q(Q(*args, **kwargs))
  File "/usr/local/lib/python3.6/dist-packages/django/db/models/sql/query.py", line 1350, in add_q
    clause, _ = self._add_q(q_object, self.used_aliases)
  File "/usr/local/lib/python3.6/dist-packages/django/db/models/sql/query.py", line 1381, in _add_q
    check_filterable=check_filterable,
  File "/usr/local/lib/python3.6/dist-packages/django/db/models/sql/query.py", line 1250, in build_filter
    lookups, parts, reffed_expression = self.solve_lookup_type(arg)
  File "/usr/local/lib/python3.6/dist-packages/django/db/models/sql/query.py", line 1087, in solve_lookup_type
    _, field, _, lookup_parts = self.names_to_path(lookup_splitted, self.get_meta())
  File "/usr/local/lib/python3.6/dist-packages/django/db/models/sql/query.py", line 1483, in names_to_path
    "Choices are: %s" % (name, ", ".join(available)))
django.core.exceptions.FieldError: Cannot resolve keyword 'book_name' into field. Choices are: author, author_book, azw3_download, azw3_flag, catalog, cover, date, douban_id, english_title, epub_download, epub_flag, file_name, id, isbn10, isbn13, kfx_download, kfx_flag, large_cover, mobi_download, mobi_flag, pages, pdf_download, pdf_flag, price, publisher, publisher_book, series, series_book, subtitle, summary, tag_book, tags, title, translator, translator_book, true_douban_id
2020-04-19 21:03:04,504:INFO:{"USER_AGENT": "Mozilla/5.0 (Linux; Android 10; COL-AL10) AppleWebKit/537.36 (KHTML, like Gecko) Chrome/80.0.3987.162 Mobile Safari/537.36", "PATH_INFO": "/", "REMOTE_HOST": null, "USER_IP": "127.0.0.1"}

2020-04-19 21:03:21,465:INFO:{"USER_AGENT": "Mozilla/5.0 (Linux; Android 10; COL-AL10 Build/HUAWEICOL-AL10; wv) AppleWebKit/537.36 (KHTML, like Gecko) Version/4.0 Chrome/73.0.3683.121 Mobile Safari/537.36", "PATH_INFO": "/", "REMOTE_HOST": null, "USER_IP": "127.0.0.1"}

2020-04-19 21:04:24,606:INFO:{"USER_AGENT": "Mozilla/5.0 (Linux; U; Android 8.1.0; zh-CN; EML-AL00 Build/HUAWEIEML-AL00) AppleWebKit/537.36 (KHTML, like Gecko) Version/4.0 Chrome/57.0.2987.108 baidu.sogo.uc.UCBrowser/11.9.4.974 UWS/2.13.1.48 Mobile Safari/537.36 AliApp(DingTalk/4.5.11) com.alibaba.android.rimet/10487439 Channel/227200 language/zh-CN", "PATH_INFO": "/", "REMOTE_HOST": null, "USER_IP": "127.0.0.1"}

2020-04-19 21:04:27,125:INFO:{"USER_AGENT": "Mozilla/5.0 (Linux; U; Android 8.1.0; zh-CN; EML-AL00 Build/HUAWEIEML-AL00) AppleWebKit/537.36 (KHTML, like Gecko) Version/4.0 Chrome/57.0.2987.108 baidu.sogo.uc.UCBrowser/11.9.4.974 UWS/2.13.1.48 Mobile Safari/537.36 AliApp(DingTalk/4.5.11) com.alibaba.android.rimet/10487439 Channel/227200 language/zh-CN", "PATH_INFO": "/", "REMOTE_HOST": null, "USER_IP": "127.0.0.1"}

2020-04-19 21:06:08,688:INFO:{"USER_AGENT": "Mozilla/5.0 (Windows NT 10.0; Win64; x64) AppleWebKit/537.36 (KHTML, like Gecko) Chrome/81.0.4044.113 Safari/537.36 Edg/81.0.416.58", "PATH_INFO": "/page=1/", "REMOTE_HOST": null, "USER_IP": "127.0.0.1"}

2020-04-19 21:07:09,087:INFO:{"USER_AGENT": "Mozilla/5.0 (Linux; Android 10; COL-AL10) AppleWebKit/537.36 (KHTML, like Gecko) Chrome/80.0.3987.162 Mobile Safari/537.36", "PATH_INFO": "/", "REMOTE_HOST": null, "USER_IP": "127.0.0.1"}

2020-04-19 21:10:15,201:INFO:{"USER_AGENT": "Mozilla/5.0 (Windows NT 10.0; Win64; x64) AppleWebKit/537.36 (KHTML, like Gecko) Chrome/81.0.4044.113 Safari/537.36 Edg/81.0.416.58", "PATH_INFO": "/page=1/", "REMOTE_HOST": null, "USER_IP": "127.0.0.1"}

2020-04-19 21:10:57,801:INFO:{"USER_AGENT": "Mozilla/5.0 (Windows NT 10.0; Win64; x64) AppleWebKit/537.36 (KHTML, like Gecko) Chrome/81.0.4044.113 Safari/537.36 Edg/81.0.416.58", "PATH_INFO": "/page=1/", "REMOTE_HOST": null, "USER_IP": "127.0.0.1"}

2020-04-19 21:11:07,719:INFO:{"USER_AGENT": "Mozilla/5.0 (iPhone; U; CPU iPhone OS 5_1_1 like Mac OS X; en-us) AppleWebKit/534.46 (KHTML, like Gecko) Version/5.1 Mobile/9B206 Safari/7534.48.3 XiaoMi/MiuiBrowser/11.11.17", "PATH_INFO": "/", "REMOTE_HOST": null, "USER_IP": "127.0.0.1"}

2020-04-19 21:11:15,785:INFO:{"USER_AGENT": "Mozilla/5.0 (Windows NT 10.0; Win64; x64) AppleWebKit/537.36 (KHTML, like Gecko) Chrome/59.0.3071.115 Safari/537.36", "PATH_INFO": "/", "REMOTE_HOST": null, "USER_IP": "127.0.0.1"}

2020-04-19 21:11:19,229:INFO:{"USER_AGENT": "Mozilla/5.0 (Windows NT 10.0; Win64; x64) AppleWebKit/537.36 (KHTML, like Gecko) Chrome/59.0.3071.115 Safari/537.36", "PATH_INFO": "/about/", "REMOTE_HOST": null, "USER_IP": "127.0.0.1"}

2020-04-19 21:11:19,237:INFO:{"USER_AGENT": "Mozilla/5.0 (Windows NT 10.0; Win64; x64) AppleWebKit/537.36 (KHTML, like Gecko) Chrome/59.0.3071.115 Safari/537.36", "PATH_INFO": "/detail/34842086/", "REMOTE_HOST": null, "USER_IP": "127.0.0.1"}

2020-04-19 21:11:21,909:INFO:{"USER_AGENT": "Mozilla/5.0 (iPhone; U; CPU iPhone OS 5_1_1 like Mac OS X; en-us) AppleWebKit/534.46 (KHTML, like Gecko) Version/5.1 Mobile/9B206 Safari/7534.48.3 XiaoMi/MiuiBrowser/11.11.17", "PATH_INFO": "/detail/27081056/", "REMOTE_HOST": null, "USER_IP": "127.0.0.1"}

2020-04-19 21:11:34,065:INFO:{"USER_AGENT": "Mozilla/5.0 (iPhone; U; CPU iPhone OS 5_1_1 like Mac OS X; en-us) AppleWebKit/534.46 (KHTML, like Gecko) Version/5.1 Mobile/9B206 Safari/7534.48.3 XiaoMi/MiuiBrowser/11.11.17", "PATH_INFO": "/", "REMOTE_HOST": null, "USER_IP": "127.0.0.1"}

2020-04-19 21:11:34,110:ERROR:Internal Server Error: /
Traceback (most recent call last):
  File "/usr/local/lib/python3.6/dist-packages/django/core/handlers/exception.py", line 34, in inner
    response = get_response(request)
  File "/usr/local/lib/python3.6/dist-packages/django/core/handlers/base.py", line 115, in _get_response
    response = self.process_exception_by_middleware(e, request)
  File "/usr/local/lib/python3.6/dist-packages/django/core/handlers/base.py", line 113, in _get_response
    response = wrapped_callback(request, *callback_args, **callback_kwargs)
  File "/home/ubuntu/resourcesNet/book/views.py", line 64, in _log_record
    return func(*args,**kwargs)
  File "/home/ubuntu/resourcesNet/book/views.py", line 48, in _block_spider
    return func(*args, **kwargs)
  File "/home/ubuntu/resourcesNet/book/views.py", line 95, in index
    a = Book.objects.filter(book_name__icontains = search)
  File "/usr/local/lib/python3.6/dist-packages/django/db/models/manager.py", line 82, in manager_method
    return getattr(self.get_queryset(), name)(*args, **kwargs)
  File "/usr/local/lib/python3.6/dist-packages/django/db/models/query.py", line 904, in filter
    return self._filter_or_exclude(False, *args, **kwargs)
  File "/usr/local/lib/python3.6/dist-packages/django/db/models/query.py", line 923, in _filter_or_exclude
    clone.query.add_q(Q(*args, **kwargs))
  File "/usr/local/lib/python3.6/dist-packages/django/db/models/sql/query.py", line 1350, in add_q
    clause, _ = self._add_q(q_object, self.used_aliases)
  File "/usr/local/lib/python3.6/dist-packages/django/db/models/sql/query.py", line 1381, in _add_q
    check_filterable=check_filterable,
  File "/usr/local/lib/python3.6/dist-packages/django/db/models/sql/query.py", line 1250, in build_filter
    lookups, parts, reffed_expression = self.solve_lookup_type(arg)
  File "/usr/local/lib/python3.6/dist-packages/django/db/models/sql/query.py", line 1087, in solve_lookup_type
    _, field, _, lookup_parts = self.names_to_path(lookup_splitted, self.get_meta())
  File "/usr/local/lib/python3.6/dist-packages/django/db/models/sql/query.py", line 1483, in names_to_path
    "Choices are: %s" % (name, ", ".join(available)))
django.core.exceptions.FieldError: Cannot resolve keyword 'book_name' into field. Choices are: author, author_book, azw3_download, azw3_flag, catalog, cover, date, douban_id, english_title, epub_download, epub_flag, file_name, id, isbn10, isbn13, kfx_download, kfx_flag, large_cover, mobi_download, mobi_flag, pages, pdf_download, pdf_flag, price, publisher, publisher_book, series, series_book, subtitle, summary, tag_book, tags, title, translator, translator_book, true_douban_id
2020-04-19 21:11:35,652:WARNING:Not Found: /favicon.ico
2020-04-19 21:11:36,748:INFO:{"USER_AGENT": "Mozilla/5.0 (iPhone; U; CPU iPhone OS 5_1_1 like Mac OS X; en-us) AppleWebKit/534.46 (KHTML, like Gecko) Version/5.1 Mobile/9B206 Safari/7534.48.3 XiaoMi/MiuiBrowser/11.11.17", "PATH_INFO": "/", "REMOTE_HOST": null, "USER_IP": "127.0.0.1"}

2020-04-19 21:11:41,918:INFO:{"USER_AGENT": "Mozilla/5.0 (iPhone; U; CPU iPhone OS 5_1_1 like Mac OS X; en-us) AppleWebKit/534.46 (KHTML, like Gecko) Version/5.1 Mobile/9B206 Safari/7534.48.3 XiaoMi/MiuiBrowser/11.11.17", "PATH_INFO": "/", "REMOTE_HOST": null, "USER_IP": "127.0.0.1"}

2020-04-19 21:11:41,962:ERROR:Internal Server Error: /
Traceback (most recent call last):
  File "/usr/local/lib/python3.6/dist-packages/django/core/handlers/exception.py", line 34, in inner
    response = get_response(request)
  File "/usr/local/lib/python3.6/dist-packages/django/core/handlers/base.py", line 115, in _get_response
    response = self.process_exception_by_middleware(e, request)
  File "/usr/local/lib/python3.6/dist-packages/django/core/handlers/base.py", line 113, in _get_response
    response = wrapped_callback(request, *callback_args, **callback_kwargs)
  File "/home/ubuntu/resourcesNet/book/views.py", line 64, in _log_record
    return func(*args,**kwargs)
  File "/home/ubuntu/resourcesNet/book/views.py", line 48, in _block_spider
    return func(*args, **kwargs)
  File "/home/ubuntu/resourcesNet/book/views.py", line 95, in index
    a = Book.objects.filter(book_name__icontains = search)
  File "/usr/local/lib/python3.6/dist-packages/django/db/models/manager.py", line 82, in manager_method
    return getattr(self.get_queryset(), name)(*args, **kwargs)
  File "/usr/local/lib/python3.6/dist-packages/django/db/models/query.py", line 904, in filter
    return self._filter_or_exclude(False, *args, **kwargs)
  File "/usr/local/lib/python3.6/dist-packages/django/db/models/query.py", line 923, in _filter_or_exclude
    clone.query.add_q(Q(*args, **kwargs))
  File "/usr/local/lib/python3.6/dist-packages/django/db/models/sql/query.py", line 1350, in add_q
    clause, _ = self._add_q(q_object, self.used_aliases)
  File "/usr/local/lib/python3.6/dist-packages/django/db/models/sql/query.py", line 1381, in _add_q
    check_filterable=check_filterable,
  File "/usr/local/lib/python3.6/dist-packages/django/db/models/sql/query.py", line 1250, in build_filter
    lookups, parts, reffed_expression = self.solve_lookup_type(arg)
  File "/usr/local/lib/python3.6/dist-packages/django/db/models/sql/query.py", line 1087, in solve_lookup_type
    _, field, _, lookup_parts = self.names_to_path(lookup_splitted, self.get_meta())
  File "/usr/local/lib/python3.6/dist-packages/django/db/models/sql/query.py", line 1483, in names_to_path
    "Choices are: %s" % (name, ", ".join(available)))
django.core.exceptions.FieldError: Cannot resolve keyword 'book_name' into field. Choices are: author, author_book, azw3_download, azw3_flag, catalog, cover, date, douban_id, english_title, epub_download, epub_flag, file_name, id, isbn10, isbn13, kfx_download, kfx_flag, large_cover, mobi_download, mobi_flag, pages, pdf_download, pdf_flag, price, publisher, publisher_book, series, series_book, subtitle, summary, tag_book, tags, title, translator, translator_book, true_douban_id
2020-04-19 21:11:50,156:INFO:{"USER_AGENT": "Mozilla/5.0 (iPhone; U; CPU iPhone OS 5_1_1 like Mac OS X; en-us) AppleWebKit/534.46 (KHTML, like Gecko) Version/5.1 Mobile/9B206 Safari/7534.48.3 XiaoMi/MiuiBrowser/11.11.17", "PATH_INFO": "/", "REMOTE_HOST": null, "USER_IP": "127.0.0.1"}

2020-04-19 21:11:50,201:ERROR:Internal Server Error: /
Traceback (most recent call last):
  File "/usr/local/lib/python3.6/dist-packages/django/core/handlers/exception.py", line 34, in inner
    response = get_response(request)
  File "/usr/local/lib/python3.6/dist-packages/django/core/handlers/base.py", line 115, in _get_response
    response = self.process_exception_by_middleware(e, request)
  File "/usr/local/lib/python3.6/dist-packages/django/core/handlers/base.py", line 113, in _get_response
    response = wrapped_callback(request, *callback_args, **callback_kwargs)
  File "/home/ubuntu/resourcesNet/book/views.py", line 64, in _log_record
    return func(*args,**kwargs)
  File "/home/ubuntu/resourcesNet/book/views.py", line 48, in _block_spider
    return func(*args, **kwargs)
  File "/home/ubuntu/resourcesNet/book/views.py", line 95, in index
    a = Book.objects.filter(book_name__icontains = search)
  File "/usr/local/lib/python3.6/dist-packages/django/db/models/manager.py", line 82, in manager_method
    return getattr(self.get_queryset(), name)(*args, **kwargs)
  File "/usr/local/lib/python3.6/dist-packages/django/db/models/query.py", line 904, in filter
    return self._filter_or_exclude(False, *args, **kwargs)
  File "/usr/local/lib/python3.6/dist-packages/django/db/models/query.py", line 923, in _filter_or_exclude
    clone.query.add_q(Q(*args, **kwargs))
  File "/usr/local/lib/python3.6/dist-packages/django/db/models/sql/query.py", line 1350, in add_q
    clause, _ = self._add_q(q_object, self.used_aliases)
  File "/usr/local/lib/python3.6/dist-packages/django/db/models/sql/query.py", line 1381, in _add_q
    check_filterable=check_filterable,
  File "/usr/local/lib/python3.6/dist-packages/django/db/models/sql/query.py", line 1250, in build_filter
    lookups, parts, reffed_expression = self.solve_lookup_type(arg)
  File "/usr/local/lib/python3.6/dist-packages/django/db/models/sql/query.py", line 1087, in solve_lookup_type
    _, field, _, lookup_parts = self.names_to_path(lookup_splitted, self.get_meta())
  File "/usr/local/lib/python3.6/dist-packages/django/db/models/sql/query.py", line 1483, in names_to_path
    "Choices are: %s" % (name, ", ".join(available)))
django.core.exceptions.FieldError: Cannot resolve keyword 'book_name' into field. Choices are: author, author_book, azw3_download, azw3_flag, catalog, cover, date, douban_id, english_title, epub_download, epub_flag, file_name, id, isbn10, isbn13, kfx_download, kfx_flag, large_cover, mobi_download, mobi_flag, pages, pdf_download, pdf_flag, price, publisher, publisher_book, series, series_book, subtitle, summary, tag_book, tags, title, translator, translator_book, true_douban_id
2020-04-19 21:12:00,526:INFO:{"USER_AGENT": "Mozilla/5.0 (iPhone; U; CPU iPhone OS 5_1_1 like Mac OS X; en-us) AppleWebKit/534.46 (KHTML, like Gecko) Version/5.1 Mobile/9B206 Safari/7534.48.3 XiaoMi/MiuiBrowser/11.11.17", "PATH_INFO": "/", "REMOTE_HOST": null, "USER_IP": "127.0.0.1"}

2020-04-19 21:13:01,934:INFO:{"USER_AGENT": "Mozilla/5.0 (Windows NT 10.0; Win64; x64) AppleWebKit/537.36 (KHTML, like Gecko) Chrome/81.0.4044.113 Safari/537.36 Edg/81.0.416.58", "PATH_INFO": "/page=1/", "REMOTE_HOST": null, "USER_IP": "127.0.0.1"}

2020-04-19 21:13:12,886:INFO:{"USER_AGENT": "Mozilla/5.0 (Windows NT 10.0; Win64; x64) AppleWebKit/537.36 (KHTML, like Gecko) Chrome/81.0.4044.113 Safari/537.36 Edg/81.0.416.58", "PATH_INFO": "/page=1/", "REMOTE_HOST": null, "USER_IP": "127.0.0.1"}

2020-04-19 21:13:15,803:INFO:{"USER_AGENT": "Mozilla/5.0 (Windows NT 10.0; Win64; x64) AppleWebKit/537.36 (KHTML, like Gecko) Chrome/81.0.4044.113 Safari/537.36 Edg/81.0.416.58", "PATH_INFO": "/page=1/", "REMOTE_HOST": null, "USER_IP": "127.0.0.1"}

2020-04-19 21:13:49,691:INFO:{"USER_AGENT": "Mozilla/5.0 (Windows NT 10.0; Win64; x64) AppleWebKit/537.36 (KHTML, like Gecko) Chrome/81.0.4044.113 Safari/537.36 Edg/81.0.416.58", "PATH_INFO": "/page=1/", "REMOTE_HOST": null, "USER_IP": "127.0.0.1"}

2020-04-19 21:13:54,121:INFO:{"USER_AGENT": "Mozilla/5.0 (Windows NT 10.0; Win64; x64) AppleWebKit/537.36 (KHTML, like Gecko) Chrome/81.0.4044.113 Safari/537.36 Edg/81.0.416.58", "PATH_INFO": "/page=1/", "REMOTE_HOST": null, "USER_IP": "127.0.0.1"}

2020-04-19 21:14:14,711:INFO:{"USER_AGENT": "Mozilla/5.0 (Linux; Android 9; MHA-TL00 Build/HUAWEIMHA-TL00; wv) AppleWebKit/537.36 (KHTML, like Gecko) Version/4.0 Chrome/79.0.3945.116 Mobile Safari/537.36 (#Build; HUAWEI; MHA-TL00; MHA-TL00 9.1.0.220(C01E219R1P14); 9) +CoolMarket/10.0.3", "PATH_INFO": "/", "REMOTE_HOST": null, "USER_IP": "127.0.0.1"}

2020-04-19 21:14:24,920:INFO:{"USER_AGENT": "Mozilla/5.0 (Windows NT 10.0; Win64; x64) AppleWebKit/537.36 (KHTML, like Gecko) Chrome/81.0.4044.113 Safari/537.36 Edg/81.0.416.58", "PATH_INFO": "/", "REMOTE_HOST": null, "USER_IP": "127.0.0.1"}

2020-04-19 21:14:24,966:ERROR:Internal Server Error: /
Traceback (most recent call last):
  File "/usr/local/lib/python3.6/dist-packages/django/core/handlers/exception.py", line 34, in inner
    response = get_response(request)
  File "/usr/local/lib/python3.6/dist-packages/django/core/handlers/base.py", line 115, in _get_response
    response = self.process_exception_by_middleware(e, request)
  File "/usr/local/lib/python3.6/dist-packages/django/core/handlers/base.py", line 113, in _get_response
    response = wrapped_callback(request, *callback_args, **callback_kwargs)
  File "/home/ubuntu/resourcesNet/book/views.py", line 64, in _log_record
    return func(*args,**kwargs)
  File "/home/ubuntu/resourcesNet/book/views.py", line 48, in _block_spider
    return func(*args, **kwargs)
  File "/home/ubuntu/resourcesNet/book/views.py", line 95, in index
    a = Book.objects.filter(book_name__icontains = search)
  File "/usr/local/lib/python3.6/dist-packages/django/db/models/manager.py", line 82, in manager_method
    return getattr(self.get_queryset(), name)(*args, **kwargs)
  File "/usr/local/lib/python3.6/dist-packages/django/db/models/query.py", line 904, in filter
    return self._filter_or_exclude(False, *args, **kwargs)
  File "/usr/local/lib/python3.6/dist-packages/django/db/models/query.py", line 923, in _filter_or_exclude
    clone.query.add_q(Q(*args, **kwargs))
  File "/usr/local/lib/python3.6/dist-packages/django/db/models/sql/query.py", line 1350, in add_q
    clause, _ = self._add_q(q_object, self.used_aliases)
  File "/usr/local/lib/python3.6/dist-packages/django/db/models/sql/query.py", line 1381, in _add_q
    check_filterable=check_filterable,
  File "/usr/local/lib/python3.6/dist-packages/django/db/models/sql/query.py", line 1250, in build_filter
    lookups, parts, reffed_expression = self.solve_lookup_type(arg)
  File "/usr/local/lib/python3.6/dist-packages/django/db/models/sql/query.py", line 1087, in solve_lookup_type
    _, field, _, lookup_parts = self.names_to_path(lookup_splitted, self.get_meta())
  File "/usr/local/lib/python3.6/dist-packages/django/db/models/sql/query.py", line 1483, in names_to_path
    "Choices are: %s" % (name, ", ".join(available)))
django.core.exceptions.FieldError: Cannot resolve keyword 'book_name' into field. Choices are: author, author_book, azw3_download, azw3_flag, catalog, cover, date, douban_id, english_title, epub_download, epub_flag, file_name, id, isbn10, isbn13, kfx_download, kfx_flag, large_cover, mobi_download, mobi_flag, pages, pdf_download, pdf_flag, price, publisher, publisher_book, series, series_book, subtitle, summary, tag_book, tags, title, translator, translator_book, true_douban_id
2020-04-19 21:14:32,132:INFO:{"USER_AGENT": "Mozilla/5.0 (Windows NT 10.0; Win64; x64) AppleWebKit/537.36 (KHTML, like Gecko) Chrome/81.0.4044.113 Safari/537.36 Edg/81.0.416.58", "PATH_INFO": "/page=1/", "REMOTE_HOST": null, "USER_IP": "127.0.0.1"}

2020-04-19 21:14:36,685:INFO:{"USER_AGENT": "Mozilla/5.0 (Windows NT 10.0; Win64; x64) AppleWebKit/537.36 (KHTML, like Gecko) Chrome/81.0.4044.113 Safari/537.36 Edg/81.0.416.58", "PATH_INFO": "/page=1/", "REMOTE_HOST": null, "USER_IP": "127.0.0.1"}

2020-04-19 21:14:39,746:INFO:{"USER_AGENT": "Mozilla/5.0 (Windows NT 10.0; Win64; x64) AppleWebKit/537.36 (KHTML, like Gecko) Chrome/81.0.4044.113 Safari/537.36 Edg/81.0.416.58", "PATH_INFO": "/", "REMOTE_HOST": null, "USER_IP": "127.0.0.1"}

2020-04-19 21:15:24,038:INFO:{"USER_AGENT": "Mozilla/5.0 (Windows NT 10.0; Win64; x64) AppleWebKit/537.36 (KHTML, like Gecko) Chrome/81.0.4044.113 Safari/537.36 Edg/81.0.416.58", "PATH_INFO": "/", "REMOTE_HOST": null, "USER_IP": "127.0.0.1"}

2020-04-19 21:15:51,308:INFO:{"USER_AGENT": "Mozilla/5.0 (Windows NT 10.0; Win64; x64) AppleWebKit/537.36 (KHTML, like Gecko) Chrome/81.0.4044.113 Safari/537.36 Edg/81.0.416.58", "PATH_INFO": "/", "REMOTE_HOST": null, "USER_IP": "127.0.0.1"}

2020-04-19 21:16:07,760:INFO:{"USER_AGENT": "Mozilla/5.0 (Windows NT 10.0; Win64; x64) AppleWebKit/537.36 (KHTML, like Gecko) Chrome/81.0.4044.113 Safari/537.36 Edg/81.0.416.58", "PATH_INFO": "/detail/34842086/", "REMOTE_HOST": null, "USER_IP": "127.0.0.1"}

2020-04-19 21:17:36,801:INFO:{"USER_AGENT": "Mozilla/5.0 (Linux; Android 10; HMA-TL00 Build/HUAWEIHMA-TL00; wv) AppleWebKit/537.36 (KHTML, like Gecko) Version/4.0 Chrome/74.0.3729.186 Mobile Safari/537.36 (#Build; HUAWEI; HMA-TL00; HMA-TL00 10.0.0.188(C01E76R2P8); 10) +CoolMarket/10.0.4", "PATH_INFO": "/", "REMOTE_HOST": null, "USER_IP": "127.0.0.1"}

2020-04-19 21:17:46,666:INFO:{"USER_AGENT": "Mozilla/5.0 (Linux; Android 10; HMA-TL00 Build/HUAWEIHMA-TL00; wv) AppleWebKit/537.36 (KHTML, like Gecko) Version/4.0 Chrome/74.0.3729.186 Mobile Safari/537.36 (#Build; HUAWEI; HMA-TL00; HMA-TL00 10.0.0.188(C01E76R2P8); 10) +CoolMarket/10.0.4", "PATH_INFO": "/", "REMOTE_HOST": null, "USER_IP": "127.0.0.1"}

2020-04-19 21:18:22,122:INFO:{"USER_AGENT": "Mozilla/5.0 (Linux; Android 10; HMA-TL00 Build/HUAWEIHMA-TL00; wv) AppleWebKit/537.36 (KHTML, like Gecko) Version/4.0 Chrome/74.0.3729.186 Mobile Safari/537.36", "PATH_INFO": "/", "REMOTE_HOST": null, "USER_IP": "127.0.0.1"}

2020-04-19 21:19:09,510:INFO:{"USER_AGENT": "Mozilla/5.0 (X11; U; Linux armv7l like Android; en-us) AppleWebKit/531.2+ (KHTML, like Gecko) Version/5.0 Safari/533.2+ Kindle/3.0+", "PATH_INFO": "/", "REMOTE_HOST": null, "USER_IP": "127.0.0.1"}

2020-04-19 21:19:14,832:INFO:{"USER_AGENT": "Mozilla/5.0 (Windows NT 10.0; Win64; x64) AppleWebKit/537.36 (KHTML, like Gecko) Chrome/81.0.4044.113 Safari/537.36 Edg/81.0.416.58", "PATH_INFO": "/", "REMOTE_HOST": null, "USER_IP": "127.0.0.1"}

2020-04-19 21:19:14,878:ERROR:Internal Server Error: /
Traceback (most recent call last):
  File "/usr/local/lib/python3.6/dist-packages/django/core/handlers/exception.py", line 34, in inner
    response = get_response(request)
  File "/usr/local/lib/python3.6/dist-packages/django/core/handlers/base.py", line 115, in _get_response
    response = self.process_exception_by_middleware(e, request)
  File "/usr/local/lib/python3.6/dist-packages/django/core/handlers/base.py", line 113, in _get_response
    response = wrapped_callback(request, *callback_args, **callback_kwargs)
  File "/home/ubuntu/resourcesNet/book/views.py", line 64, in _log_record
    return func(*args,**kwargs)
  File "/home/ubuntu/resourcesNet/book/views.py", line 48, in _block_spider
    return func(*args, **kwargs)
  File "/home/ubuntu/resourcesNet/book/views.py", line 95, in index
    a = Book.objects.filter(book_name__icontains = search)
  File "/usr/local/lib/python3.6/dist-packages/django/db/models/manager.py", line 82, in manager_method
    return getattr(self.get_queryset(), name)(*args, **kwargs)
  File "/usr/local/lib/python3.6/dist-packages/django/db/models/query.py", line 904, in filter
    return self._filter_or_exclude(False, *args, **kwargs)
  File "/usr/local/lib/python3.6/dist-packages/django/db/models/query.py", line 923, in _filter_or_exclude
    clone.query.add_q(Q(*args, **kwargs))
  File "/usr/local/lib/python3.6/dist-packages/django/db/models/sql/query.py", line 1350, in add_q
    clause, _ = self._add_q(q_object, self.used_aliases)
  File "/usr/local/lib/python3.6/dist-packages/django/db/models/sql/query.py", line 1381, in _add_q
    check_filterable=check_filterable,
  File "/usr/local/lib/python3.6/dist-packages/django/db/models/sql/query.py", line 1250, in build_filter
    lookups, parts, reffed_expression = self.solve_lookup_type(arg)
  File "/usr/local/lib/python3.6/dist-packages/django/db/models/sql/query.py", line 1087, in solve_lookup_type
    _, field, _, lookup_parts = self.names_to_path(lookup_splitted, self.get_meta())
  File "/usr/local/lib/python3.6/dist-packages/django/db/models/sql/query.py", line 1483, in names_to_path
    "Choices are: %s" % (name, ", ".join(available)))
django.core.exceptions.FieldError: Cannot resolve keyword 'book_name' into field. Choices are: author, author_book, azw3_download, azw3_flag, catalog, cover, date, douban_id, english_title, epub_download, epub_flag, file_name, id, isbn10, isbn13, kfx_download, kfx_flag, large_cover, mobi_download, mobi_flag, pages, pdf_download, pdf_flag, price, publisher, publisher_book, series, series_book, subtitle, summary, tag_book, tags, title, translator, translator_book, true_douban_id
2020-04-19 21:19:48,502:INFO:{"USER_AGENT": "Mozilla/5.0 (X11; U; Linux armv7l like Android; en-us) AppleWebKit/531.2+ (KHTML, like Gecko) Version/5.0 Safari/533.2+ Kindle/3.0+", "PATH_INFO": "/", "REMOTE_HOST": null, "USER_IP": "127.0.0.1"}

2020-04-19 21:19:48,548:ERROR:Internal Server Error: /
Traceback (most recent call last):
  File "/usr/local/lib/python3.6/dist-packages/django/core/handlers/exception.py", line 34, in inner
    response = get_response(request)
  File "/usr/local/lib/python3.6/dist-packages/django/core/handlers/base.py", line 115, in _get_response
    response = self.process_exception_by_middleware(e, request)
  File "/usr/local/lib/python3.6/dist-packages/django/core/handlers/base.py", line 113, in _get_response
    response = wrapped_callback(request, *callback_args, **callback_kwargs)
  File "/home/ubuntu/resourcesNet/book/views.py", line 64, in _log_record
    return func(*args,**kwargs)
  File "/home/ubuntu/resourcesNet/book/views.py", line 48, in _block_spider
    return func(*args, **kwargs)
  File "/home/ubuntu/resourcesNet/book/views.py", line 95, in index
    a = Book.objects.filter(book_name__icontains = search)
  File "/usr/local/lib/python3.6/dist-packages/django/db/models/manager.py", line 82, in manager_method
    return getattr(self.get_queryset(), name)(*args, **kwargs)
  File "/usr/local/lib/python3.6/dist-packages/django/db/models/query.py", line 904, in filter
    return self._filter_or_exclude(False, *args, **kwargs)
  File "/usr/local/lib/python3.6/dist-packages/django/db/models/query.py", line 923, in _filter_or_exclude
    clone.query.add_q(Q(*args, **kwargs))
  File "/usr/local/lib/python3.6/dist-packages/django/db/models/sql/query.py", line 1350, in add_q
    clause, _ = self._add_q(q_object, self.used_aliases)
  File "/usr/local/lib/python3.6/dist-packages/django/db/models/sql/query.py", line 1381, in _add_q
    check_filterable=check_filterable,
  File "/usr/local/lib/python3.6/dist-packages/django/db/models/sql/query.py", line 1250, in build_filter
    lookups, parts, reffed_expression = self.solve_lookup_type(arg)
  File "/usr/local/lib/python3.6/dist-packages/django/db/models/sql/query.py", line 1087, in solve_lookup_type
    _, field, _, lookup_parts = self.names_to_path(lookup_splitted, self.get_meta())
  File "/usr/local/lib/python3.6/dist-packages/django/db/models/sql/query.py", line 1483, in names_to_path
    "Choices are: %s" % (name, ", ".join(available)))
django.core.exceptions.FieldError: Cannot resolve keyword 'book_name' into field. Choices are: author, author_book, azw3_download, azw3_flag, catalog, cover, date, douban_id, english_title, epub_download, epub_flag, file_name, id, isbn10, isbn13, kfx_download, kfx_flag, large_cover, mobi_download, mobi_flag, pages, pdf_download, pdf_flag, price, publisher, publisher_book, series, series_book, subtitle, summary, tag_book, tags, title, translator, translator_book, true_douban_id
2020-04-19 21:19:50,905:WARNING:Not Found: /favicon.ico
2020-04-19 21:20:12,737:INFO:{"USER_AGENT": "Mozilla/5.0 (X11; U; Linux armv7l like Android; en-us) AppleWebKit/531.2+ (KHTML, like Gecko) Version/5.0 Safari/533.2+ Kindle/3.0+", "PATH_INFO": "/", "REMOTE_HOST": null, "USER_IP": "127.0.0.1"}

2020-04-19 21:20:27,154:INFO:{"USER_AGENT": "Mozilla/5.0 (X11; U; Linux armv7l like Android; en-us) AppleWebKit/531.2+ (KHTML, like Gecko) Version/5.0 Safari/533.2+ Kindle/3.0+", "PATH_INFO": "/detail/26280924/", "REMOTE_HOST": null, "USER_IP": "127.0.0.1"}

2020-04-19 21:20:59,357:INFO:{"USER_AGENT": "Mozilla/5.0 (X11; U; Linux armv7l like Android; en-us) AppleWebKit/531.2+ (KHTML, like Gecko) Version/5.0 Safari/533.2+ Kindle/3.0+", "PATH_INFO": "/", "REMOTE_HOST": null, "USER_IP": "127.0.0.1"}

2020-04-19 21:22:59,275:INFO:{"USER_AGENT": "Mozilla/5.0 (Windows NT 10.0; Win64; x64) AppleWebKit/537.36 (KHTML, like Gecko) Chrome/81.0.4044.113 Safari/537.36 Edg/81.0.416.58", "PATH_INFO": "/", "REMOTE_HOST": null, "USER_IP": "127.0.0.1"}

2020-04-19 21:23:02,889:INFO:{"USER_AGENT": "Mozilla/5.0 (Windows NT 10.0; Win64; x64) AppleWebKit/537.36 (KHTML, like Gecko) Chrome/81.0.4044.113 Safari/537.36 Edg/81.0.416.58", "PATH_INFO": "/", "REMOTE_HOST": null, "USER_IP": "127.0.0.1"}

2020-04-19 21:23:02,953:ERROR:Internal Server Error: /
Traceback (most recent call last):
  File "/usr/local/lib/python3.6/dist-packages/django/core/handlers/exception.py", line 34, in inner
    response = get_response(request)
  File "/usr/local/lib/python3.6/dist-packages/django/core/handlers/base.py", line 115, in _get_response
    response = self.process_exception_by_middleware(e, request)
  File "/usr/local/lib/python3.6/dist-packages/django/core/handlers/base.py", line 113, in _get_response
    response = wrapped_callback(request, *callback_args, **callback_kwargs)
  File "/home/ubuntu/resourcesNet/book/views.py", line 64, in _log_record
    return func(*args,**kwargs)
  File "/home/ubuntu/resourcesNet/book/views.py", line 48, in _block_spider
    return func(*args, **kwargs)
  File "/home/ubuntu/resourcesNet/book/views.py", line 95, in index
    a = Book.objects.filter(book_name__icontains = search)
  File "/usr/local/lib/python3.6/dist-packages/django/db/models/manager.py", line 82, in manager_method
    return getattr(self.get_queryset(), name)(*args, **kwargs)
  File "/usr/local/lib/python3.6/dist-packages/django/db/models/query.py", line 904, in filter
    return self._filter_or_exclude(False, *args, **kwargs)
  File "/usr/local/lib/python3.6/dist-packages/django/db/models/query.py", line 923, in _filter_or_exclude
    clone.query.add_q(Q(*args, **kwargs))
  File "/usr/local/lib/python3.6/dist-packages/django/db/models/sql/query.py", line 1350, in add_q
    clause, _ = self._add_q(q_object, self.used_aliases)
  File "/usr/local/lib/python3.6/dist-packages/django/db/models/sql/query.py", line 1381, in _add_q
    check_filterable=check_filterable,
  File "/usr/local/lib/python3.6/dist-packages/django/db/models/sql/query.py", line 1250, in build_filter
    lookups, parts, reffed_expression = self.solve_lookup_type(arg)
  File "/usr/local/lib/python3.6/dist-packages/django/db/models/sql/query.py", line 1087, in solve_lookup_type
    _, field, _, lookup_parts = self.names_to_path(lookup_splitted, self.get_meta())
  File "/usr/local/lib/python3.6/dist-packages/django/db/models/sql/query.py", line 1483, in names_to_path
    "Choices are: %s" % (name, ", ".join(available)))
django.core.exceptions.FieldError: Cannot resolve keyword 'book_name' into field. Choices are: author, author_book, azw3_download, azw3_flag, catalog, cover, date, douban_id, english_title, epub_download, epub_flag, file_name, id, isbn10, isbn13, kfx_download, kfx_flag, large_cover, mobi_download, mobi_flag, pages, pdf_download, pdf_flag, price, publisher, publisher_book, series, series_book, subtitle, summary, tag_book, tags, title, translator, translator_book, true_douban_id
2020-04-19 21:37:06,601:INFO:{"USER_AGENT": "Mozilla/5.0 (Windows NT 10.0; Win64; x64) AppleWebKit/537.36 (KHTML, like Gecko) Chrome/81.0.4044.113 Safari/537.36 Edg/81.0.416.58", "PATH_INFO": "/", "REMOTE_HOST": null, "USER_IP": "127.0.0.1"}

2020-04-19 21:37:15,090:INFO:{"USER_AGENT": "Mozilla/5.0 (Windows NT 10.0; Win64; x64) AppleWebKit/537.36 (KHTML, like Gecko) Chrome/81.0.4044.113 Safari/537.36 Edg/81.0.416.58", "PATH_INFO": "/", "REMOTE_HOST": null, "USER_IP": "127.0.0.1"}

2020-04-19 21:37:17,703:INFO:{"USER_AGENT": "Mozilla/5.0 (Windows NT 10.0; Win64; x64) AppleWebKit/537.36 (KHTML, like Gecko) Chrome/81.0.4044.113 Safari/537.36 Edg/81.0.416.58", "PATH_INFO": "/", "REMOTE_HOST": null, "USER_IP": "127.0.0.1"}

2020-04-19 21:37:45,459:INFO:{"USER_AGENT": "Mozilla/5.0 (Windows NT 10.0; Win64; x64) AppleWebKit/537.36 (KHTML, like Gecko) Chrome/81.0.4044.113 Safari/537.36 Edg/81.0.416.58", "PATH_INFO": "/page=2/", "REMOTE_HOST": null, "USER_IP": "127.0.0.1"}

2020-04-19 21:37:50,844:INFO:{"USER_AGENT": "Mozilla/5.0 (Windows NT 10.0; Win64; x64) AppleWebKit/537.36 (KHTML, like Gecko) Chrome/81.0.4044.113 Safari/537.36 Edg/81.0.416.58", "PATH_INFO": "/page=1/", "REMOTE_HOST": null, "USER_IP": "127.0.0.1"}

2020-04-19 21:40:36,045:INFO:{"USER_AGENT": "Mozilla/5.0 (Windows NT 10.0; Win64; x64) AppleWebKit/537.36 (KHTML, like Gecko) Chrome/81.0.4044.113 Safari/537.36 Edg/81.0.416.58", "PATH_INFO": "/page=1/", "REMOTE_HOST": null, "USER_IP": "127.0.0.1"}

2020-04-19 21:41:55,443:INFO:{"USER_AGENT": "Mozilla/5.0 (iPhone; U; CPU iPhone OS 5_1_1 like Mac OS X; en-us) AppleWebKit/534.46 (KHTML, like Gecko) Version/5.1 Mobile/9B206 Safari/7534.48.3 XiaoMi/MiuiBrowser/11.11.17", "PATH_INFO": "/", "REMOTE_HOST": null, "USER_IP": "127.0.0.1"}

2020-04-19 21:41:56,930:INFO:{"USER_AGENT": "Mozilla/5.0 (Windows NT 10.0; Win64; x64) AppleWebKit/537.36 (KHTML, like Gecko) Chrome/46.0.2486.0 Safari/537.36 Edge/13.10586", "PATH_INFO": "/", "REMOTE_HOST": null, "USER_IP": "127.0.0.1"}

2020-04-19 21:41:57,737:INFO:{"USER_AGENT": "Mozilla/5.0 (Windows NT 10.0; Win64; x64) AppleWebKit/537.36 (KHTML, like Gecko) Chrome/46.0.2486.0 Safari/537.36 Edge/13.10586", "PATH_INFO": "/about/", "REMOTE_HOST": null, "USER_IP": "127.0.0.1"}

2020-04-19 21:41:57,812:INFO:{"USER_AGENT": "Mozilla/5.0 (Windows NT 10.0; Win64; x64) AppleWebKit/537.36 (KHTML, like Gecko) Chrome/46.0.2486.0 Safari/537.36 Edge/13.10586", "PATH_INFO": "/detail/34842086/", "REMOTE_HOST": null, "USER_IP": "127.0.0.1"}

2020-04-19 21:41:59,835:INFO:{"USER_AGENT": "Mozilla/5.0 (iPhone; U; CPU iPhone OS 5_1_1 like Mac OS X; en-us) AppleWebKit/534.46 (KHTML, like Gecko) Version/5.1 Mobile/9B206 Safari/7534.48.3 XiaoMi/MiuiBrowser/11.11.17", "PATH_INFO": "/page=2/", "REMOTE_HOST": null, "USER_IP": "127.0.0.1"}

2020-04-19 21:42:49,253:ERROR:Internal Server Error: /postbox/
Traceback (most recent call last):
  File "/usr/local/lib/python3.6/dist-packages/django/core/handlers/exception.py", line 34, in inner
    response = get_response(request)
  File "/usr/local/lib/python3.6/dist-packages/django/core/handlers/base.py", line 115, in _get_response
    response = self.process_exception_by_middleware(e, request)
  File "/usr/local/lib/python3.6/dist-packages/django/core/handlers/base.py", line 113, in _get_response
    response = wrapped_callback(request, *callback_args, **callback_kwargs)
  File "/usr/local/lib/python3.6/dist-packages/django/views/decorators/csrf.py", line 54, in wrapped_view
    return view_func(*args, **kwargs)
  File "/home/ubuntu/resourcesNet/book/views.py", line 267, in postbox
    if b.data:
AttributeError: 'Book' object has no attribute 'data'
2020-04-19 21:54:30,348:INFO:{"USER_AGENT": "Mozilla/5.0 (Linux; Android 10; Redmi K20 Pro Build/QKQ1.190825.002; wv) AppleWebKit/537.36 (KHTML, like Gecko) Version/4.0 Chrome/80.0.3987.99 Mobile Safari/537.36 (#Build; Xiaomi; Redmi K20 Pro; QKQ1.190825.002 test-keys; 10) +CoolMarket/10.0.4", "PATH_INFO": "/", "REMOTE_HOST": null, "USER_IP": "127.0.0.1"}

2020-04-19 21:54:35,686:INFO:{"USER_AGENT": "Mozilla/5.0 (Linux; Android 10; Redmi K20 Pro Build/QKQ1.190825.002; wv) AppleWebKit/537.36 (KHTML, like Gecko) Version/4.0 Chrome/80.0.3987.99 Mobile Safari/537.36 (#Build; Xiaomi; Redmi K20 Pro; QKQ1.190825.002 test-keys; 10) +CoolMarket/10.0.4", "PATH_INFO": "/", "REMOTE_HOST": null, "USER_IP": "127.0.0.1"}

2020-04-19 21:54:44,266:INFO:{"USER_AGENT": "Mozilla/5.0 (Linux; Android 10; MIX 2S Build/QKQ1.190828.002; wv) AppleWebKit/537.36 (KHTML, like Gecko) Version/4.0 Chrome/78.0.3904.96 Mobile Safari/537.36 (#Build; Xiaomi; MIX 2S; QKQ1.190828.002 test-keys; 10) +CoolMarket/10.0.4", "PATH_INFO": "/", "REMOTE_HOST": null, "USER_IP": "127.0.0.1"}

2020-04-19 21:55:05,559:INFO:{"USER_AGENT": "Mozilla/5.0 (Linux; Android 10; Redmi K20 Pro Build/QKQ1.190825.002; wv) AppleWebKit/537.36 (KHTML, like Gecko) Version/4.0 Chrome/80.0.3987.99 Mobile Safari/537.36 (#Build; Xiaomi; Redmi K20 Pro; QKQ1.190825.002 test-keys; 10) +CoolMarket/10.0.4", "PATH_INFO": "/", "REMOTE_HOST": null, "USER_IP": "127.0.0.1"}

2020-04-19 21:56:12,237:INFO:{"USER_AGENT": "Mozilla/5.0 (Windows NT 10.0; Win64; x64) AppleWebKit/537.36 (KHTML, like Gecko) Chrome/81.0.4044.113 Safari/537.36 Edg/81.0.416.58", "PATH_INFO": "/", "REMOTE_HOST": null, "USER_IP": "127.0.0.1"}

2020-04-19 21:56:31,573:INFO:{"USER_AGENT": "Mozilla/5.0 (Windows NT 10.0; Win64; x64) AppleWebKit/537.36 (KHTML, like Gecko) Chrome/81.0.4044.113 Safari/537.36 Edg/81.0.416.58", "PATH_INFO": "/", "REMOTE_HOST": null, "USER_IP": "127.0.0.1"}

2020-04-19 21:57:35,195:INFO:{"USER_AGENT": "Mozilla/5.0 (Windows NT 10.0; Win64; x64) AppleWebKit/537.36 (KHTML, like Gecko) Chrome/81.0.4044.113 Safari/537.36 Edg/81.0.416.58", "PATH_INFO": "/", "REMOTE_HOST": null, "USER_IP": "127.0.0.1"}

2020-04-19 21:58:12,239:INFO:{"USER_AGENT": "Mozilla/5.0 (Windows NT 10.0; Win64; x64) AppleWebKit/537.36 (KHTML, like Gecko) Chrome/81.0.4044.113 Safari/537.36 Edg/81.0.416.58", "PATH_INFO": "/", "REMOTE_HOST": null, "USER_IP": "127.0.0.1"}

2020-04-19 21:59:23,971:INFO:{"USER_AGENT": "Mozilla/5.0 (Windows NT 10.0; Win64; x64) AppleWebKit/537.36 (KHTML, like Gecko) Chrome/81.0.4044.113 Safari/537.36 Edg/81.0.416.58", "PATH_INFO": "/", "REMOTE_HOST": null, "USER_IP": "127.0.0.1"}

2020-04-19 22:00:13,089:INFO:{"USER_AGENT": "Mozilla/5.0 (Windows NT 10.0; Win64; x64) AppleWebKit/537.36 (KHTML, like Gecko) Chrome/81.0.4044.113 Safari/537.36 Edg/81.0.416.58", "PATH_INFO": "/", "REMOTE_HOST": null, "USER_IP": "127.0.0.1"}

2020-04-19 22:03:53,688:INFO:{"USER_AGENT": "Mozilla/5.0 (Windows NT 10.0; Win64; x64) AppleWebKit/537.36 (KHTML, like Gecko) Chrome/81.0.4044.113 Safari/537.36 Edg/81.0.416.58", "PATH_INFO": "/", "REMOTE_HOST": null, "USER_IP": "127.0.0.1"}

2020-04-19 22:06:26,588:INFO:{"USER_AGENT": "Mozilla/5.0 (Linux; Android 10; MI 9 Build/QKQ1.190825.002; wv) AppleWebKit/537.36 (KHTML, like Gecko) Version/4.0 Chrome/80.0.3987.132 Mobile Safari/537.36 (#Build; Xiaomi; MI 9; QKQ1.190825.002 test-keys; 10) +CoolMarket/9.6.3", "PATH_INFO": "/", "REMOTE_HOST": null, "USER_IP": "127.0.0.1"}

2020-04-19 22:06:40,141:INFO:{"USER_AGENT": "Mozilla/5.0 (Linux; Android 10; MI 9 Build/QKQ1.190825.002; wv) AppleWebKit/537.36 (KHTML, like Gecko) Version/4.0 Chrome/80.0.3987.132 Mobile Safari/537.36 (#Build; Xiaomi; MI 9; QKQ1.190825.002 test-keys; 10) +CoolMarket/9.6.3", "PATH_INFO": "/", "REMOTE_HOST": null, "USER_IP": "127.0.0.1"}

2020-04-19 22:06:43,358:INFO:{"USER_AGENT": "Mozilla/5.0 (Linux; Android 10; MI 9 Build/QKQ1.190825.002; wv) AppleWebKit/537.36 (KHTML, like Gecko) Version/4.0 Chrome/80.0.3987.132 Mobile Safari/537.36 (#Build; Xiaomi; MI 9; QKQ1.190825.002 test-keys; 10) +CoolMarket/9.6.3", "PATH_INFO": "/", "REMOTE_HOST": null, "USER_IP": "127.0.0.1"}

2020-04-19 22:20:22,736:INFO:{"USER_AGENT": "Mozilla/5.0 (Windows NT 10.0; Win64; x64) AppleWebKit/537.36 (KHTML, like Gecko) Chrome/81.0.4044.113 Safari/537.36 Edg/81.0.416.58", "PATH_INFO": "/", "REMOTE_HOST": null, "USER_IP": "127.0.0.1"}

2020-04-19 22:20:22,744:ERROR:Internal Server Error: /
Traceback (most recent call last):
  File "/usr/local/lib/python3.6/dist-packages/django/core/handlers/exception.py", line 34, in inner
    response = get_response(request)
  File "/usr/local/lib/python3.6/dist-packages/django/core/handlers/base.py", line 115, in _get_response
    response = self.process_exception_by_middleware(e, request)
  File "/usr/local/lib/python3.6/dist-packages/django/core/handlers/base.py", line 113, in _get_response
    response = wrapped_callback(request, *callback_args, **callback_kwargs)
  File "/home/ubuntu/resourcesNet/book/views.py", line 64, in _log_record
    return func(*args,**kwargs)
  File "/home/ubuntu/resourcesNet/book/views.py", line 48, in _block_spider
    return func(*args, **kwargs)
  File "/home/ubuntu/resourcesNet/book/views.py", line 97, in index
    return render(request,'book/index.html',{'information':a,'total_page':total_page,'now_page':1})
  File "/usr/local/lib/python3.6/dist-packages/django/shortcuts.py", line 19, in render
    content = loader.render_to_string(template_name, context, request, using=using)
  File "/usr/local/lib/python3.6/dist-packages/django/template/loader.py", line 62, in render_to_string
    return template.render(context, request)
  File "/usr/local/lib/python3.6/dist-packages/django/template/backends/django.py", line 61, in render
    return self.template.render(context)
  File "/usr/local/lib/python3.6/dist-packages/django/template/base.py", line 171, in render
    return self._render(context)
  File "/usr/local/lib/python3.6/dist-packages/django/template/base.py", line 163, in _render
    return self.nodelist.render(context)
  File "/usr/local/lib/python3.6/dist-packages/django/template/base.py", line 936, in render
    bit = node.render_annotated(context)
  File "/usr/local/lib/python3.6/dist-packages/django/template/base.py", line 903, in render_annotated
    return self.render(context)
  File "/usr/local/lib/python3.6/dist-packages/django/template/loader_tags.py", line 150, in render
    return compiled_parent._render(context)
  File "/usr/local/lib/python3.6/dist-packages/django/template/base.py", line 163, in _render
    return self.nodelist.render(context)
  File "/usr/local/lib/python3.6/dist-packages/django/template/base.py", line 936, in render
    bit = node.render_annotated(context)
  File "/usr/local/lib/python3.6/dist-packages/django/template/base.py", line 903, in render_annotated
    return self.render(context)
  File "/usr/local/lib/python3.6/dist-packages/django/template/loader_tags.py", line 62, in render
    result = block.nodelist.render(context)
  File "/usr/local/lib/python3.6/dist-packages/django/template/base.py", line 936, in render
    bit = node.render_annotated(context)
  File "/usr/local/lib/python3.6/dist-packages/django/template/base.py", line 903, in render_annotated
    return self.render(context)
  File "/usr/local/lib/python3.6/dist-packages/django/template/defaulttags.py", line 309, in render
    return nodelist.render(context)
  File "/usr/local/lib/python3.6/dist-packages/django/template/base.py", line 936, in render
    bit = node.render_annotated(context)
  File "/usr/local/lib/python3.6/dist-packages/django/template/base.py", line 903, in render_annotated
    return self.render(context)
  File "/usr/local/lib/python3.6/dist-packages/django/template/defaulttags.py", line 209, in render
    nodelist.append(node.render_annotated(context))
  File "/usr/local/lib/python3.6/dist-packages/django/template/base.py", line 903, in render_annotated
    return self.render(context)
  File "/usr/local/lib/python3.6/dist-packages/django/template/defaulttags.py", line 443, in render
    url = reverse(view_name, args=args, kwargs=kwargs, current_app=current_app)
  File "/usr/local/lib/python3.6/dist-packages/django/urls/base.py", line 87, in reverse
    return iri_to_uri(resolver._reverse_with_prefix(view, prefix, *args, **kwargs))
  File "/usr/local/lib/python3.6/dist-packages/django/urls/resolvers.py", line 677, in _reverse_with_prefix
    raise NoReverseMatch(msg)
django.urls.exceptions.NoReverseMatch: Reverse for 'detail' with keyword arguments '{'id': ''}' not found. 1 pattern(s) tried: ['detail\\/(?P<id>[^/]+)\\/$']
2020-04-19 22:20:29,028:INFO:{"USER_AGENT": "Mozilla/5.0 (Windows NT 10.0; Win64; x64) AppleWebKit/537.36 (KHTML, like Gecko) Chrome/81.0.4044.113 Safari/537.36 Edg/81.0.416.58", "PATH_INFO": "/", "REMOTE_HOST": null, "USER_IP": "127.0.0.1"}

2020-04-19 22:20:29,035:ERROR:Internal Server Error: /
Traceback (most recent call last):
  File "/usr/local/lib/python3.6/dist-packages/django/core/handlers/exception.py", line 34, in inner
    response = get_response(request)
  File "/usr/local/lib/python3.6/dist-packages/django/core/handlers/base.py", line 115, in _get_response
    response = self.process_exception_by_middleware(e, request)
  File "/usr/local/lib/python3.6/dist-packages/django/core/handlers/base.py", line 113, in _get_response
    response = wrapped_callback(request, *callback_args, **callback_kwargs)
  File "/home/ubuntu/resourcesNet/book/views.py", line 64, in _log_record
    return func(*args,**kwargs)
  File "/home/ubuntu/resourcesNet/book/views.py", line 48, in _block_spider
    return func(*args, **kwargs)
  File "/home/ubuntu/resourcesNet/book/views.py", line 97, in index
    return render(request,'book/index.html',{'information':a,'total_page':total_page,'now_page':1})
  File "/usr/local/lib/python3.6/dist-packages/django/shortcuts.py", line 19, in render
    content = loader.render_to_string(template_name, context, request, using=using)
  File "/usr/local/lib/python3.6/dist-packages/django/template/loader.py", line 62, in render_to_string
    return template.render(context, request)
  File "/usr/local/lib/python3.6/dist-packages/django/template/backends/django.py", line 61, in render
    return self.template.render(context)
  File "/usr/local/lib/python3.6/dist-packages/django/template/base.py", line 171, in render
    return self._render(context)
  File "/usr/local/lib/python3.6/dist-packages/django/template/base.py", line 163, in _render
    return self.nodelist.render(context)
  File "/usr/local/lib/python3.6/dist-packages/django/template/base.py", line 936, in render
    bit = node.render_annotated(context)
  File "/usr/local/lib/python3.6/dist-packages/django/template/base.py", line 903, in render_annotated
    return self.render(context)
  File "/usr/local/lib/python3.6/dist-packages/django/template/loader_tags.py", line 150, in render
    return compiled_parent._render(context)
  File "/usr/local/lib/python3.6/dist-packages/django/template/base.py", line 163, in _render
    return self.nodelist.render(context)
  File "/usr/local/lib/python3.6/dist-packages/django/template/base.py", line 936, in render
    bit = node.render_annotated(context)
  File "/usr/local/lib/python3.6/dist-packages/django/template/base.py", line 903, in render_annotated
    return self.render(context)
  File "/usr/local/lib/python3.6/dist-packages/django/template/loader_tags.py", line 62, in render
    result = block.nodelist.render(context)
  File "/usr/local/lib/python3.6/dist-packages/django/template/base.py", line 936, in render
    bit = node.render_annotated(context)
  File "/usr/local/lib/python3.6/dist-packages/django/template/base.py", line 903, in render_annotated
    return self.render(context)
  File "/usr/local/lib/python3.6/dist-packages/django/template/defaulttags.py", line 309, in render
    return nodelist.render(context)
  File "/usr/local/lib/python3.6/dist-packages/django/template/base.py", line 936, in render
    bit = node.render_annotated(context)
  File "/usr/local/lib/python3.6/dist-packages/django/template/base.py", line 903, in render_annotated
    return self.render(context)
  File "/usr/local/lib/python3.6/dist-packages/django/template/defaulttags.py", line 209, in render
    nodelist.append(node.render_annotated(context))
  File "/usr/local/lib/python3.6/dist-packages/django/template/base.py", line 903, in render_annotated
    return self.render(context)
  File "/usr/local/lib/python3.6/dist-packages/django/template/defaulttags.py", line 443, in render
    url = reverse(view_name, args=args, kwargs=kwargs, current_app=current_app)
  File "/usr/local/lib/python3.6/dist-packages/django/urls/base.py", line 87, in reverse
    return iri_to_uri(resolver._reverse_with_prefix(view, prefix, *args, **kwargs))
  File "/usr/local/lib/python3.6/dist-packages/django/urls/resolvers.py", line 677, in _reverse_with_prefix
    raise NoReverseMatch(msg)
django.urls.exceptions.NoReverseMatch: Reverse for 'detail' with keyword arguments '{'id': ''}' not found. 1 pattern(s) tried: ['detail\\/(?P<id>[^/]+)\\/$']
2020-04-19 22:22:48,719:INFO:{"USER_AGENT": "Mozilla/5.0 (Windows NT 10.0; Win64; x64) AppleWebKit/537.36 (KHTML, like Gecko) Chrome/81.0.4044.113 Safari/537.36 Edg/81.0.416.58", "PATH_INFO": "/", "REMOTE_HOST": null, "USER_IP": "127.0.0.1"}

2020-04-19 22:22:48,726:ERROR:Internal Server Error: /
Traceback (most recent call last):
  File "/usr/local/lib/python3.6/dist-packages/django/core/handlers/exception.py", line 34, in inner
    response = get_response(request)
  File "/usr/local/lib/python3.6/dist-packages/django/core/handlers/base.py", line 115, in _get_response
    response = self.process_exception_by_middleware(e, request)
  File "/usr/local/lib/python3.6/dist-packages/django/core/handlers/base.py", line 113, in _get_response
    response = wrapped_callback(request, *callback_args, **callback_kwargs)
  File "/home/ubuntu/resourcesNet/book/views.py", line 64, in _log_record
    return func(*args,**kwargs)
  File "/home/ubuntu/resourcesNet/book/views.py", line 48, in _block_spider
    return func(*args, **kwargs)
  File "/home/ubuntu/resourcesNet/book/views.py", line 97, in index
    return render(request,'book/index.html',{'information':a,'total_page':total_page,'now_page':1})
  File "/usr/local/lib/python3.6/dist-packages/django/shortcuts.py", line 19, in render
    content = loader.render_to_string(template_name, context, request, using=using)
  File "/usr/local/lib/python3.6/dist-packages/django/template/loader.py", line 62, in render_to_string
    return template.render(context, request)
  File "/usr/local/lib/python3.6/dist-packages/django/template/backends/django.py", line 61, in render
    return self.template.render(context)
  File "/usr/local/lib/python3.6/dist-packages/django/template/base.py", line 171, in render
    return self._render(context)
  File "/usr/local/lib/python3.6/dist-packages/django/template/base.py", line 163, in _render
    return self.nodelist.render(context)
  File "/usr/local/lib/python3.6/dist-packages/django/template/base.py", line 936, in render
    bit = node.render_annotated(context)
  File "/usr/local/lib/python3.6/dist-packages/django/template/base.py", line 903, in render_annotated
    return self.render(context)
  File "/usr/local/lib/python3.6/dist-packages/django/template/loader_tags.py", line 150, in render
    return compiled_parent._render(context)
  File "/usr/local/lib/python3.6/dist-packages/django/template/base.py", line 163, in _render
    return self.nodelist.render(context)
  File "/usr/local/lib/python3.6/dist-packages/django/template/base.py", line 936, in render
    bit = node.render_annotated(context)
  File "/usr/local/lib/python3.6/dist-packages/django/template/base.py", line 903, in render_annotated
    return self.render(context)
  File "/usr/local/lib/python3.6/dist-packages/django/template/loader_tags.py", line 62, in render
    result = block.nodelist.render(context)
  File "/usr/local/lib/python3.6/dist-packages/django/template/base.py", line 936, in render
    bit = node.render_annotated(context)
  File "/usr/local/lib/python3.6/dist-packages/django/template/base.py", line 903, in render_annotated
    return self.render(context)
  File "/usr/local/lib/python3.6/dist-packages/django/template/defaulttags.py", line 309, in render
    return nodelist.render(context)
  File "/usr/local/lib/python3.6/dist-packages/django/template/base.py", line 936, in render
    bit = node.render_annotated(context)
  File "/usr/local/lib/python3.6/dist-packages/django/template/base.py", line 903, in render_annotated
    return self.render(context)
  File "/usr/local/lib/python3.6/dist-packages/django/template/defaulttags.py", line 209, in render
    nodelist.append(node.render_annotated(context))
  File "/usr/local/lib/python3.6/dist-packages/django/template/base.py", line 903, in render_annotated
    return self.render(context)
  File "/usr/local/lib/python3.6/dist-packages/django/template/defaulttags.py", line 443, in render
    url = reverse(view_name, args=args, kwargs=kwargs, current_app=current_app)
  File "/usr/local/lib/python3.6/dist-packages/django/urls/base.py", line 87, in reverse
    return iri_to_uri(resolver._reverse_with_prefix(view, prefix, *args, **kwargs))
  File "/usr/local/lib/python3.6/dist-packages/django/urls/resolvers.py", line 677, in _reverse_with_prefix
    raise NoReverseMatch(msg)
django.urls.exceptions.NoReverseMatch: Reverse for 'detail' with keyword arguments '{'id': ''}' not found. 1 pattern(s) tried: ['detail\\/(?P<id>[^/]+)\\/$']
2020-04-19 22:23:24,465:INFO:{"USER_AGENT": "Mozilla/5.0 (Windows NT 10.0; Win64; x64) AppleWebKit/537.36 (KHTML, like Gecko) Chrome/81.0.4044.113 Safari/537.36 Edg/81.0.416.58", "PATH_INFO": "/", "REMOTE_HOST": null, "USER_IP": "127.0.0.1"}

2020-04-19 22:23:24,472:ERROR:Internal Server Error: /
Traceback (most recent call last):
  File "/usr/local/lib/python3.6/dist-packages/django/core/handlers/exception.py", line 34, in inner
    response = get_response(request)
  File "/usr/local/lib/python3.6/dist-packages/django/core/handlers/base.py", line 115, in _get_response
    response = self.process_exception_by_middleware(e, request)
  File "/usr/local/lib/python3.6/dist-packages/django/core/handlers/base.py", line 113, in _get_response
    response = wrapped_callback(request, *callback_args, **callback_kwargs)
  File "/home/ubuntu/resourcesNet/book/views.py", line 64, in _log_record
    return func(*args,**kwargs)
  File "/home/ubuntu/resourcesNet/book/views.py", line 48, in _block_spider
    return func(*args, **kwargs)
  File "/home/ubuntu/resourcesNet/book/views.py", line 97, in index
    return render(request,'book/index.html',{'information':a,'total_page':total_page,'now_page':1})
  File "/usr/local/lib/python3.6/dist-packages/django/shortcuts.py", line 19, in render
    content = loader.render_to_string(template_name, context, request, using=using)
  File "/usr/local/lib/python3.6/dist-packages/django/template/loader.py", line 62, in render_to_string
    return template.render(context, request)
  File "/usr/local/lib/python3.6/dist-packages/django/template/backends/django.py", line 61, in render
    return self.template.render(context)
  File "/usr/local/lib/python3.6/dist-packages/django/template/base.py", line 171, in render
    return self._render(context)
  File "/usr/local/lib/python3.6/dist-packages/django/template/base.py", line 163, in _render
    return self.nodelist.render(context)
  File "/usr/local/lib/python3.6/dist-packages/django/template/base.py", line 936, in render
    bit = node.render_annotated(context)
  File "/usr/local/lib/python3.6/dist-packages/django/template/base.py", line 903, in render_annotated
    return self.render(context)
  File "/usr/local/lib/python3.6/dist-packages/django/template/loader_tags.py", line 150, in render
    return compiled_parent._render(context)
  File "/usr/local/lib/python3.6/dist-packages/django/template/base.py", line 163, in _render
    return self.nodelist.render(context)
  File "/usr/local/lib/python3.6/dist-packages/django/template/base.py", line 936, in render
    bit = node.render_annotated(context)
  File "/usr/local/lib/python3.6/dist-packages/django/template/base.py", line 903, in render_annotated
    return self.render(context)
  File "/usr/local/lib/python3.6/dist-packages/django/template/loader_tags.py", line 62, in render
    result = block.nodelist.render(context)
  File "/usr/local/lib/python3.6/dist-packages/django/template/base.py", line 936, in render
    bit = node.render_annotated(context)
  File "/usr/local/lib/python3.6/dist-packages/django/template/base.py", line 903, in render_annotated
    return self.render(context)
  File "/usr/local/lib/python3.6/dist-packages/django/template/defaulttags.py", line 309, in render
    return nodelist.render(context)
  File "/usr/local/lib/python3.6/dist-packages/django/template/base.py", line 936, in render
    bit = node.render_annotated(context)
  File "/usr/local/lib/python3.6/dist-packages/django/template/base.py", line 903, in render_annotated
    return self.render(context)
  File "/usr/local/lib/python3.6/dist-packages/django/template/defaulttags.py", line 209, in render
    nodelist.append(node.render_annotated(context))
  File "/usr/local/lib/python3.6/dist-packages/django/template/base.py", line 903, in render_annotated
    return self.render(context)
  File "/usr/local/lib/python3.6/dist-packages/django/template/defaulttags.py", line 443, in render
    url = reverse(view_name, args=args, kwargs=kwargs, current_app=current_app)
  File "/usr/local/lib/python3.6/dist-packages/django/urls/base.py", line 87, in reverse
    return iri_to_uri(resolver._reverse_with_prefix(view, prefix, *args, **kwargs))
  File "/usr/local/lib/python3.6/dist-packages/django/urls/resolvers.py", line 677, in _reverse_with_prefix
    raise NoReverseMatch(msg)
django.urls.exceptions.NoReverseMatch: Reverse for 'detail' with keyword arguments '{'id': ''}' not found. 1 pattern(s) tried: ['detail\\/(?P<id>[^/]+)\\/$']
2020-04-19 22:23:28,507:ERROR:Internal Server Error: /postbox/
Traceback (most recent call last):
  File "/usr/local/lib/python3.6/dist-packages/django/db/models/fields/__init__.py", line 1772, in get_prep_value
    return int(value)
ValueError: invalid literal for int() with base 10: ''

The above exception was the direct cause of the following exception:

Traceback (most recent call last):
  File "/usr/local/lib/python3.6/dist-packages/django/core/handlers/exception.py", line 34, in inner
    response = get_response(request)
  File "/usr/local/lib/python3.6/dist-packages/django/core/handlers/base.py", line 115, in _get_response
    response = self.process_exception_by_middleware(e, request)
  File "/usr/local/lib/python3.6/dist-packages/django/core/handlers/base.py", line 113, in _get_response
    response = wrapped_callback(request, *callback_args, **callback_kwargs)
  File "/usr/local/lib/python3.6/dist-packages/django/views/decorators/csrf.py", line 54, in wrapped_view
    return view_func(*args, **kwargs)
  File "/home/ubuntu/resourcesNet/book/views.py", line 229, in postbox
    b.save()
  File "/usr/local/lib/python3.6/dist-packages/django/db/models/base.py", line 746, in save
    force_update=force_update, update_fields=update_fields)
  File "/usr/local/lib/python3.6/dist-packages/django/db/models/base.py", line 784, in save_base
    force_update, using, update_fields,
  File "/usr/local/lib/python3.6/dist-packages/django/db/models/base.py", line 865, in _save_table
    forced_update)
  File "/usr/local/lib/python3.6/dist-packages/django/db/models/base.py", line 917, in _do_update
    return filtered._update(values) > 0
  File "/usr/local/lib/python3.6/dist-packages/django/db/models/query.py", line 771, in _update
    return query.get_compiler(self.db).execute_sql(CURSOR)
  File "/usr/local/lib/python3.6/dist-packages/django/db/models/sql/compiler.py", line 1499, in execute_sql
    cursor = super().execute_sql(result_type)
  File "/usr/local/lib/python3.6/dist-packages/django/db/models/sql/compiler.py", line 1138, in execute_sql
    sql, params = self.as_sql()
  File "/usr/local/lib/python3.6/dist-packages/django/db/models/sql/compiler.py", line 1465, in as_sql
    val = field.get_db_prep_save(val, connection=self.connection)
  File "/usr/local/lib/python3.6/dist-packages/django/db/models/fields/__init__.py", line 821, in get_db_prep_save
    return self.get_db_prep_value(value, connection=connection, prepared=False)
  File "/usr/local/lib/python3.6/dist-packages/django/db/models/fields/__init__.py", line 816, in get_db_prep_value
    value = self.get_prep_value(value)
  File "/usr/local/lib/python3.6/dist-packages/django/db/models/fields/__init__.py", line 1776, in get_prep_value
    ) from e
ValueError: Field 'pages' expected a number but got ''.
2020-04-19 22:28:53,110:INFO:{"USER_AGENT": "Mozilla/5.0 (Windows NT 10.0; Win64; x64) AppleWebKit/537.36 (KHTML, like Gecko) Chrome/81.0.4044.113 Safari/537.36 Edg/81.0.416.58", "PATH_INFO": "/", "REMOTE_HOST": null, "USER_IP": "127.0.0.1"}

2020-04-19 22:28:53,144:ERROR:Internal Server Error: /
Traceback (most recent call last):
  File "/usr/local/lib/python3.6/dist-packages/django/core/handlers/exception.py", line 34, in inner
    response = get_response(request)
  File "/usr/local/lib/python3.6/dist-packages/django/core/handlers/base.py", line 115, in _get_response
    response = self.process_exception_by_middleware(e, request)
  File "/usr/local/lib/python3.6/dist-packages/django/core/handlers/base.py", line 113, in _get_response
    response = wrapped_callback(request, *callback_args, **callback_kwargs)
  File "/home/ubuntu/resourcesNet/book/views.py", line 64, in _log_record
    return func(*args,**kwargs)
  File "/home/ubuntu/resourcesNet/book/views.py", line 48, in _block_spider
    return func(*args, **kwargs)
  File "/home/ubuntu/resourcesNet/book/views.py", line 97, in index
    return render(request,'book/index.html',{'information':a,'total_page':total_page,'now_page':1})
  File "/usr/local/lib/python3.6/dist-packages/django/shortcuts.py", line 19, in render
    content = loader.render_to_string(template_name, context, request, using=using)
  File "/usr/local/lib/python3.6/dist-packages/django/template/loader.py", line 62, in render_to_string
    return template.render(context, request)
  File "/usr/local/lib/python3.6/dist-packages/django/template/backends/django.py", line 61, in render
    return self.template.render(context)
  File "/usr/local/lib/python3.6/dist-packages/django/template/base.py", line 171, in render
    return self._render(context)
  File "/usr/local/lib/python3.6/dist-packages/django/template/base.py", line 163, in _render
    return self.nodelist.render(context)
  File "/usr/local/lib/python3.6/dist-packages/django/template/base.py", line 936, in render
    bit = node.render_annotated(context)
  File "/usr/local/lib/python3.6/dist-packages/django/template/base.py", line 903, in render_annotated
    return self.render(context)
  File "/usr/local/lib/python3.6/dist-packages/django/template/loader_tags.py", line 150, in render
    return compiled_parent._render(context)
  File "/usr/local/lib/python3.6/dist-packages/django/template/base.py", line 163, in _render
    return self.nodelist.render(context)
  File "/usr/local/lib/python3.6/dist-packages/django/template/base.py", line 936, in render
    bit = node.render_annotated(context)
  File "/usr/local/lib/python3.6/dist-packages/django/template/base.py", line 903, in render_annotated
    return self.render(context)
  File "/usr/local/lib/python3.6/dist-packages/django/template/loader_tags.py", line 62, in render
    result = block.nodelist.render(context)
  File "/usr/local/lib/python3.6/dist-packages/django/template/base.py", line 936, in render
    bit = node.render_annotated(context)
  File "/usr/local/lib/python3.6/dist-packages/django/template/base.py", line 903, in render_annotated
    return self.render(context)
  File "/usr/local/lib/python3.6/dist-packages/django/template/defaulttags.py", line 309, in render
    return nodelist.render(context)
  File "/usr/local/lib/python3.6/dist-packages/django/template/base.py", line 936, in render
    bit = node.render_annotated(context)
  File "/usr/local/lib/python3.6/dist-packages/django/template/base.py", line 903, in render_annotated
    return self.render(context)
  File "/usr/local/lib/python3.6/dist-packages/django/template/defaulttags.py", line 209, in render
    nodelist.append(node.render_annotated(context))
  File "/usr/local/lib/python3.6/dist-packages/django/template/base.py", line 903, in render_annotated
    return self.render(context)
  File "/usr/local/lib/python3.6/dist-packages/django/template/defaulttags.py", line 443, in render
    url = reverse(view_name, args=args, kwargs=kwargs, current_app=current_app)
  File "/usr/local/lib/python3.6/dist-packages/django/urls/base.py", line 87, in reverse
    return iri_to_uri(resolver._reverse_with_prefix(view, prefix, *args, **kwargs))
  File "/usr/local/lib/python3.6/dist-packages/django/urls/resolvers.py", line 677, in _reverse_with_prefix
    raise NoReverseMatch(msg)
django.urls.exceptions.NoReverseMatch: Reverse for 'detail' with keyword arguments '{'id': ''}' not found. 1 pattern(s) tried: ['detail\\/(?P<id>[^/]+)\\/$']
2020-04-19 22:28:56,166:INFO:{"USER_AGENT": "Mozilla/5.0 (Windows NT 10.0; Win64; x64) AppleWebKit/537.36 (KHTML, like Gecko) Chrome/81.0.4044.113 Safari/537.36 Edg/81.0.416.58", "PATH_INFO": "/", "REMOTE_HOST": null, "USER_IP": "127.0.0.1"}

2020-04-19 22:28:56,202:ERROR:Internal Server Error: /
Traceback (most recent call last):
  File "/usr/local/lib/python3.6/dist-packages/django/core/handlers/exception.py", line 34, in inner
    response = get_response(request)
  File "/usr/local/lib/python3.6/dist-packages/django/core/handlers/base.py", line 115, in _get_response
    response = self.process_exception_by_middleware(e, request)
  File "/usr/local/lib/python3.6/dist-packages/django/core/handlers/base.py", line 113, in _get_response
    response = wrapped_callback(request, *callback_args, **callback_kwargs)
  File "/home/ubuntu/resourcesNet/book/views.py", line 64, in _log_record
    return func(*args,**kwargs)
  File "/home/ubuntu/resourcesNet/book/views.py", line 48, in _block_spider
    return func(*args, **kwargs)
  File "/home/ubuntu/resourcesNet/book/views.py", line 97, in index
    return render(request,'book/index.html',{'information':a,'total_page':total_page,'now_page':1})
  File "/usr/local/lib/python3.6/dist-packages/django/shortcuts.py", line 19, in render
    content = loader.render_to_string(template_name, context, request, using=using)
  File "/usr/local/lib/python3.6/dist-packages/django/template/loader.py", line 62, in render_to_string
    return template.render(context, request)
  File "/usr/local/lib/python3.6/dist-packages/django/template/backends/django.py", line 61, in render
    return self.template.render(context)
  File "/usr/local/lib/python3.6/dist-packages/django/template/base.py", line 171, in render
    return self._render(context)
  File "/usr/local/lib/python3.6/dist-packages/django/template/base.py", line 163, in _render
    return self.nodelist.render(context)
  File "/usr/local/lib/python3.6/dist-packages/django/template/base.py", line 936, in render
    bit = node.render_annotated(context)
  File "/usr/local/lib/python3.6/dist-packages/django/template/base.py", line 903, in render_annotated
    return self.render(context)
  File "/usr/local/lib/python3.6/dist-packages/django/template/loader_tags.py", line 150, in render
    return compiled_parent._render(context)
  File "/usr/local/lib/python3.6/dist-packages/django/template/base.py", line 163, in _render
    return self.nodelist.render(context)
  File "/usr/local/lib/python3.6/dist-packages/django/template/base.py", line 936, in render
    bit = node.render_annotated(context)
  File "/usr/local/lib/python3.6/dist-packages/django/template/base.py", line 903, in render_annotated
    return self.render(context)
  File "/usr/local/lib/python3.6/dist-packages/django/template/loader_tags.py", line 62, in render
    result = block.nodelist.render(context)
  File "/usr/local/lib/python3.6/dist-packages/django/template/base.py", line 936, in render
    bit = node.render_annotated(context)
  File "/usr/local/lib/python3.6/dist-packages/django/template/base.py", line 903, in render_annotated
    return self.render(context)
  File "/usr/local/lib/python3.6/dist-packages/django/template/defaulttags.py", line 309, in render
    return nodelist.render(context)
  File "/usr/local/lib/python3.6/dist-packages/django/template/base.py", line 936, in render
    bit = node.render_annotated(context)
  File "/usr/local/lib/python3.6/dist-packages/django/template/base.py", line 903, in render_annotated
    return self.render(context)
  File "/usr/local/lib/python3.6/dist-packages/django/template/defaulttags.py", line 209, in render
    nodelist.append(node.render_annotated(context))
  File "/usr/local/lib/python3.6/dist-packages/django/template/base.py", line 903, in render_annotated
    return self.render(context)
  File "/usr/local/lib/python3.6/dist-packages/django/template/defaulttags.py", line 443, in render
    url = reverse(view_name, args=args, kwargs=kwargs, current_app=current_app)
  File "/usr/local/lib/python3.6/dist-packages/django/urls/base.py", line 87, in reverse
    return iri_to_uri(resolver._reverse_with_prefix(view, prefix, *args, **kwargs))
  File "/usr/local/lib/python3.6/dist-packages/django/urls/resolvers.py", line 677, in _reverse_with_prefix
    raise NoReverseMatch(msg)
django.urls.exceptions.NoReverseMatch: Reverse for 'detail' with keyword arguments '{'id': ''}' not found. 1 pattern(s) tried: ['detail\\/(?P<id>[^/]+)\\/$']
2020-04-19 22:29:33,051:INFO:{"USER_AGENT": "Mozilla/5.0 (Windows NT 10.0; Win64; x64) AppleWebKit/537.36 (KHTML, like Gecko) Chrome/81.0.4044.113 Safari/537.36 Edg/81.0.416.58", "PATH_INFO": "/detail/26628819/", "REMOTE_HOST": null, "USER_IP": "127.0.0.1"}

2020-04-19 22:31:55,396:INFO:{"USER_AGENT": "Mozilla/5.0 (Windows NT 10.0; Win64; x64) AppleWebKit/537.36 (KHTML, like Gecko) Chrome/81.0.4044.113 Safari/537.36 Edg/81.0.416.58", "PATH_INFO": "/", "REMOTE_HOST": "", "USER_IP": "52.229.158.174"}

2020-04-19 22:31:55,556:ERROR:Internal Server Error: /
Traceback (most recent call last):
  File "/usr/local/lib/python3.6/dist-packages/django/core/handlers/exception.py", line 34, in inner
    response = get_response(request)
  File "/usr/local/lib/python3.6/dist-packages/django/core/handlers/base.py", line 115, in _get_response
    response = self.process_exception_by_middleware(e, request)
  File "/usr/local/lib/python3.6/dist-packages/django/core/handlers/base.py", line 113, in _get_response
    response = wrapped_callback(request, *callback_args, **callback_kwargs)
  File "/home/ubuntu/resourcesNet/book/views.py", line 64, in _log_record
    return func(*args,**kwargs)
  File "/home/ubuntu/resourcesNet/book/views.py", line 48, in _block_spider
    return func(*args, **kwargs)
  File "/home/ubuntu/resourcesNet/book/views.py", line 97, in index
    return render(request,'book/index.html',{'information':a,'total_page':total_page,'now_page':1})
  File "/usr/local/lib/python3.6/dist-packages/django/shortcuts.py", line 19, in render
    content = loader.render_to_string(template_name, context, request, using=using)
  File "/usr/local/lib/python3.6/dist-packages/django/template/loader.py", line 62, in render_to_string
    return template.render(context, request)
  File "/usr/local/lib/python3.6/dist-packages/django/template/backends/django.py", line 61, in render
    return self.template.render(context)
  File "/usr/local/lib/python3.6/dist-packages/django/template/base.py", line 171, in render
    return self._render(context)
  File "/usr/local/lib/python3.6/dist-packages/django/template/base.py", line 163, in _render
    return self.nodelist.render(context)
  File "/usr/local/lib/python3.6/dist-packages/django/template/base.py", line 936, in render
    bit = node.render_annotated(context)
  File "/usr/local/lib/python3.6/dist-packages/django/template/base.py", line 903, in render_annotated
    return self.render(context)
  File "/usr/local/lib/python3.6/dist-packages/django/template/loader_tags.py", line 150, in render
    return compiled_parent._render(context)
  File "/usr/local/lib/python3.6/dist-packages/django/template/base.py", line 163, in _render
    return self.nodelist.render(context)
  File "/usr/local/lib/python3.6/dist-packages/django/template/base.py", line 936, in render
    bit = node.render_annotated(context)
  File "/usr/local/lib/python3.6/dist-packages/django/template/base.py", line 903, in render_annotated
    return self.render(context)
  File "/usr/local/lib/python3.6/dist-packages/django/template/loader_tags.py", line 62, in render
    result = block.nodelist.render(context)
  File "/usr/local/lib/python3.6/dist-packages/django/template/base.py", line 936, in render
    bit = node.render_annotated(context)
  File "/usr/local/lib/python3.6/dist-packages/django/template/base.py", line 903, in render_annotated
    return self.render(context)
  File "/usr/local/lib/python3.6/dist-packages/django/template/defaulttags.py", line 309, in render
    return nodelist.render(context)
  File "/usr/local/lib/python3.6/dist-packages/django/template/base.py", line 936, in render
    bit = node.render_annotated(context)
  File "/usr/local/lib/python3.6/dist-packages/django/template/base.py", line 903, in render_annotated
    return self.render(context)
  File "/usr/local/lib/python3.6/dist-packages/django/template/defaulttags.py", line 209, in render
    nodelist.append(node.render_annotated(context))
  File "/usr/local/lib/python3.6/dist-packages/django/template/base.py", line 903, in render_annotated
    return self.render(context)
  File "/usr/local/lib/python3.6/dist-packages/django/template/defaulttags.py", line 443, in render
    url = reverse(view_name, args=args, kwargs=kwargs, current_app=current_app)
  File "/usr/local/lib/python3.6/dist-packages/django/urls/base.py", line 87, in reverse
    return iri_to_uri(resolver._reverse_with_prefix(view, prefix, *args, **kwargs))
  File "/usr/local/lib/python3.6/dist-packages/django/urls/resolvers.py", line 677, in _reverse_with_prefix
    raise NoReverseMatch(msg)
django.urls.exceptions.NoReverseMatch: Reverse for 'detail' with keyword arguments '{'id': ''}' not found. 1 pattern(s) tried: ['detail\\/(?P<id>[^/]+)\\/$']
2020-04-19 22:33:55,926:INFO:/home/ubuntu/resourcesNet/book/urls.py changed, reloading.
